Workbook

Sheet ⓪サマリー
A1: 株式会社YOZAN 事業計画書（3か年）
A2: 作成日 2026年9月10日／代表取締役 古川 博庸
A4: ■ 申込の内容
A5: 借入申込額 | B5: 7,000,000円（全額 運転資金）
A6: 資金使途 | B6: 経常運転資金3,337,170円＋増加運転資金2,618,520円＋季節資金1,066,653円＝7,022,343円（うち自己資金22,343円）
A7: 返済期間 | B7: 7年（84回）／元金据置6か月／毎月5日返済
A8: 計画期間 | B8: 第3期〜第5期（2026年9月〜2029年8月）。決算期は8月31日
A10: ■ 3か年の数字
B11: 第1期 実績 | C11: 第2期 実績 （11か月） | D11: 第2期 見込 （通期） | E11: 第3期 計画 | F11: 第4期 計画 | G11: 第5期 計画
A12: 売上高 | B12: =③3か年収支計画!B9 -> 7927283 | C12: =③3か年収支計画!C9 -> 24979520 | D12: =③3か年収支計画!D9 -> 27250000 | E12: =③3か年収支計画!E9 -> 47240607 | F12: =③3か年収支計画!F9 -> 62984833 | G12: =③3か年収支計画!G9 -> 69620683
A13: 営業損益 | B13: =③3か年収支計画!B13 -> 0 | C13: =③3か年収支計画!C13 -> -1138361 | D13: =③3か年収支計画!D13 -> -1568361 | E13: =③3か年収支計画!E13 -> 1430075 | F13: =③3か年収支計画!F13 -> 13033052 | G13: =③3か年収支計画!G13 -> 15212554
A14: 当期純損益 | B14: =③3か年収支計画!B18 -> -576759 | C14: =③3か年収支計画!C18 -> -1005162 | D14: =③3か年収支計画!D18 -> -1435162 | E14: =③3か年収支計画!E18 -> 1131163 | F14: =③3か年収支計画!F18 -> 8810790 | G14: =③3か年収支計画!G18 -> 10015831
A15: 簡易キャッシュフロー | B15: =③3か年収支計画!B22 -> 0 | C15: =③3か年収支計画!C22 -> 0 | D15: =③3か年収支計画!D22 -> -1435162 | E15: =③3か年収支計画!E22 -> 1831163 | F15: =③3か年収支計画!F22 -> 9510790 | G15: =③3か年収支計画!G22 -> 10715831
A16: 期末 純資産 | B16: =③3か年収支計画!B25 -> -276759 | C16: =③3か年収支計画!C25 -> -1281921 | D16: =③3か年収支計画!D25 -> -1711921 | E16: =③3か年収支計画!E25 -> -580758 | F16: =③3か年収支計画!F25 -> 8230032 | G16: =③3か年収支計画!G25 -> 18245863
A18: ■ この計画の要点
A19: 1. 第2期の赤字は「売れない赤字」ではなく、2号店 FRANK GOLF 姫路（2026年9月2日開業）を立ち上げるための先行投資です。
A20: 事業4部門（キャディ・GOLF WING 宝塚・FRANK・システム）は第2期の時点ですでに合計で黒字で、赤字は本社・共通で発生しています。
A21: 2. その2号店は、開業9日間で体験34件・入会13件（個人12名＋法人1社）。体験→入会の転換率35%は、7月に作成した収支計画の
A22: 標準シナリオと一致しています。本計画の会員数は、この実績を基準に置いています。
A23: 3. 第3期は2号店が通年で寄与し、全社の営業損益・当期純損益はともに黒字に転換します。FRANK GOLF 単体は会員123名（損益分岐点）に
A24: 到達する2027年5月から単月黒字となり、通期では第3期はわずかに赤字、第4期から本格的に寄与します。
A25: 会計上の純資産は第4期に債務超過を解消します。役員借入1,500,000円を資本性とみなした実質ベースでは第3期に解消します。
A26: 4. 700万円は全額が運転資金です。設備（TrackMan 4ほか）はすでに取得しBSに計上済で、今回の申込に設備資金は含みません。
A27: 5. 返済は、簡易キャッシュフローが年間元金返済額を上回る水準を3か年とも確保する計画です（③シート「返済余力」）。
A28: 6. 経費削減 月100,000円（年1,200,000円）の実行は、この計画が成立するための条件として明示的に織り込んでいます。
A29: ■ シートの構成
... A38: ⑨出典と注記 … 数字の出どころと、決算確定後に差し替える項目

Sheet ①前提条件
A1: 株式会社YOZAN 3か年事業計画 前提条件
A2: 黄色のセルが入力値です。ここを変えると②以降のシートがすべて連動して再計算されます。／作成 2026年9月10日
A4: ■ 会社・決算
A5: 決算期 | B5: 8月31日 | E5: 第1期=2024/9/24設立〜2025/8/31、第2期=2025/9/1〜2026/8/31
A6: 計画期間 | B6: 第3期〜第5期（2026/9〜2029/8） | E6: 第3期＝FRANK GOLF 姫路の営業1年目
A7: ■ FRANK GOLF 姫路（直営2号店・2026年9月2日開業）
A8: 稼働打席数 | B8: 3 | C8: 打席 | E8: A打席=DTECT／B打席=TrackMan 4（左右打席）／C打席=OKONGOLF。D打席は未稼働（増設余地）
A9: 個人会員 平均月会費（税抜） | B9: 11000 | E9: 実績構成 レギュラー13,800円(税込)×9名／ライト9,800円(税込)×3名の加重平均12,182円(税込)＝11,075円(税抜)を保守側に丸め
A10: 法人プラン 月額（税抜） | B10: 54364 | E10: 法人プレミアムプラン 59,800円(税込)÷1.1。1社あたり利用者4名まで
A11: 入会金（税抜） | B11: 4545 | E11: 5,000円(税込)÷1.1
A12: 月次退会率 | B12: 0.03 | E12: GOLF WING 宝塚の実績は月3.5〜3.9%。新店は会員の定着期が浅いため保守的に3.0%で置く
A13: 会員数の上限（3打席） | B13: 180 | C13: 名 | E13: 宝塚（会員218名）を上限の目安としつつ、3打席の予約枠が窮屈にならない水準として保守的に180名で頭打ちとする
A14: 会員数の上限（D打席 増設後） | B14: 220 | C14: 名 | E14: 第5期にD打席（4打席目）を稼働させた場合の上限
A15: 店舗固定費（月額） | B15: 1309260 | E15: 家賃440,000＋人件費580,000＋光熱80,000＋広告80,000＋通信15,000＋保険12,000＋システム40,000＋清掃20,000＋修繕積立30,000＋消耗品15,000。8/21提出「増加運転資金」の算定根拠と同額
A16: 同上 第4期（人員増） | B16: 18000000 | E16: 会員200名規模の受付・コーチ体制。年額
A17: 同上 第5期（D打席稼働） | B17: 20000000 | E17: 年額
A18: ビジター利用 月間件数 | B18: 25 | C18: 件 | E18: 開業9日間の実績 dropin 9件（月換算約30件）を保守側に置く
A19: ビジター利用 単価（税抜） | B19: 2500
A20: パーソナルレッスン 月間件数 | B20: 40 | C20: 件 | E20: 25分パーソナル。会員の付帯利用
A21: パーソナルレッスン 単価（税抜） | B21: 2500 | E21: BookingCfg.lesson_option.price（税抜2,500円）
A22: 物販売上 月額（税抜） | B22: 150000 | E22: 宝塚の会員1人あたり物販実績から保守推計
A23: 物販原価率 | B23: 0.65
A24: 決済手数料率 | B24: 0.03 | E24: Square
A25: ■ 既存事業（GOLF WING 宝塚 受託運営＋キャディ派遣）
A26: 第2期 売上高（通期見込） | B26: 27250000 | E26: 11か月実績24,979,520円（税理士 残高試算表 令和8年7月31日）＋8月分を月商換算2,270,865円で加算した見込み。決算確定後に差し替える
A27: 既存事業 年成長率 | B27: 0.03 | E27: 会員218→230名程度の緩やかな増加を想定。宝塚はファイン精算後の純額計上のため伸びは限定的
A28: ■ システム開発・外販
A29: 第3期 売上高 | B29: 2400000 | E29: ホームページ制作（10万円＋月額1万円）／PRO SITE（月5,000円）／店舗運営システムの外販。2026年8月開始
A30: 第4期 売上高 | B30: 4200000
A31: 第5期 売上高 | B31: 6000000
A32: システム外販 営業利益率 | B32: 0.35 | E32: 自社開発のため原価は工数中心。外注費・サーバー費控除後
A33: ■ 部門別営業損益のベース（第2期・年換算）
A34: キャディ派遣 | B34: 5842728 | E34: 月次平均+486,894円×12。出典: 全社資金繰り表 2026-08-17「4区分の収支」（9/4 提出済）
A35: GOLF WING 宝塚 | B35: 5811816 | E35: 月次平均+484,318円×12。同上
A36: FRANK GOLF 姫路 | B36: -770184 | E36: 月次平均▲64,182円×12。当期は開業前の先行費用のみ
A37: 本社・共通 | B37: -12452721 | E37: 資金繰り表の月次平均▲928,473円（年換算▲11,141,676円）に対し、第2期の営業損益見込（11か月実績▲1,138,361円＋8月分▲430,000円＝▲1,568,361円）と部門別の合計が一致するよう調整。差1,311,045円は決算確定時に精査
A38: 経費削減（第3期に実行・年額） | B38: 1200000 | E38: 月100,000円。8/21提出の資金繰り前提と同じ。計画成立の条件
A39: 本社・共通 第4期 | B39: -11500000 | E39: 管理部門1名増を織り込む
A40: 本社・共通 第5期 | B40: -12500000
A41: キャディ派遣 第3期 | B41: 6400000 | E41: 取引ゴルフ場7社→9社。当期実績 売上10,956,460円／原価7,770,764円（Caddy OS台帳）
...

Sheet ②FRANK月次計画
A1: ② FRANK GOLF 姫路 会員数計画と月次収支（第3期〜第5期）
A2: 会員数＝前月末×(1−退会率)＋新規入会（上限あり）。単価・退会率・固定費は①前提条件シートの黄色セルで変更できます。
A4: 期 | B4: 年月 | C4: 期首 会員数 | D4: 新規 入会 | E4: 退会 | F4: 期末 会員数 | G4: 法人 契約数 | H4: 個人会費 | I4: 法人会費 | J4: 入会金 | K4: ビジター | L4: パーソナル レッスン | M4: 物販 | N4: 売上 計 | O4: 物販原価 | P4: 決済 手数料 | Q4: 変動費 計 | R4: 店舗固定費 | S4: 営業損益
A5: 第3期 | B5: 2026-09 | C5: 0 | D5: 22 | E5: =ROUND(C5*①前提条件!$B$12,0) -> 0 | F5: =MIN(①前提条件!$B$13,C5+D5-E5) -> 22 | G5: 1 | H5: =ROUND((C5+F5)/2*①前提条件!$B$9,0) -> 121000 | I5: =G5*①前提条件!$B$10 -> 54364 | J5: =D5*①前提条件!$B$11 -> 99990 | K5: =①前提条件!$B$18*①前提条件!$B$19 -> 62500 | L5: =①前提条件!$B$20*①前提条件!$B$21 -> 100000 | M5: =①前提条件!$B$22 -> 150000 | N5: =SUM(H5:M5) -> 587854 | O5: =ROUND(M5*①前提条件!$B$23,0) -> 97500 | P5: =ROUND((N5-M5)*①前提条件!$B$24,0) -> 13136 | Q5: =O5+P5 -> 110636 | R5: =ROUND(①前提条件!$B$15,0) -> 1309260 | S5: =N5-Q5-R5 -> -832042 | U5: =IF(F5>=$H$46,1,0) -> 0
A6: 第3期 | B6: 2026-10 | C6: =F5 -> 22 | D6: 15 | E6: =ROUND(C6*①前提条件!$B$12,0) -> 1 | F6: =MIN(①前提条件!$B$13,C6+D6-E6) -> 36 | G6: 1 | H6: =ROUND((C6+F6)/2*①前提条件!$B$9,0) -> 319000 | I6: =G6*①前提条件!$B$10 -> 54364 | J6: =D6*①前提条件!$B$11 -> 68175 | K6: =①前提条件!$B$18*①前提条件!$B$19 -> 62500 | L6: =①前提条件!$B$20*①前提条件!$B$21 -> 100000 | M6: =①前提条件!$B$22 -> 150000 | N6: =SUM(H6:M6) -> 754039 | O6: =ROUND(M6*①前提条件!$B$23,0) -> 97500 | P6: =ROUND((N6-M6)*①前提条件!$B$24,0) -> 18121 | Q6: =O6+P6 -> 115621 | R6: =ROUND(①前提条件!$B$15,0) -> 1309260 | S6: =N6-Q6-R6 -> -670842 | U6: =IF(F6>=$H$46,1,0) -> 0
A7: 第3期 | B7: 2026-11 | C7: =F6 -> 36 | D7: 15 | E7: =ROUND(C7*①前提条件!$B$12,0) -> 1 | F7: =MIN(①前提条件!$B$13,C7+D7-E7) -> 50 | G7: 1 | H7: =ROUND((C7+F7)/2*①前提条件!$B$9,0) -> 473000 | I7: =G7*①前提条件!$B$10 -> 54364 | J7: =D7*①前提条件!$B$11 -> 68175 | K7: =①前提条件!$B$18*①前提条件!$B$19 -> 62500 | L7: =①前提条件!$B$20*①前提条件!$B$21 -> 100000 | M7: =①前提条件!$B$22 -> 150000 | N7: =SUM(H7:M7) -> 908039 | O7: =ROUND(M7*①前提条件!$B$23,0) -> 97500 | P7: =ROUND((N7-M7)*①前提条件!$B$24,0) -> 22741 | Q7: =O7+P7 -> 120241 | R7: =ROUND(①前提条件!$B$15,0) -> 1309260 | S7: =N7-Q7-R7 -> -521462 | U7: =IF(F7>=$H$46,1,0) -> 0
A8: 第3期 | B8: 2026-12 | C8: =F7 -> 50 | D8: 15 | E8: =ROUND(C8*①前提条件!$B$12,0) -> 2 | F8: =MIN(①前提条件!$B$13,C8+D8-E8) -> 63 | G8: 1 | H8: =ROUND((C8+F8)/2*①前提条件!$B$9,0) -> 621500 | I8: =G8*①前提条件!$B$10 -> 54364 | J8: =D8*①前提条件!$B$11 -> 68175 | K8: =①前提条件!$B$18*①前提条件!$B$19 -> 62500 | L8: =①前提条件!$B$20*①前提条件!$B$21 -> 100000 | M8: =①前提条件!$B$22 -> 150000 | N8: =SUM(H8:M8) -> 1056539 | O8: =ROUND(M8*①前提条件!$B$23,0) -> 97500 | P8: =ROUND((N8-M8)*①前提条件!$B$24,0) -> 27196 | Q8: =O8+P8 -> 124696 | R8: =ROUND(①前提条件!$B$15,0) -> 1309260 | S8: =N8-Q8-R8 -> -377417 | U8: =IF(F8>=$H$46,1,0) -> 0
A9: 第3期 | B9: 2027-01 | C9: =F8 -> 63 | D9: 15 | E9: =ROUND(C9*①前提条件!$B$12,0) -> 2 | F9: =MIN(①前提条件!$B$13,C9+D9-E9) -> 76 | G9: 1 | H9: =ROUND((C9+F9)/2*①前提条件!$B$9,0) -> 764500 | I9: =G9*①前提条件!$B$10 -> 54364 | J9: =D9*①前提条件!$B$11 -> 68175 | K9: =①前提条件!$B$18*①前提条件!$B$19 -> 62500 | L9: =①前提条件!$B$20*①前提条件!$B$21 -> 100000 | M9: =①前提条件!$B$22 -> 150000 | N9: =SUM(H9:M9) -> 1199539 | O9: =ROUND(M9*①前提条件!$B$23,0) -> 97500 | P9: =ROUND((N9-M9)*①前提条件!$B$24,0) -> 31486 | Q9: =O9+P9 -> 128986 | R9: =ROUND(①前提条件!$B$15,0) -> 1309260 | S9: =N9-Q9-R9 -> -238707 | U9: =IF(F9>=$H$46,1,0) -> 0
A10: 第3期 | B10: 2027-02 | C10: =F9 -> 76 | D10: 15 | E10: =ROUND(C10*①前提条件!$B$12,0) -> 2 | F10: =MIN(①前提条件!$B$13,C10+D10-E10) -> 89 | G10: 1 | H10: =ROUND((C10+F10)/2*①前提条件!$B$9,0) -> 907500 | I10: =G10*①前提条件!$B$10 -> 54364 | J10: =D10*①前提条件!$B$11 -> 68175 | K10: =①前提条件!$B$18*①前提条件!$B$19 -> 62500 | L10: =①前提条件!$B$20*①前提条件!$B$21 -> 100000 | M10: =①前提条件!$B$22 -> 150000 | N10: =SUM(H10:M10) -> 1342539 | O10: =ROUND(M10*①前提条件!$B$23,0) -> 97500 | P10: =ROUND((N10-M10)*①前提条件!$B$24,0) -> 35776 | Q10: =O10+P10 -> 133276 | R10: =ROUND(①前提条件!$B$15,0) -> 1309260 | S10: =N10-Q10-R10 -> -99997 | U10: =IF(F10>=$H$46,1,0) -> 0
A11: 第3期 | B11: 2027-03 | C11: =F10 -> 89 | D11: 15 | E11: =ROUND(C11*①前提条件!$B$12,0) -> 3 | F11: =MIN(①前提条件!$B$13,C11+D11-E11) -> 101 | G11: 2 | H11: =ROUND((C11+F11)/2*①前提条件!$B$9,0) -> 1045000 | I11: =G11*①前提条件!$B$10 -> 108728 | J11: =D11*①前提条件!$B$11 -> 68175 | K11: =①前提条件!$B$18*①前提条件!$B$19 -> 62500 | L11: =①前提条件!$B$20*①前提条件!$B$21 -> 100000 | M11: =①前提条件!$B$22 -> 150000 | N11: =SUM(H11:M11) -> 1534403 | O11: =ROUND(M11*①前提条件!$B$23,0) -> 97500 | P11: =ROUND((N11-M11)*①前提条件!$B$24,0) -> 41532 | Q11: =O11+P11 -> 139032 | R11: =ROUND(①前提条件!$B$15,0) -> 1309260 | S11: =N11-Q11-R11 -> 86111 | U11: =IF(F11>=$H$46,1,0) -> 0
A12: 第3期 | B12: 2027-04 | C12: =F11 -> 101 | D12: 15 | E12: =ROUND(C12*①前提条件!$B$12,0) -> 3 | F12: =MIN(①前提条件!$B$13,C12+D12-E12) -> 113 | G12: 2 | H12: =ROUND((C12+F12)/2*①前提条件!$B$9,0) -> 1177000 | I12: =G12*①前提条件!$B$10 -> 108728 | J12: =D12*①前提条件!$B$11 -> 68175 | K12: =①前提条件!$B$18*①前提条件!$B$19 -> 62500 | L12: =①前提条件!$B$20*①前提条件!$B$21 -> 100000 | M12: =①前提条件!$B$22 -> 150000 | N12: =SUM(H12:M12) -> 1666403 | O12: =ROUND(M12*①前提条件!$B$23,0) -> 97500 | P12: =ROUND((N12-M12)*①前提条件!$B$24,0) -> 45492 | Q12: =O12+P12 -> 142992 | R12: =ROUND(①前提条件!$B$15,0) -> 1309260 | S12: =N12-Q12-R12 -> 214151 | U12: =IF(F12>=$H$46,1,0) -> 0
A13: 第3期 | B13: 2027-05 | C13: =F12 -> 113 | D13: 13 | E13: =ROUND(C13*①前提条件!$B$12,0) -> 3 | F13: =MIN(①前提条件!$B$13,C13+D13-E13) -> 123 | G13: 2 | H13: =ROUND((C13+F13)/2*①前提条件!$B$9,0) -> 1298000 | I13: =G13*①前提条件!$B$10 -> 108728 | J13: =D13*①前提条件!$B$11 -> 59085 | K13: =①前提条件!$B$18*①前提条件!$B$19 -> 62500 | L13: =①前提条件!$B$20*①前提条件!$B$21 -> 100000 | M13: =①前提条件!$B$22 -> 150000 | N13: =SUM(H13:M13) -> 1778313 | O13: =ROUND(M13*①前提条件!$B$23,0) -> 97500 | P13: =ROUND((N13-M13)*①前提条件!$B$24,0) -> 48849 | Q13: =O13+P13 -> 146349 | R13: =ROUND(①前提条件!$B$15,0) -> 1309260 | S13: =N13-Q13-R13 -> 322704 | U13: =IF(F13>=$H$46,1,0) -> 1
A14: 第3期 | B14: 2027-06 | C14: =F13 -> 123 | D14: 13 | E14: =ROUND(C14*①前提条件!$B$12,0) -> 4 | F14: =MIN(①前提条件!$B$13,C14+D14-E14) -> 132 | G14: 2 | H14: =ROUND((C14+F14)/2*①前提条件!$B$9,0) -> 1402500 | I14: =G14*①前提条件!$B$10 -> 108728 | J14: =D14*①前提条件!$B$11 -> 59085 | K14: =①前提条件!$B$18*①前提条件!$B$19 -> 62500 | L14: =①前提条件!$B$20*①前提条件!$B$21 -> 100000 | M14: =①前提条件!$B$22 -> 150000 | N14: =SUM(H14:M14) -> 1882813 | O14: =ROUND(M14*①前提条件!$B$23,0) -> 97500 | P14: =ROUND((N14-M14)*①前提条件!$B$24,0) -> 51984 | Q14: =O14+P14 -> 149484 | R14: =ROUND(①前提条件!$B$15,0) -> 1309260 | S14: =N14-Q14-R14 -> 424069 | U14: =IF(F14>=$H$46,1,0) -> 1
A15: 第3期 | B15: 2027-07 | C15: =F14 -> 132 | D15: 13 | E15: =ROUND(C15*①前提条件!$B$12,0) -> 4 | F15: =MIN(①前提条件!$B$13,C15+D15-E15) -> 141 | G15: 2 | H15: =ROUND((C15+F15)/2*①前提条件!$B$9,0) -> 1501500 | I15: =G15*①前提条件!$B$10 -> 108728 | J15: =D15*①前提条件!$B$11 -> 59085 | K15: =①前提条件!$B$18*①前提条件!$B$19 -> 62500 | L15: =①前提条件!$B$20*①前提条件!$B$21 -> 100000 | M15: =①前提条件!$B$22 -> 150000 | N15: =SUM(H15:M15) -> 1981813 | O15: =ROUND(M15*①前提条件!$B$23,0) -> 97500 | P15: =ROUND((N15-M15)*①前提条件!$B$24,0) -> 54954 | Q15: =O15+P15 -> 152454 | R15: =ROUND(①前提条件!$B$15,0) -> 1309260 | S15: =N15-Q15-R15 -> 520099 | U15: =IF(F15>=$H$46,1,0) -> 1
A16: 第3期 | B16: 2027-08 | C16: =F15 -> 141 | D16: 13 | E16: =ROUND(C16*①前提条件!$B$12,0) -> 4 | F16: =MIN(①前提条件!$B$13,C16+D16-E16) -> 150 | G16: 2 | H16: =ROUND((C16+F16)/2*①前提条件!$B$9,0) -> 1600500 | I16: =G16*①前提条件!$B$10 -> 108728 | J16: =D16*①前提条件!$B$11 -> 59085 | K16: =①前提条件!$B$18*①前提条件!$B$19 -> 62500 | L16: =①前提条件!$B$20*①前提条件!$B$21 -> 100000 | M16: =①前提条件!$B$22 -> 150000 | N16: =SUM(H16:M16) -> 2080813 | O16: =ROUND(M16*①前提条件!$B$23,0) -> 97500 | P16: =ROUND((N16-M16)*①前提条件!$B$24,0) -> 57924 | Q16: =O16+P16 -> 155424 | R16: =ROUND(①前提条件!$B$15,0) -> 1309260 | S16: =N16-Q16-R16 -> 616129 | U16: =IF(F16>=$H$46,1,0) -> 1
A17: 第4期 | B17: 2027-09 | C17: =F16 -> 150 | D17: 13 | E17: =ROUND(C17*①前提条件!$B$12,0) -> 5 | F17: =MIN(①前提条件!$B$13,C17+D17-E17) -> 158 | G17: 3 | H17: =ROUND((C17+F17)/2*①前提条件!$B$9,0) -> 1694000 | I17: =G17*①前提条件!$B$10 -> 163092 | J17: =D17*①前提条件!$B$11 -> 59085 | K17: =①前提条件!$B$18*①前提条件!$B$19 -> 62500 | L17: =①前提条件!$B$20*①前提条件!$B$21 -> 100000 | M17: =①前提条件!$B$22 -> 150000 | N17: =SUM(H17:M17) -> 2228677 | O17: =ROUND(M17*①前提条件!$B$23,0) -> 97500 | P17: =ROUND((N17-M17)*①前提条件!$B$24,0) -> 62360 | Q17: =O17+P17 -> 159860 | R17: =ROUND(①前提条件!$B$16/12,0) -> 1500000 | S17: =N17-Q17-R17 -> 568817 | U17: =IF(F17>=$H$46,1,0) -> 1
A18: 第4期 | B18: 2027-10 | C18: =F17 -> 158 | D18: 13 | E18: =ROUND(C18*①前提条件!$B$12,0) -> 5 | F18: =MIN(①前提条件!$B$13,C18+D18-E18) -> 166 | G18: 3 | H18: =ROUND((C18+F18)/2*①前提条件!$B$9,0) -> 1782000 | I18: =G18*①前提条件!$B$10 -> 163092 | J18: =D18*①前提条件!$B$11 -> 59085 | K18: =①前提条件!$B$18*①前提条件!$B$19 -> 62500 | L18: =①前提条件!$B$20*①前提条件!$B$21 -> 100000 | M18: =①前提条件!$B$22 -> 150000 | N18: =SUM(H18:M18) -> 2316677 | O18: =ROUND(M18*①前提条件!$B$23,0) -> 97500 | P18: =ROUND((N18-M18)*①前提条件!$B$24,0) -> 65000 | Q18: =O18+P18 -> 162500 | R18: =ROUND(①前提条件!$B$16/12,0) -> 1500000 | S18: =N18-Q18-R18 -> 654177 | U18: =IF(F18>=$H$46,1,0) -> 1
A19: 第4期 | B19: 2027-11 | C19: =F18 -> 166 | D19: 13 | E19: =ROUND(C19*①前提条件!$B$12,0) -> 5 | F19: =MIN(①前提条件!$B$13,C19+D19-E19) -> 174 | G19: 3 | H19: =ROUND((C19+F19)/2*①前提条件!$B$9,0) -> 1870000 | I19: =G19*①前提条件!$B$10 -> 163092 | J19: =D19*①前提条件!$B$11 -> 59085 | K19: =①前提条件!$B$18*①前提条件!$B$19 -> 62500 | L19: =①前提条件!$B$20*①前提条件!$B$21 -> 100000 | M19: =①前提条件!$B$22 -> 150000 | N19: =SUM(H19:M19) -> 2404677 | O19: =ROUND(M19*①前提条件!$B$23,0) -> 97500 | P19: =ROUND((N19-M19)*①前提条件!$B$24,0) -> 67640 | Q19: =O19+P19 -> 165140 | R19: =ROUND(①前提条件!$B$16/12,0) -> 1500000 | S19: =N19-Q19-R19 -> 739537 | U19: =IF(F19>=$H$46,1,0) -> 1
A20: 第4期 | B20: 2027-12 | C20: =F19 -> 174 | D20: 13 | E20: =ROUND(C20*①前提条件!$B$12,0) -> 5 | F20: =MIN(①前提条件!$B$13,C20+D20-E20) -> 180 | G20: 3 | H20: =ROUND((C20+F20)/2*①前提条件!$B$9,0) -> 1947000 | I20: =G20*①前提条件!$B$10 -> 163092 | J20: =D20*①前提条件!$B$11 -> 59085 | K20: =①前提条件!$B$18*①前提条件!$B$19 -> 62500 | L20: =①前提条件!$B$20*①前提条件!$B$21 -> 100000 | M20: =①前提条件!$B$22 -> 150000 | N20: =SUM(H20:M20) -> 2481677 | O20: =ROUND(M20*①前提条件!$B$23,0) -> 97500 | P20: =ROUND((N20-M20)*①前提条件!$B$24,0) -> 69950 | Q20: =O20+P20 -> 167450 | R20: =ROUND(①前提条件!$B$16/12,0) -> 1500000 | S20: =N20-Q20-R20 -> 814227 | U20: =IF(F20>=$H$46,1,0) -> 1
A21: 第4期 | B21: 2028-01 | C21: =F20 -> 180 | D21: 13 | E21: =ROUND(C21*①前提条件!$B$12,0) -> 5 | F21: =MIN(①前提条件!$B$13,C21+D21-E21) -> 180 | G21: 3 | H21: =ROUND((C21+F21)/2*①前提条件!$B$9,0) -> 1980000 | I21: =G21*①前提条件!$B$10 -> 163092 | J21: =D21*①前提条件!$B$11 -> 59085 | K21: =①前提条件!$B$18*①前提条件!$B$19 -> 62500 | L21: =①前提条件!$B$20*①前提条件!$B$21 -> 100000 | M21: =①前提条件!$B$22 -> 150000 | N21: =SUM(H21:M21) -> 2514677 | O21: =ROUND(M21*①前提条件!$B$23,0) -> 97500 | P21: =ROUND((N21-M21)*①前提条件!$B$24,0) -> 70940 | Q21: =O21+P21 -> 168440 | R21: =ROUND(①前提条件!$B$16/12,0) -> 1500000 | S21: =N21-Q21-R21 -> 846237 | U21: =IF(F21>=$H$46,1,0) -> 1
A22: 第4期 | B22: 2028-02 | C22: =F21 -> 180 | D22: 13 | E22: =ROUND(C22*①前提条件!$B$12,0) -> 5 | F22: =MIN(①前提条件!$B$13,C22+D22-E22) -> 180 | G22: 3 | H22: =ROUND((C22+F22)/2*①前提条件!$B$9,0) -> 1980000 | I22: =G22*①前提条件!$B$10 -> 163092 | J22: =D22*①前提条件!$B$11 -> 59085 | K22: =①前提条件!$B$18*①前提条件!$B$19 -> 62500 | L22: =①前提条件!$B$20*①前提条件!$B$21 -> 100000 | M22: =①前提条件!$B$22 -> 150000 | N22: =SUM(H22:M22) -> 2514677 | O22: =ROUND(M22*①前提条件!$B$23,0) -> 97500 | P22: =ROUND((N22-M22)*①前提条件!$B$24,0) -> 70940 | Q22: =O22+P22 -> 168440 | R22: =ROUND(①前提条件!$B$16/12,0) -> 1500000 | S22: =N22-Q22-R22 -> 846237 | U22: =IF(F22>=$H$46,1,0) -> 1
A23: 第4期 | B23: 2028-03 | C23: =F22 -> 180 | D23: 13 | E23: =ROUND(C23*①前提条件!$B$12,0) -> 5 | F23: =MIN(①前提条件!$B$13,C23+D23-E23) -> 180 | G23: 4 | H23: =ROUND((C23+F23)/2*①前提条件!$B$9,0) -> 1980000 | I23: =G23*①前提条件!$B$10 -> 217456 | J23: =D23*①前提条件!$B$11 -> 59085 | K23: =①前提条件!$B$18*①前提条件!$B$19 -> 62500 | L23: =①前提条件!$B$20*①前提条件!$B$21 -> 100000 | M23: =①前提条件!$B$22 -> 150000 | N23: =SUM(H23:M23) -> 2569041 | O23: =ROUND(M23*①前提条件!$B$23,0) -> 97500 | P23: =ROUND((N23-M23)*①前提条件!$B$24,0) -> 72571 | Q23: =O23+P23 -> 170071 | R23: =ROUND(①前提条件!$B$16/12,0) -> 1500000 | S23: =N23-Q23-R23 -> 898970 | U23: =IF(F23>=$H$46,1,0) -> 1
A24: 第4期 | B24: 2028-04 | C24: =F23 -> 180 | D24: 13 | E24: =ROUND(C24*①前提条件!$B$12,0) -> 5 | F24: =MIN(①前提条件!$B$13,C24+D24-E24) -> 180 | G24: 4 | H24: =ROUND((C24+F24)/2*①前提条件!$B$9,0) -> 1980000 | I24: =G24*①前提条件!$B$10 -> 217456 | J24: =D24*①前提条件!$B$11 -> 59085 | K24: =①前提条件!$B$18*①前提条件!$B$19 -> 62500 | L24: =①前提条件!$B$20*①前提条件!$B$21 -> 100000 | M24: =①前提条件!$B$22 -> 150000 | N24: =SUM(H24:M24) -> 2569041 | O24: =ROUND(M24*①前提条件!$B$23,0) -> 97500 | P24: =ROUND((N24-M24)*①前提条件!$B$24,0) -> 72571 | Q24: =O24+P24 -> 170071 | R24: =ROUND(①前提条件!$B$16/12,0) -> 1500000 | S24: =N24-Q24-R24 -> 898970 | U24: =IF(F24>=$H$46,1,0) -> 1
A25: 第4期 | B25: 2028-05 | C25: =F24 -> 180 | D25: 13 | E25: =ROUND(C25*①前提条件!$B$12,0) -> 5 | F25: =MIN(①前提条件!$B$13,C25+D25-E25) -> 180 | G25: 4 | H25: =ROUND((C25+F25)/2*①前提条件!$B$9,0) -> 1980000 | I25: =G25*①前提条件!$B$10 -> 217456 | J25: =D25*①前提条件!$B$11 -> 59085 | K25: =①前提条件!$B$18*①前提条件!$B$19 -> 62500 | L25: =①前提条件!$B$20*①前提条件!$B$21 -> 100000 | M25: =①前提条件!$B$22 -> 150000 | N25: =SUM(H25:M25) -> 2569041 | O25: =ROUND(M25*①前提条件!$B$23,0) -> 97500 | P25: =ROUND((N25-M25)*①前提条件!$B$24,0) -> 72571 | Q25: =O25+P25 -> 170071 | R25: =ROUND(①前提条件!$B$16/12,0) -> 1500000 | S25: =N25-Q25-R25 -> 898970 | U25: =IF(F25>=$H$46,1,0) -> 1
A26: 第4期 | B26: 2028-06 | C26: =F25 -> 180 | D26: 13 | E26: =ROUND(C26*①前提条件!$B$12,0) -> 5 | F26: =MIN(①前提条件!$B$13,C26+D26-E26) -> 180 | G26: 4 | H26: =ROUND((C26+F26)/2*①前提条件!$B$9,0) -> 1980000 | I26: =G26*①前提条件!$B$10 -> 217456 | J26: =D26*①前提条件!$B$11 -> 59085 | K26: =①前提条件!$B$18*①前提条件!$B$19 -> 62500 | L26: =①前提条件!$B$20*①前提条件!$B$21 -> 100000 | M26: =①前提条件!$B$22 -> 150000 | N26: =SUM(H26:M26) -> 2569041 | O26: =ROUND(M26*①前提条件!$B$23,0) -> 97500 | P26: =ROUND((N26-M26)*①前提条件!$B$24,0) -> 72571 | Q26: =O26+P26 -> 170071 | R26: =ROUND(①前提条件!$B$16/12,0) -> 1500000 | S26: =N26-Q26-R26 -> 898970 | U26: =IF(F26>=$H$46,1,0) -> 1
A27: 第4期 | B27: 2028-07 | C27: =F26 -> 180 | D27: 13 | E27: =ROUND(C27*①前提条件!$B$12,0) -> 5 | F27: =MIN(①前提条件!$B$13,C27+D27-E27) -> 180 | G27: 4 | H27: =ROUND((C27+F27)/2*①前提条件!$B$9,0) -> 1980000 | I27: =G27*①前提条件!$B$10 -> 217456 | J27: =D27*①前提条件!$B$11 -> 59085 | K27: =①前提条件!$B$18*①前提条件!$B$19 -> 62500 | L27: =①前提条件!$B$20*①前提条件!$B$21 -> 100000 | M27: =①前提条件!$B$22 -> 150000 | N27: =SUM(H27:M27) -> 2569041 | O27: =ROUND(M27*①前提条件!$B$23,0) -> 97500 | P27: =ROUND((N27-M27)*①前提条件!$B$24,0) -> 72571 | Q27: =O27+P27 -> 170071 | R27: =ROUND(①前提条件!$B$16/12,0) -> 1500000 | S27: =N27-Q27-R27 -> 898970 | U27: =IF(F27>=$H$46,1,0) -> 1
A28: 第4期 | B28: 2028-08 | C28: =F27 -> 180 | D28: 13 | E28: =ROUND(C28*①前提条件!$B$12,0) -> 5 | F28: =MIN(①前提条件!$B$13,C28+D28-E28) -> 180 | G28: 4 | H28: =ROUND((C28+F28)/2*①前提条件!$B$9,0) -> 1980000 | I28: =G28*①前提条件!$B$10 -> 217456 | J28: =D28*①前提条件!$B$11 -> 59085 | K28: =①前提条件!$B$18*①前提条件!$B$19 -> 62500 | L28: =①前提条件!$B$20*①前提条件!$B$21 -> 100000 | M28: =①前提条件!$B$22 -> 150000 | N28: =SUM(H28:M28) -> 2569041 | O28: =ROUND(M28*①前提条件!$B$23,0) -> 97500 | P28: =ROUND((N28-M28)*①前提条件!$B$24,0) -> 72571 | Q28: =O28+P28 -> 170071 | R28: =ROUND(①前提条件!$B$16/12,0) -> 1500000 | S28: =N28-Q28-R28 -> 898970 | U28: =IF(F28>=$H$46,1,0) -> 1
A29: 第5期 | B29: 2028-09 | C29: =F28 -> 180 | D29: 10 | E29: =ROUND(C29*①前提条件!$B$12,0) -> 5 | F29: =MIN(①前提条件!$B$14,C29+D29-E29) -> 185 | G29: 4 | H29: =ROUND((C29+F29)/2*①前提条件!$B$9,0) -> 2007500 | I29: =G29*①前提条件!$B$10 -> 217456 | J29: =D29*①前提条件!$B$11 -> 45450 | K29: =①前提条件!$B$18*①前提条件!$B$19 -> 62500 | L29: =①前提条件!$B$20*①前提条件!$B$21 -> 100000 | M29: =①前提条件!$B$22 -> 150000 | N29: =SUM(H29:M29) -> 2582906 | O29: =ROUND(M29*①前提条件!$B$23,0) -> 97500 | P29: =ROUND((N29-M29)*①前提条件!$B$24,0) -> 72987 | Q29: =O29+P29 -> 170487 | R29: =ROUND(①前提条件!$B$17/12,0) -> 1666667 | S29: =N29-Q29-R29 -> 745752 | U29: =IF(F29>=$H$46,1,0) -> 1
A30: 第5期 | B30: 2028-10 | C30: =F29 -> 185 | D30: 10 | E30: =ROUND(C30*①前提条件!$B$12,0) -> 6 | F30: =MIN(①前提条件!$B$14,C30+D30-E30) -> 189 | G30: 4 | H30: =ROUND((C30+F30)/2*①前提条件!$B$9,0) -> 2057000 | I30: =G30*①前提条件!$B$10 -> 217456 | J30: =D30*①前提条件!$B$11 -> 45450 | K30: =①前提条件!$B$18*①前提条件!$B$19 -> 62500 | L30: =①前提条件!$B$20*①前提条件!$B$21 -> 100000 | M30: =①前提条件!$B$22 -> 150000 | N30: =SUM(H30:M30) -> 2632406 | O30: =ROUND(M30*①前提条件!$B$23,0) -> 97500 | P30: =ROUND((N30-M30)*①前提条件!$B$24,0) -> 74472 | Q30: =O30+P30 -> 171972 | R30: =ROUND(①前提条件!$B$17/12,0) -> 1666667 | S30: =N30-Q30-R30 -> 793767 | U30: =IF(F30>=$H$46,1,0) -> 1
A31: 第5期 | B31: 2028-11 | C31: =F30 -> 189 | D31: 10 | E31: =ROUND(C31*①前提条件!$B$12,0) -> 6 | F31: =MIN(①前提条件!$B$14,C31+D31-E31) -> 193 | G31: 4 | H31: =ROUND((C31+F31)/2*①前提条件!$B$9,0) -> 2101000 | I31: =G31*①前提条件!$B$10 -> 217456 | J31: =D31*①前提条件!$B$11 -> 45450 | K31: =①前提条件!$B$18*①前提条件!$B$19 -> 62500 | L31: =①前提条件!$B$20*①前提条件!$B$21 -> 100000 | M31: =①前提条件!$B$22 -> 150000 | N31: =SUM(H31:M31) -> 2676406 | O31: =ROUND(M31*①前提条件!$B$23,0) -> 97500 | P31: =ROUND((N31-M31)*①前提条件!$B$24,0) -> 75792 | Q31: =O31+P31 -> 173292 | R31: =ROUND(①前提条件!$B$17/12,0) -> 1666667 | S31: =N31-Q31-R31 -> 836447 | U31: =IF(F31>=$H$46,1,0) -> 1
A32: 第5期 | B32: 2028-12 | C32: =F31 -> 193 | D32: 10 | E32: =ROUND(C32*①前提条件!$B$12,0) -> 6 | F32: =MIN(①前提条件!$B$14,C32+D32-E32) -> 197 | G32: 4 | H32: =ROUND((C32+F32)/2*①前提条件!$B$9,0) -> 2145000 | I32: =G32*①前提条件!$B$10 -> 217456 | J32: =D32*①前提条件!$B$11 -> 45450 | K32: =①前提条件!$B$18*①前提条件!$B$19 -> 62500 | L32: =①前提条件!$B$20*①前提条件!$B$21 -> 100000 | M32: =①前提条件!$B$22 -> 150000 | N32: =SUM(H32:M32) -> 2720406 | O32: =ROUND(M32*①前提条件!$B$23,0) -> 97500 | P32: =ROUND((N32-M32)*①前提条件!$B$24,0) -> 77112 | Q32: =O32+P32 -> 174612 | R32: =ROUND(①前提条件!$B$17/12,0) -> 1666667 | S32: =N32-Q32-R32 -> 879127 | U32: =IF(F32>=$H$46,1,0) -> 1
A33: 第5期 | B33: 2029-01 | C33: =F32 -> 197 | D33: 10 | E33: =ROUND(C33*①前提条件!$B$12,0) -> 6 | F33: =MIN(①前提条件!$B$14,C33+D33-E33) -> 201 | G33: 4 | H33: =ROUND((C33+F33)/2*①前提条件!$B$9,0) -> 2189000 | I33: =G33*①前提条件!$B$10 -> 217456 | J33: =D33*①前提条件!$B$11 -> 45450 | K33: =①前提条件!$B$18*①前提条件!$B$19 -> 62500 | L33: =①前提条件!$B$20*①前提条件!$B$21 -> 100000 | M33: =①前提条件!$B$22 -> 150000 | N33: =SUM(H33:M33) -> 2764406 | O33: =ROUND(M33*①前提条件!$B$23,0) -> 97500 | P33: =ROUND((N33-M33)*①前提条件!$B$24,0) -> 78432 | Q33: =O33+P33 -> 175932 | R33: =ROUND(①前提条件!$B$17/12,0) -> 1666667 | S33: =N33-Q33-R33 -> 921807 | U33: =IF(F33>=$H$46,1,0) -> 1
A34: 第5期 | B34: 2029-02 | C34: =F33 -> 201 | D34: 10 | E34: =ROUND(C34*①前提条件!$B$12,0) -> 6 | F34: =MIN(①前提条件!$B$14,C34+D34-E34) -> 205 | G34: 4 | H34: =ROUND((C34+F34)/2*①前提条件!$B$9,0) -> 2233000 | I34: =G34*①前提条件!$B$10 -> 217456 | J34: =D34*①前提条件!$B$11 -> 45450 | K34: =①前提条件!$B$18*①前提条件!$B$19 -> 62500 | L34: =①前提条件!$B$20*①前提条件!$B$21 -> 100000 | M34: =①前提条件!$B$22 -> 150000 | N34: =SUM(H34:M34) -> 2808406 | O34: =ROUND(M34*①前提条件!$B$23,0) -> 97500 | P34: =ROUND((N34-M34)*①前提条件!$B$24,0) -> 79752 | Q34: =O34+P34 -> 177252 | R34: =ROUND(①前提条件!$B$17/12,0) -> 1666667 | S34: =N34-Q34-R34 -> 964487 | U34: =IF(F34>=$H$46,1,0) -> 1
A35: 第5期 | B35: 2029-03 | C35: =F34 -> 205 | D35: 10 | E35: =ROUND(C35*①前提条件!$B$12,0) -> 6 | F35: =MIN(①前提条件!$B$14,C35+D35-E35) -> 209 | G35: 4 | H35: =ROUND((C35+F35)/2*①前提条件!$B$9,0) -> 2277000 | I35: =G35*①前提条件!$B$10 -> 217456 | J35: =D35*①前提条件!$B$11 -> 45450 | K35: =①前提条件!$B$18*①前提条件!$B$19 -> 62500 | L35: =①前提条件!$B$20*①前提条件!$B$21 -> 100000 | M35: =①前提条件!$B$22 -> 150000 | N35: =SUM(H35:M35) -> 2852406 | O35: =ROUND(M35*①前提条件!$B$23,0) -> 97500 | P35: =ROUND((N35-M35)*①前提条件!$B$24,0) -> 81072 | Q35: =O35+P35 -> 178572 | R35: =ROUND(①前提条件!$B$17/12,0) -> 1666667 | S35: =N35-Q35-R35 -> 1007167 | U35: =IF(F35>=$H$46,1,0) -> 1
A36: 第5期 | B36: 2029-04 | C36: =F35 -> 209 | D36: 10 | E36: =ROUND(C36*①前提条件!$B$12,0) -> 6 | F36: =MIN(①前提条件!$B$14,C36+D36-E36) -> 213 | G36: 4 | H36: =ROUND((C36+F36)/2*①前提条件!$B$9,0) -> 2321000 | I36: =G36*①前提条件!$B$10 -> 217456 | J36: =D36*①前提条件!$B$11 -> 45450 | K36: =①前提条件!$B$18*①前提条件!$B$19 -> 62500 | L36: =①前提条件!$B$20*①前提条件!$B$21 -> 100000 | M36: =①前提条件!$B$22 -> 150000 | N36: =SUM(H36:M36) -> 2896406 | O36: =ROUND(M36*①前提条件!$B$23,0) -> 97500 | P36: =ROUND((N36-M36)*①前提条件!$B$24,0) -> 82392 | Q36: =O36+P36 -> 179892 | R36: =ROUND(①前提条件!$B$17/12,0) -> 1666667 | S36: =N36-Q36-R36 -> 1049847 | U36: =IF(F36>=$H$46,1,0) -> 1
A37: 第5期 | B37: 2029-05 | C37: =F36 -> 213 | D37: 10 | E37: =ROUND(C37*①前提条件!$B$12,0) -> 6 | F37: =MIN(①前提条件!$B$14,C37+D37-E37) -> 217 | G37: 4 | H37: =ROUND((C37+F37)/2*①前提条件!$B$9,0) -> 2365000 | I37: =G37*①前提条件!$B$10 -> 217456 | J37: =D37*①前提条件!$B$11 -> 45450 | K37: =①前提条件!$B$18*①前提条件!$B$19 -> 62500 | L37: =①前提条件!$B$20*①前提条件!$B$21 -> 100000 | M37: =①前提条件!$B$22 -> 150000 | N37: =SUM(H37:M37) -> 2940406 | O37: =ROUND(M37*①前提条件!$B$23,0) -> 97500 | P37: =ROUND((N37-M37)*①前提条件!$B$24,0) -> 83712 | Q37: =O37+P37 -> 181212 | R37: =ROUND(①前提条件!$B$17/12,0) -> 1666667 | S37: =N37-Q37-R37 -> 1092527 | U37: =IF(F37>=$H$46,1,0) -> 1
A38: 第5期 | B38: 2029-06 | C38: =F37 -> 217 | D38: 10 | E38: =ROUND(C38*①前提条件!$B$12,0) -> 7 | F38: =MIN(①前提条件!$B$14,C38+D38-E38) -> 220 | G38: 4 | H38: =ROUND((C38+F38)/2*①前提条件!$B$9,0) -> 2403500 | I38: =G38*①前提条件!$B$10 -> 217456 | J38: =D38*①前提条件!$B$11 -> 45450 | K38: =①前提条件!$B$18*①前提条件!$B$19 -> 62500 | L38: =①前提条件!$B$20*①前提条件!$B$21 -> 100000 | M38: =①前提条件!$B$22 -> 150000 | N38: =SUM(H38:M38) -> 2978906 | O38: =ROUND(M38*①前提条件!$B$23,0) -> 97500 | P38: =ROUND((N38-M38)*①前提条件!$B$24,0) -> 84867 | Q38: =O38+P38 -> 182367 | R38: =ROUND(①前提条件!$B$17/12,0) -> 1666667 | S38: =N38-Q38-R38 -> 1129872 | U38: =IF(F38>=$H$46,1,0) -> 1
A39: 第5期 | B39: 2029-07 | C39: =F38 -> 220 | D39: 10 | E39: =ROUND(C39*①前提条件!$B$12,0) -> 7 | F39: =MIN(①前提条件!$B$14,C39+D39-E39) -> 220 | G39: 4 | H39: =ROUND((C39+F39)/2*①前提条件!$B$9,0) -> 2420000 | I39: =G39*①前提条件!$B$10 -> 217456 | J39: =D39*①前提条件!$B$11 -> 45450 | K39: =①前提条件!$B$18*①前提条件!$B$19 -> 62500 | L39: =①前提条件!$B$20*①前提条件!$B$21 -> 100000 | M39: =①前提条件!$B$22 -> 150000 | N39: =SUM(H39:M39) -> 2995406 | O39: =ROUND(M39*①前提条件!$B$23,0) -> 97500 | P39: =ROUND((N39-M39)*①前提条件!$B$24,0) -> 85362 | Q39: =O39+P39 -> 182862 | R39: =ROUND(①前提条件!$B$17/12,0) -> 1666667 | S39: =N39-Q39-R39 -> 1145877 | U39: =IF(F39>=$H$46,1,0) -> 1
A40: 第5期 | B40: 2029-08 | C40: =F39 -> 220 | D40: 10 | E40: =ROUND(C40*①前提条件!$B$12,0) -> 7 | F40: =MIN(①前提条件!$B$14,C40+D40-E40) -> 220 | G40: 4 | H40: =ROUND((C40+F40)/2*①前提条件!$B$9,0) -> 2420000 | I40: =G40*①前提条件!$B$10 -> 217456 | J40: =D40*①前提条件!$B$11 -> 45450 | K40: =①前提条件!$B$18*①前提条件!$B$19 -> 62500 | L40: =①前提条件!$B$20*①前提条件!$B$21 -> 100000 | M40: =①前提条件!$B$22 -> 150000 | N40: =SUM(H40:M40) -> 2995406 | O40: =ROUND(M40*①前提条件!$B$23,0) -> 97500 | P40: =ROUND((N40-M40)*①前提条件!$B$24,0) -> 85362 | Q40: =O40+P40 -> 182862 | R40: =ROUND(①前提条件!$B$17/12,0) -> 1666667 | S40: =N40-Q40-R40 -> 1145877 | U40: =IF(F40>=$H$46,1,0) -> 1
A41: 第3期 合計 | D41: =SUM(D5:D16) -> 179 | F41: =F16 -> 150 | H41: =SUM(H5:H16) -> 11231000 | I41: =SUM(I5:I16) -> 978552 | J41: =SUM(J5:J16) -> 813555 | K41: =SUM(K5:K16) -> 750000 | L41: =SUM(L5:L16) -> 1200000 | M41: =SUM(M5:M16) -> 1800000 | N41: =SUM(N5:N16) -> 16773107 | O41: =SUM(O5:O16) -> 1170000 | ... S41: =SUM(S5:S16) -> -557204
...

Sheet ③3か年収支計画
A1: ③ 株式会社YOZAN 3か年収支計画（全社）
A2: 第1期・第2期は実績（税理士作成 残高試算表）。第2期の8月分と第3期以降は計画値です。単位：円
A4: 区分 | B4: 第1期 実績 2024/9〜2025/8 | C4: 第2期 実績（11か月） 2025/9〜2026/7 | D4: 第2期 見込（通期） 2025/9〜2026/8 | E4: 第3期 計画 2026/9〜2027/8 | F4: 第4期 計画 2027/9〜2028/8 | G4: 第5期 計画 2028/9〜2029/8 | H4: 備考
A5: 【売上高】
A6: 既存事業（GOLF WING 宝塚 受託運営＋キャディ派遣） | B6: 7927283 | C6: 24979520 | D6: =①前提条件!$B$26 -> 27250000 | E6: =ROUND(D6*(1+①前提条件!$B$27),0) -> 28067500 | F6: =ROUND(E6*(1+①前提条件!$B$27),0) -> 28909525 | G6: =ROUND(F6*(1+①前提条件!$B$27),0) -> 29776811 | H6: 宝塚は㈱ファインが必要経費とロイヤリティを控除した純額が当社売上となる（純額率 約44%）。第2期見込＝11か月実績＋8月分の月商換算
A7: FRANK GOLF 姫路（直営2号店・2026年9月2日開業） | B7: 0 | C7: 0 | D7: 0 | E7: =②FRANK月次計画!N41 -> 16773107 | F7: =②FRANK月次計画!N42 -> 29875308 | G7: =②FRANK月次計画!N43 -> 33843872 | H7: ②シートの会員数計画から積み上げ。第2期は開業前のため売上ゼロ
A8: システム開発・外販 | B8: 0 | C8: 0 | D8: 0 | E8: =①前提条件!$B$29 -> 2400000 | F8: =①前提条件!$B$30 -> 4200000 | G8: =①前提条件!$B$31 -> 6000000 | H8: ホームページ制作・PRO SITE・店舗運営システム。2026年8月開始。第2期の売上は僅少のため既存事業に含む
A9: 売上高 合計 | B9: =B6 -> 7927283 | C9: =C6 -> 24979520 | D9: =D6 -> 27250000 | E9: =SUM(E6:E8) -> 47240607 | F9: =SUM(F6:F8) -> 62984833 | G9: =SUM(G6:G8) -> 69620683
A10: 前期比 | D10: =D9/B9 -> 3.4374955 | E10: =E9/D9 -> 1.7336003 | F10: =F9/E9 -> 1.3332774 | G10: =G9/F9 -> 1.1053563 | H10: 第2期は前期比3.4倍（月商換算）。第3期は2号店の通年寄与で1.8倍
A12: 【損益】
A13: 営業損益 | C13: -1138361 | D13: =C13+①前提条件!$B$60 -> -1568361 | E13: =④部門別営業損益!E10 -> 1430075 | F13: =④部門別営業損益!F10 -> 13033052 | G13: =④部門別営業損益!G10 -> 15212554 | H13: 第2期見込は11か月実績の12か月換算。第3期以降は④部門別営業損益シートから
A14: 営業利益率 | C14: =C13/C9 -> -0.045571772 | D14: =D13/D9 -> -0.057554532 | E14: =E13/E9 -> 0.030272155 | F14: =F13/F9 -> 0.20692366 | G14: =G13/G9 -> 0.21850624
A15: 支払利息 | E15: =-ROUND(⑥返済計画!G6,0) -> -228912 | F15: =-ROUND(⑥返済計画!G7,0) -> -211948 | G15: =-ROUND(⑥返済計画!G8,0) -> -159075 | H15: 既存長期借入＋今回の700万円
A16: 経常損益 | D16: =D13 -> -1568361 | E16: =E13+E15 -> 1201163 | F16: =F13+F15 -> 12821104 | G16: =G13+G15 -> 15053479
A17: 法人税等 | E17: =-ROUND(MAX(0,E16+⑦純資産と債務超過!D8)*①前提条件!$B$57,0)-70000 -> -70000 | F17: =-ROUND(MAX(0,F16+⑦純資産と債務超過!E8)*①前提条件!$B$57,0)-70000 -> -4010314 | G17: =-ROUND(MAX(0,G16+⑦純資産と債務超過!F8)*①前提条件!$B$57,0)-70000 -> -5037648 | H17: 繰越欠損金を控除したうえで実効税率33%。均等割70,000円を加算
A18: 当期純損益 | B18: -576759 | C18: -1005162 | D18: =C18+①前提条件!$B$60 -> -1435162 | E18: =E16+E17 -> 1131163 | F18: =F16+F17 -> 8810790 | G18: =G16+G17 -> 10015831 | H18: 第1期は純資産▲276,759＝資本金300,000＋繰越利益剰余金▲576,759から導出。第2期11か月は純資産の期中増減から導出
A20: 【資金・財務】
A21: 減価償却費 | E21: =①前提条件!$B$56 -> 700000 | F21: =①前提条件!$B$56 -> 700000 | G21: =①前提条件!$B$56 -> 700000
A22: 簡易キャッシュフロー（当期純損益＋減価償却費） | D22: =D18 -> -1435162 | E22: =E18+E21 -> 1831163 | F22: =F18+F21 -> 9510790 | G22: =G18+G21 -> 10715831
A23: 年間元金返済額（既存＋今回） | E23: =⑥返済計画!H6 -> 1656272 | F23: =⑥返済計画!H7 -> 2374224 | G23: =⑥返済計画!H8 -> 2374224
A24: 返済余力（簡易CF ÷ 年間元金返済額） | E24: =E22/E23 -> 1.1055932 | F24: =F22/F23 -> 4.005852 | G24: =G22/G23 -> 4.5134035 | H24: 1.0倍を超えていれば営業活動で返済がまかなえる
A25: 期末 純資産 | B25: -276759 | C25: -1281921 | D25: =⑦純資産と債務超過!C6 -> -1711921 | E25: =⑦純資産と債務超過!D6 -> -580758 | F25: =⑦純資産と債務超過!E6 -> 8230032 | G25: =⑦純資産と債務超過!F6 -> 18245863 | H25: 第3期に債務超過を解消する計画

Sheet ④部門別営業損益
A1: ④ 部門別 営業損益（第2期実績 → 第5期計画）
A2: 第2期は 全社資金繰り表 2026-08-17「4区分の収支」（保証協会へ2026年9月4日提出済）の月次平均を年換算したもの。単位：円
A4: 部門 | B4: （参考） 月次平均 第2期 | C4: 第2期 年換算 （実績ベース） | E4: 第3期 計画 2026/9〜2027/8 | F4: 第4期 計画 2027/9〜2028/8 | G4: 第5期 計画 2028/9〜2029/8 | H4: 備考
A5: キャディ派遣 | B5: =ROUND(①前提条件!$B$34/12,0) -> 486894 | C5: =①前提条件!$B$34 -> 5842728 | E5: =①前提条件!$B$41 -> 6400000 | F5: =①前提条件!$B$42 -> 7000000 | G5: =①前提条件!$B$43 -> 7500000 | H5: 当期実績 売上10,956,460円／原価7,770,764円（Caddy OS台帳）。取引ゴルフ場7社→9社へ。林の固定給270,000円/月が損益分岐点
A6: GOLF WING 宝塚（受託運営） | B6: =ROUND(①前提条件!$B$35/12,0) -> 484318 | C6: =①前提条件!$B$35 -> 5811816 | E6: =①前提条件!$B$44 -> 6000000 | F6: =①前提条件!$B$45 -> 6200000 | G6: =①前提条件!$B$46 -> 6400000 | H6: ㈱ファインからの受託運営。精算後の入金ベース。課金会員 前期末144名→当期末218名（計画200名に対し達成率109%）
A7: FRANK GOLF 姫路（直営2号店） | B7: =ROUND(①前提条件!$B$36/12,0) -> -64182 | C7: =①前提条件!$B$36 -> -770184 | E7: =②FRANK月次計画!S41 -> -557204 | F7: =②FRANK月次計画!S42 -> 9863052 | G7: =②FRANK月次計画!S43 -> 11712554 | H7: 第2期は開業前の先行費用（地代家賃440,000円/月ほか）のみ。第3期以降は②FRANK月次計画シートから連動
A8: システム開発・外販 | C8: 0 | E8: =ROUND(①前提条件!$B$29*①前提条件!$B$32,0) -> 840000 | F8: =ROUND(①前提条件!$B$30*①前提条件!$B$32,0) -> 1470000 | G8: =ROUND(①前提条件!$B$31*①前提条件!$B$32,0) -> 2100000 | H8: 売上高（①前提条件）×営業利益率35%。自社開発のため原価は工数中心
A9: 本社・共通 | B9: =ROUND(①前提条件!$B$37/12,0) -> -1037727 | C9: =①前提条件!$B$37 -> -12452721 | E9: =①前提条件!$B$37+①前提条件!$B$38 -> -11252721 | F9: =①前提条件!$B$39 -> -11500000 | G9: =①前提条件!$B$40 -> -12500000 | H9: 役員報酬・システム・本部経費。第3期は経費削減（月100,000円＝年1,200,000円）の実行を織り込む。第4期は管理部門1名増
A10: 営業損益 合計 | B10: =SUM(B5:B9) -> -130697 | C10: =SUM(C5:C9) -> -1568361 | E10: =SUM(E5:E9) -> 1430075 | F10: =SUM(F5:F9) -> 13033052 | G10: =SUM(G5:G9) -> 15212554 | H10: ③3か年収支計画シートの「営業損益」はこの行を参照している
A12: （参考）事業4部門 小計 | B12: =SUM(B5:B8) -> 907030 | C12: =SUM(C5:C8) -> 10884360 | E12: =SUM(E5:E8) -> 12682796 | F12: =SUM(F5:F8) -> 24533052 | G12: =SUM(G5:G8) -> 27712554 | H12: 本社・共通を除いた、店舗と事業そのものの収益力。第2期でもすでに年間+1,088万円の黒字
A14: ■ 読み方
A15: ・第2期の赤字の発生源は本社・共通です。事業4部門（キャディ・宝塚・FRANK・システム）は第2期の時点ですでに合計で黒字です。
A16: ・第2期の「本社・共通」▲12,126,208円は、資金繰り表の月次平均▲928,473円（年換算▲11,141,676円）に対し、会計上の営業損益
A17: （11か月▲1,138,361円→12か月換算▲1,241,848円）と一致させるために置いた金額です。差額984,532円は決算確定時に精査します。
A18: ・第3期に営業損益が黒字転換する主因は、FRANK GOLF 姫路が開業1年目を通年で寄与すること、および経費削減月100,000円の実行です。

Sheet ⑤資金繰り計画
A1: ⑤ 資金繰り計画（2026年9月〜2028年8月・24か月）
A2: 期首現預金 5,021,382円（2026年9月1日）。今回の700万円を2026年10月に実行する前提。右端に、調達しなかった場合の残高を並べています。単位：円
A4: 年月 | B4: 期首残高 | C4: 営業損益 （月次） | D4: 減価償却 （戻し） | E4: 法人税等 | F4: 社会保険 2回納付月 | G4: その他税・ 一時支出 | H4: 未払金の 圧縮 | I4: 借入 実行 | J4: 元金返済 | K4: 支払利息 | L4: カード分割 （エポス） | M4: 増減 計 | N4: 期末残高 | P4: （参考） 無調達の場合
A5: 2026-09 | B5: =①前提条件!$B$58 -> 5021382 | C5: =ROUND(②FRANK月次計画!S5+(④部門別営業損益!E5+④部門別営業損益!E6+④部門別営業損益!E8+④部門別営業損益!E9)/12,0) -> -666435 | D5: =ROUND(①前提条件!$B$56/12,0) -> 58333 | E5: =ROUND(③3か年収支計画!E17/12,0) -> -5833 | F5: 0 | G5: -100000 | H5: 0 | I5: 0 | J5: =-(0+⑥返済計画!J21) -> -108108 | K5: =-(0+⑥返済計画!K21) -> -8008 | L5: =-①前提条件!$B$55 -> -289050 | M5: =SUM(C5:L5) -> -1119101 | N5: =B5+M5 -> 3902281 | P5: =①前提条件!$B$58+SUM(C5:H5)+⑥返済計画!J21*-1+⑥返済計画!K21*-1+L5 -> 3902281
A6: 2026-10 | B6: =N5 -> 3902281 | C6: =ROUND(②FRANK月次計画!S6+(④部門別営業損益!E5+④部門別営業損益!E6+④部門別営業損益!E8+④部門別営業損益!E9)/12,0) -> -505235 | D6: =ROUND(①前提条件!$B$56/12,0) -> 58333 | E6: =ROUND(③3か年収支計画!E17/12,0) -> -5833 | F6: 0 | G6: -100000 | H6: -213083 | I6: =①前提条件!$B$48 -> 7000000 | J6: =-(0+⑥返済計画!J22) -> -108108 | K6: =-(0+⑥返済計画!K22) -> -7828 | L6: =-①前提条件!$B$55 -> -289050 | M6: =SUM(C6:L6) -> 5829196 | N6: =B6+M6 -> 9731477 | P6: =P5+SUM(C6:H6)+⑥返済計画!J22*-1+⑥返済計画!K22*-1+L6 -> 2731477
A7: 2026-11 | B7: =N6 -> 9731477 | C7: =ROUND(②FRANK月次計画!S7+(④部門別営業損益!E5+④部門別営業損益!E6+④部門別営業損益!E8+④部門別営業損益!E9)/12,0) -> -355855 | D7: =ROUND(①前提条件!$B$56/12,0) -> 58333 | E7: =ROUND(③3か年収支計画!E17/12,0) -> -5833 | F7: -355551 | G7: -100000 | H7: -213083 | I7: 0 | J7: =-(⑥返済計画!D21+⑥返済計画!J23) -> -108108 | K7: =-(⑥返済計画!E21+⑥返済計画!K23) -> -22231 | L7: =-①前提条件!$B$55 -> -289050 | M7: =SUM(C7:L7) -> -1391378 | N7: =B7+M7 -> 8340099 | P7: =P6+SUM(C7:H7)+⑥返済計画!J23*-1+⑥返済計画!K23*-1+L7 -> 1354682
A8: 2026-12 | B8: =N7 -> 8340099 | C8: =ROUND(②FRANK月次計画!S8+(④部門別営業損益!E5+④部門別営業損益!E6+④部門別営業損益!E8+④部門別営業損益!E9)/12,0) -> -211810 | D8: =ROUND(①前提条件!$B$56/12,0) -> 58333 | E8: =ROUND(③3か年収支計画!E17/12,0) -> -5833 | F8: 0 | G8: -100000 | H8: -213083 | I8: 0 | J8: =-(⑥返済計画!D22+⑥返済計画!J24) -> -108108 | K8: =-(⑥返済計画!E22+⑥返済計画!K24) -> -22050 | L8: =-①前提条件!$B$55 -> -289050 | M8: =SUM(C8:L8) -> -891601 | N8: =B8+M8 -> 7448498 | P8: =P7+SUM(C8:H8)+⑥返済計画!J24*-1+⑥返済計画!K24*-1+L8 -> 477664
A9: 2027-01 | B9: =N8 -> 7448498 | C9: =ROUND(②FRANK月次計画!S9+(④部門別営業損益!E5+④部門別営業損益!E6+④部門別営業損益!E8+④部門別営業損益!E9)/12,0) -> -73100 | D9: =ROUND(①前提条件!$B$56/12,0) -> 58333 | E9: =ROUND(③3か年収支計画!E17/12,0) -> -5833 | F9: 0 | G9: -100000 | H9: -213083 | I9: 0 | J9: =-(⑥返済計画!D23+⑥返済計画!J25) -> -108108 | K9: =-(⑥返済計画!E23+⑥返済計画!K25) -> -21870 | L9: =-①前提条件!$B$55 -> -289050 | M9: =SUM(C9:L9) -> -752711 | N9: =B9+M9 -> 6695787 | P9: =P8+SUM(C9:H9)+⑥返済計画!J25*-1+⑥返済計画!K25*-1+L9 -> -260464
A10: 2027-02 | B10: =N9 -> 6695787 | C10: =ROUND(②FRANK月次計画!S10+(④部門別営業損益!E5+④部門別営業損益!E6+④部門別営業損益!E8+④部門別営業損益!E9)/12,0) -> 65610 | D10: =ROUND(①前提条件!$B$56/12,0) -> 58333 | E10: =ROUND(③3か年収支計画!E17/12,0) -> -5833 | F10: 0 | G10: -100000 | H10: -213083 | I10: 0 | J10: =-(⑥返済計画!D24+⑥返済計画!J26) -> -108108 | K10: =-(⑥返済計画!E24+⑥返済計画!K26) -> -21690 | L10: =-①前提条件!$B$55 -> -289050 | M10: =SUM(C10:L10) -> -613821 | N10: =B10+M10 -> 6081966 | P10: =P9+SUM(C10:H10)+⑥返済計画!J26*-1+⑥返済計画!K26*-1+L10 -> -859702
A11: 2027-03 | B11: =N10 -> 6081966 | C11: =ROUND(②FRANK月次計画!S11+(④部門別営業損益!E5+④部門別営業損益!E6+④部門別営業損益!E8+④部門別営業損益!E9)/12,0) -> 251718 | D11: =ROUND(①前提条件!$B$56/12,0) -> 58333 | E11: =ROUND(③3か年収支計画!E17/12,0) -> -5833 | F11: -355551 | G11: -100000 | H11: -213083 | I11: 0 | J11: =-(⑥返済計画!D25+⑥返済計画!J27) -> -108108 | K11: =-(⑥返済計画!E25+⑥返済計画!K27) -> -21510 | L11: =-①前提条件!$B$55 -> -289050 | M11: =SUM(C11:L11) -> -783084 | N11: =B11+M11 -> 5298882 | P11: =P10+SUM(C11:H11)+⑥返済計画!J27*-1+⑥返済計画!K27*-1+L11 -> -1628203
A12: 2027-04 | B12: =N11 -> 5298882 | C12: =ROUND(②FRANK月次計画!S12+(④部門別営業損益!E5+④部門別営業損益!E6+④部門別営業損益!E8+④部門別営業損益!E9)/12,0) -> 379758 | D12: =ROUND(①前提条件!$B$56/12,0) -> 58333 | E12: =ROUND(③3か年収支計画!E17/12,0) -> -5833 | F12: 0 | G12: -100000 | H12: 0 | I12: 0 | J12: =-(⑥返済計画!D26+⑥返済計画!J28) -> -108108 | K12: =-(⑥返済計画!E26+⑥返済計画!K28) -> -21330 | L12: =-①前提条件!$B$55 -> -289050 | M12: =SUM(C12:L12) -> -86230 | N12: =B12+M12 -> 5212652 | P12: =P11+SUM(C12:H12)+⑥返済計画!J28*-1+⑥返済計画!K28*-1+L12 -> -1699850
A13: 2027-05 | B13: =N12 -> 5212652 | C13: =ROUND(②FRANK月次計画!S13+(④部門別営業損益!E5+④部門別営業損益!E6+④部門別営業損益!E8+④部門別営業損益!E9)/12,0) -> 488311 | D13: =ROUND(①前提条件!$B$56/12,0) -> 58333 | E13: =ROUND(③3か年収支計画!E17/12,0) -> -5833 | F13: 0 | G13: -100000 | H13: 0 | I13: 0 | J13: =-(⑥返済計画!D27+⑥返済計画!J29) -> -197852 | K13: =-(⑥返済計画!E27+⑥返済計画!K29) -> -21150 | L13: =-①前提条件!$B$55 -> -289050 | M13: =SUM(C13:L13) -> -67241 | N13: =B13+M13 -> 5145411 | P13: =P12+SUM(C13:H13)+⑥返済計画!J29*-1+⑥返済計画!K29*-1+L13 -> -1662764
A14: 2027-06 | B14: =N13 -> 5145411 | C14: =ROUND(②FRANK月次計画!S14+(④部門別営業損益!E5+④部門別営業損益!E6+④部門別営業損益!E8+④部門別営業損益!E9)/12,0) -> 589676 | D14: =ROUND(①前提条件!$B$56/12,0) -> 58333 | E14: =ROUND(③3か年収支計画!E17/12,0) -> -5833 | F14: 0 | G14: -100000 | H14: 0 | I14: 0 | J14: =-(⑥返済計画!D28+⑥返済計画!J30) -> -197852 | K14: =-(⑥返済計画!E28+⑥返済計画!K30) -> -20782 | L14: 0 | M14: =SUM(C14:L14) -> 323542 | N14: =B14+M14 -> 5468953 | P14: =P13+SUM(C14:H14)+⑥返済計画!J30*-1+⑥返済計画!K30*-1+L14 -> -1235082
A15: 2027-07 | B15: =N14 -> 5468953 | C15: =ROUND(②FRANK月次計画!S15+(④部門別営業損益!E5+④部門別営業損益!E6+④部門別営業損益!E8+④部門別営業損益!E9)/12,0) -> 685706 | D15: =ROUND(①前提条件!$B$56/12,0) -> 58333 | E15: =ROUND(③3か年収支計画!E17/12,0) -> -5833 | F15: 0 | G15: -100000 | H15: 0 | I15: 0 | J15: =-(⑥返済計画!D29+⑥返済計画!J31) -> -197852 | K15: =-(⑥返済計画!E29+⑥返済計画!K31) -> -20415 | L15: 0 | M15: =SUM(C15:L15) -> 419939 | N15: =B15+M15 -> 5888892 | P15: =P14+SUM(C15:H15)+⑥返済計画!J31*-1+⑥返済計画!K31*-1+L15 -> -711190
A16: 2027-08 | B16: =N15 -> 5888892 | C16: =ROUND(②FRANK月次計画!S16+(④部門別営業損益!E5+④部門別営業損益!E6+④部門別営業損益!E8+④部門別営業損益!E9)/12,0) -> 781736 | D16: =ROUND(①前提条件!$B$56/12,0) -> 58333 | E16: =ROUND(③3か年収支計画!E17/12,0) -> -5833 | F16: -355551 | G16: -100000 | H16: 0 | I16: 0 | J16: =-(⑥返済計画!D30+⑥返済計画!J32) -> -197852 | K16: =-(⑥返済計画!E30+⑥返済計画!K32) -> -20048 | L16: 0 | M16: =SUM(C16:L16) -> 160785 | N16: =B16+M16 -> 6049677 | P16: =P15+SUM(C16:H16)+⑥返済計画!J32*-1+⑥返済計画!K32*-1+L16 -> -446639
A17: 2027-09 | B17: =N16 -> 6049677 | C17: =ROUND(②FRANK月次計画!S17+(④部門別営業損益!F5+④部門別営業損益!F6+④部門別営業損益!F8+④部門別営業損益!F9)/12,0) -> 832984 | D17: =ROUND(①前提条件!$B$56/12,0) -> 58333 | E17: =ROUND(③3か年収支計画!F17/12,0) -> -334193 | F17: 0 | G17: -100000 | H17: 0 | I17: 0 | J17: =-(⑥返済計画!D31+⑥返済計画!J33) -> -197852 | K17: =-(⑥返済計画!E31+⑥返済計画!K33) -> -19681 | L17: 0 | M17: =SUM(C17:L17) -> 239591 | N17: =B17+M17 -> 6289268 | P17: =P16+SUM(C17:H17)+⑥返済計画!J33*-1+⑥返済計画!K33*-1+L17 -> -103469
A18: 2027-10 | B18: =N17 -> 6289268 | C18: =ROUND(②FRANK月次計画!S18+(④部門別営業損益!F5+④部門別営業損益!F6+④部門別営業損益!F8+④部門別営業損益!F9)/12,0) -> 918344 | D18: =ROUND(①前提条件!$B$56/12,0) -> 58333 | E18: =ROUND(③3か年収支計画!F17/12,0) -> -334193 | F18: 0 | G18: -100000 | H18: 0 | I18: 0 | J18: =-(⑥返済計画!D32+⑥返済計画!J34) -> -197852 | K18: =-(⑥返済計画!E32+⑥返済計画!K34) -> -19315 | L18: 0 | M18: =SUM(C18:L18) -> 325317 | N18: =B18+M18 -> 6614585 | P18: =P17+SUM(C18:H18)+⑥返済計画!J34*-1+⑥返済計画!K34*-1+L18 -> 325241
A19: 2027-11 | B19: =N18 -> 6614585 | C19: =ROUND(②FRANK月次計画!S19+(④部門別営業損益!F5+④部門別営業損益!F6+④部門別営業損益!F8+④部門別営業損益!F9)/12,0) -> 1003704 | D19: =ROUND(①前提条件!$B$56/12,0) -> 58333 | E19: =ROUND(③3か年収支計画!F17/12,0) -> -334193 | F19: -355551 | G19: -100000 | H19: 0 | I19: 0 | J19: =-(⑥返済計画!D33+⑥返済計画!J35) -> -197852 | K19: =-(⑥返済計画!E33+⑥返済計画!K35) -> -18948 | L19: 0 | M19: =SUM(C19:L19) -> 55493 | N19: =B19+M19 -> 6670078 | P19: =P18+SUM(C19:H19)+⑥返済計画!J35*-1+⑥返済計画!K35*-1+L19 -> 483940
A20: 2027-12 | B20: =N19 -> 6670078 | C20: =ROUND(②FRANK月次計画!S20+(④部門別営業損益!F5+④部門別営業損益!F6+④部門別営業損益!F8+④部門別営業損益!F9)/12,0) -> 1078394 | D20: =ROUND(①前提条件!$B$56/12,0) -> 58333 | E20: =ROUND(③3か年収支計画!F17/12,0) -> -334193 | F20: 0 | G20: -100000 | H20: 0 | I20: 0 | J20: =-(⑥返済計画!D34+⑥返済計画!J36) -> -197852 | K20: =-(⑥返済計画!E34+⑥返済計画!K36) -> -18580 | L20: 0 | M20: =SUM(C20:L20) -> 486102 | N20: =B20+M20 -> 7156180 | P20: =P19+SUM(C20:H20)+⑥返済計画!J36*-1+⑥返済計画!K36*-1+L20 -> 1073061
A21: 2028-01 | B21: =N20 -> 7156180 | C21: =ROUND(②FRANK月次計画!S21+(④部門別営業損益!F5+④部門別営業損益!F6+④部門別営業損益!F8+④部門別営業損益!F9)/12,0) -> 1110404 | D21: =ROUND(①前提条件!$B$56/12,0) -> 58333 | E21: =ROUND(③3か年収支計画!F17/12,0) -> -334193 | F21: 0 | G21: -100000 | H21: 0 | I21: 0 | J21: =-(⑥返済計画!D35+⑥返済計画!J37) -> -197852 | K21: =-(⑥返済計画!E35+⑥返済計画!K37) -> -18213 | L21: 0 | M21: =SUM(C21:L21) -> 518479 | N21: =B21+M21 -> 7674659 | P21: =P20+SUM(C21:H21)+⑥返済計画!J37*-1+⑥返済計画!K37*-1+L21 -> 1694372
A22: 2028-02 | B22: =N21 -> 7674659 | C22: =ROUND(②FRANK月次計画!S22+(④部門別営業損益!F5+④部門別営業損益!F6+④部門別営業損益!F8+④部門別営業損益!F9)/12,0) -> 1110404 | D22: =ROUND(①前提条件!$B$56/12,0) -> 58333 | E22: =ROUND(③3か年収支計画!F17/12,0) -> -334193 | F22: 0 | G22: -100000 | H22: 0 | I22: 0 | J22: =-(⑥返済計画!D36+⑥返済計画!J38) -> -197852 | K22: =-(⑥返済計画!E36+⑥返済計画!K38) -> -17846 | L22: 0 | M22: =SUM(C22:L22) -> 518846 | N22: =B22+M22 -> 8193505 | P22: =P21+SUM(C22:H22)+⑥返済計画!J38*-1+⑥返済計画!K38*-1+L22 -> 2315863
A23: 2028-03 | B23: =N22 -> 8193505 | C23: =ROUND(②FRANK月次計画!S23+(④部門別営業損益!F5+④部門別営業損益!F6+④部門別営業損益!F8+④部門別営業損益!F9)/12,0) -> 1163137 | D23: =ROUND(①前提条件!$B$56/12,0) -> 58333 | E23: =ROUND(③3か年収支計画!F17/12,0) -> -334193 | F23: -355551 | G23: -100000 | H23: 0 | I23: 0 | J23: =-(⑥返済計画!D37+⑥返済計画!J39) -> -197852 | K23: =-(⑥返済計画!E37+⑥返済計画!K39) -> -17479 | L23: 0 | M23: =SUM(C23:L23) -> 216395 | N23: =B23+M23 -> 8409900 | P23: =P22+SUM(C23:H23)+⑥返済計画!J39*-1+⑥返済計画!K39*-1+L23 -> 2634716
A24: 2028-04 | B24: =N23 -> 8409900 | C24: =ROUND(②FRANK月次計画!S24+(④部門別営業損益!F5+④部門別営業損益!F6+④部門別営業損益!F8+④部門別営業損益!F9)/12,0) -> 1163137 | D24: =ROUND(①前提条件!$B$56/12,0) -> 58333 | E24: =ROUND(③3か年収支計画!F17/12,0) -> -334193 | F24: 0 | G24: -100000 | H24: 0 | I24: 0 | J24: =-(⑥返済計画!D38+⑥返済計画!J40) -> -197852 | K24: =-(⑥返済計画!E38+⑥返済計画!K40) -> -17112 | L24: 0 | M24: =SUM(C24:L24) -> 572313 | N24: =B24+M24 -> 8982213 | P24: =P23+SUM(C24:H24)+⑥返済計画!J40*-1+⑥返済計画!K40*-1+L24 -> 3309300
A25: 2028-05 | B25: =N24 -> 8982213 | C25: =ROUND(②FRANK月次計画!S25+(④部門別営業損益!F5+④部門別営業損益!F6+④部門別営業損益!F8+④部門別営業損益!F9)/12,0) -> 1163137 | D25: =ROUND(①前提条件!$B$56/12,0) -> 58333 | E25: =ROUND(③3か年収支計画!F17/12,0) -> -334193 | F25: 0 | G25: -100000 | H25: 0 | I25: 0 | J25: =-(⑥返済計画!D39+⑥返済計画!J41) -> -197852 | K25: =-(⑥返済計画!E39+⑥返済計画!K41) -> -16744 | L25: 0 | M25: =SUM(C25:L25) -> 572681 | N25: =B25+M25 -> 9554894 | P25: =P24+SUM(C25:H25)+⑥返済計画!J41*-1+⑥返済計画!K41*-1+L25 -> 3984065
A26: 2028-06 | B26: =N25 -> 9554894 | C26: =ROUND(②FRANK月次計画!S26+(④部門別営業損益!F5+④部門別営業損益!F6+④部門別営業損益!F8+④部門別営業損益!F9)/12,0) -> 1163137 | D26: =ROUND(①前提条件!$B$56/12,0) -> 58333 | E26: =ROUND(③3か年収支計画!F17/12,0) -> -334193 | F26: 0 | G26: -100000 | H26: 0 | I26: 0 | J26: =-(⑥返済計画!D40+⑥返済計画!J42) -> -197852 | K26: =-(⑥返済計画!E40+⑥返済計画!K42) -> -16377 | L26: 0 | M26: =SUM(C26:L26) -> 573048 | N26: =B26+M26 -> 10127942 | P26: =P25+SUM(C26:H26)+⑥返済計画!J42*-1+⑥返済計画!K42*-1+L26 -> 4659010
A27: 2028-07 | B27: =N26 -> 10127942 | C27: =ROUND(②FRANK月次計画!S27+(④部門別営業損益!F5+④部門別営業損益!F6+④部門別営業損益!F8+④部門別営業損益!F9)/12,0) -> 1163137 | D27: =ROUND(①前提条件!$B$56/12,0) -> 58333 | E27: =ROUND(③3か年収支計画!F17/12,0) -> -334193 | F27: 0 | G27: -100000 | H27: 0 | I27: 0 | J27: =-(⑥返済計画!D41+⑥返済計画!J43) -> -197852 | K27: =-(⑥返済計画!E41+⑥返済計画!K43) -> -16010 | L27: 0 | M27: =SUM(C27:L27) -> 573415 | N27: =B27+M27 -> 10701357 | P27: =P26+SUM(C27:H27)+⑥返済計画!J43*-1+⑥返済計画!K43*-1+L27 -> 5334135
A28: 2028-08 | B28: =N27 -> 10701357 | C28: =ROUND(②FRANK月次計画!S28+(④部門別営業損益!F5+④部門別営業損益!F6+④部門別営業損益!F8+④部門別営業損益!F9)/12,0) -> 1163137 | D28: =ROUND(①前提条件!$B$56/12,0) -> 58333 | E28: =ROUND(③3か年収支計画!F17/12,0) -> -334193 | F28: -355551 | G28: -100000 | H28: 0 | I28: 0 | J28: =-(⑥返済計画!D42+⑥返済計画!J44) -> -197852 | K28: =-(⑥返済計画!E42+⑥返済計画!K44) -> -15643 | L28: 0 | M28: =SUM(C28:L28) -> 218231 | N28: =B28+M28 -> 10919588 | P28: =P27+SUM(C28:H28)+⑥返済計画!J44*-1+⑥返済計画!K44*-1+L28 -> 5653889
A30: ■ 判定
A31: 今回の700万円を調達した場合 24か月の最低残高 | E31: =MIN(N5:N28) -> 3902281 | G31: =INDEX(A5:A28,MATCH(MIN(N5:N28),N5:N28,0)) -> 2026-09 | H31: に発生
A32: 借入実行後（2026年11月以降）の最低残高 | E32: =MIN(N7:N28) -> 5145411 | G32: =INDEX(A7:A28,MATCH(MIN(N7:N28),N7:N28,0)) -> 2027-05 | H32: に発生
A33: 調達しなかった場合 24か月の最低残高 | E33: =MIN(P5:P28) -> -1699850 | G33: =INDEX(A5:A28,MATCH(MIN(P5:P28),P5:P28,0)) -> 2027-04 | H33: に発生
A34: ストレステスト：営業損益が計画比▲10%で推移した場合（借入あり） | E34: =MIN(N7:N28)-ABS(SUM(C5:C28))*0.1 -> 3699097.4
A36: ※ 営業損益（月次）は、FRANK GOLF は②シートの月次計画から、既存事業・システム外販・本社共通は④シートの年額を12等分して置いています。
A37: ※ 社会保険は年3回（11月・3月・8月）が2か月分まとめての納付月になるため、その上乗せ分355,551円を計上しています（今回の申込の「季節資金」の根拠）。
A38: ※ その他税・一時支出 月100,000円は、2026年8月21日提出の資金繰り表と同じ前提です。
A39: ※ 未払金の圧縮は、未払金7,018,672円のうち開業投資に対応しない残 1,278,497円を、2026年10月から6か月で支払う想定です。
A40: ※ カード分割（エポス）289,050円/月は2027年5月で完済します。開業投資のカード分割であり、費用ではなく未払金の返済です。
A41: ※ アメリカン・エキスプレス法人カード（月約450,000円）は、営業損益に含まれる経費の決済手段のため、二重には計上していません。
A42: ※ GOLF WING 宝塚は㈱ファインからの精算が当月分→翌月末入金のため、実際の入金は1か月遅れます。上表は月次平均で均しています。
A43: ※ 2026年8月21日に提出した資金繰り表では、最低残高は3,422,996円（2027年3月）でした。本計画は開業後の実績を織り込んで作り直したものです。

Sheet ⑥返済計画
A1: ⑥ 借入金の返済計画
A2: 今回の申込 700万円（年2.5%・84回・元金据置6か月）と、既存の長期借入金 4,804,819円（毎月元金108,108円）。単位：円
A4: 決算期 | B4: 期間 | C4: 今回借入 元金返済 | D4: 今回借入 支払利息 | E4: 既存借入 元金返済 | F4: 既存借入 支払利息 | G4: 支払利息 計 | H4: 元金返済 計 | I4: 期末 借入金残高
A5: 第2期 | B5: （借入実行前） | C5: =SUMIF($A$21:$A$104,$A5,$D$21:$D$104) -> 0 | D5: =SUMIF($A$21:$A$104,$A5,$E$21:$E$104) -> 0 | E5: =SUMIF($H$21:$H$104,$A5,$J$21:$J$104) -> 0 | F5: =SUMIF($H$21:$H$104,$A5,$K$21:$K$104) -> 0 | G5: =D5+F5 -> 0 | H5: =C5+E5 -> 0 | I5: =①前提条件!$B$48+①前提条件!$B$53 -> 11804819
A6: 第3期 | B6: 2026/9〜2027/8 | C6: =SUMIF($A$21:$A$104,$A6,$D$21:$D$104) -> 358976 | D6: =SUMIF($A$21:$A$104,$A6,$E$21:$E$104) -> 144708 | E6: =SUMIF($H$21:$H$104,$A6,$J$21:$J$104) -> 1297296 | F6: =SUMIF($H$21:$H$104,$A6,$K$21:$K$104) -> 84204 | G6: =D6+F6 -> 228912 | H6: =C6+E6 -> 1656272 | I6: =I5-C6-E6 -> 10148547
A7: 第4期 | B7: 2027/9〜2028/8 | C7: =SUMIF($A$21:$A$104,$A7,$D$21:$D$104) -> 1076928 | D7: =SUMIF($A$21:$A$104,$A7,$E$21:$E$104) -> 153689 | E7: =SUMIF($H$21:$H$104,$A7,$J$21:$J$104) -> 1297296 | F7: =SUMIF($H$21:$H$104,$A7,$K$21:$K$104) -> 58259 | G7: =D7+F7 -> 211948 | H7: =C7+E7 -> 2374224 | I7: =I6-C7-E7 -> 7774323
A8: 第5期 | B8: 2028/9〜2029/8 | C8: =SUMIF($A$21:$A$104,$A8,$D$21:$D$104) -> 1076928 | D8: =SUMIF($A$21:$A$104,$A8,$E$21:$E$104) -> 126762 | E8: =SUMIF($H$21:$H$104,$A8,$J$21:$J$104) -> 1297296 | F8: =SUMIF($H$21:$H$104,$A8,$K$21:$K$104) -> 32313 | G8: =D8+F8 -> 159075 | H8: =C8+E8 -> 2374224 | I8: =I7-C8-E8 -> 5400099
A9: 第6期 | B9: 2029/9〜2030/8 | C9: =SUMIF($A$21:$A$104,$A9,$D$21:$D$104) -> 1076928 | D9: =SUMIF($A$21:$A$104,$A9,$E$21:$E$104) -> 99839 | E9: =SUMIF($H$21:$H$104,$A9,$J$21:$J$104) -> 912931 | F9: =SUMIF($H$21:$H$104,$A9,$K$21:$K$104) -> 7207 | G9: =D9+F9 -> 107046 | H9: =C9+E9 -> 1989859 | I9: =I8-C9-E9 -> 3410240
A10: 第7期 | B10: 2030/9〜2031/8 | C10: =SUMIF($A$21:$A$104,$A10,$D$21:$D$104) -> 1076928 | D10: =SUMIF($A$21:$A$104,$A10,$E$21:$E$104) -> 72918 | E10: =SUMIF($H$21:$H$104,$A10,$J$21:$J$104) -> 0 | F10: =SUMIF($H$21:$H$104,$A10,$K$21:$K$104) -> 0 | G10: =D10+F10 -> 72918 | H10: =C10+E10 -> 1076928 | I10: =I9-C10-E10 -> 2333312
A13: ■ 返済のしかた
A14: ・今回の700万円は、元金据置6か月ののち78回で元金均等返済（毎月89,744円＋利息）。返済日は毎月5日。
A15: ・据置期間を置くのは、資金繰りの残高が最も薄くなる2027年3月を越えてから元金返済を始めるためです。
A16: ・既存の長期借入金は毎月108,108円の元金返済で、2030年3月ごろ完済の見込みです（金利は年2.0%と仮置き／返済予定表で差し替え）。
A19: ■ 返済明細
A20: 決算期 | B20: 回 | C20: 返済日 | D20: 元金（今回700万） | E20: 利息 | F20: 期末残高 | H20: 決算期 | I20: 回 | J20: 元金（既存） | K20: 利息 | L20: 残高（既存）
A21: 第3期 | B21: 1 | C21: 46331 | D21: =IF(1<=①前提条件!$B$51,0,MIN(①前提条件!$B$48,ROUND(①前提条件!$B$48/(①前提条件!$B$50-①前提条件!$B$51),0))) -> 0 | E21: =ROUND(①前提条件!$B$48*①前提条件!$B$49/12,0) -> 14583 | F21: =①前提条件!$B$48-D21 -> 7000000 | H21: 第3期 | I21: 1 | J21: =MIN(①前提条件!$B$53,①前提条件!$B$54) -> 108108 | K21: =ROUND(①前提条件!$B$53*0.02/12,0) -> 8008 | L21: =①前提条件!$B$53-J21 -> 4696711
A22: 第3期 | B22: 2 | C22: 46361 | D22: =IF(2<=①前提条件!$B$51,0,MIN(F21,ROUND(①前提条件!$B$48/(①前提条件!$B$50-①前提条件!$B$51),0))) -> 0 | E22: =ROUND(F21*①前提条件!$B$49/12,0) -> 14583 | F22: =F21-D22 -> 7000000 | H22: 第3期 | I22: 2 | J22: =MIN(L21,①前提条件!$B$54) -> 108108 | K22: =ROUND(L21*0.02/12,0) -> 7828 | L22: =L21-J22 -> 4588603
A23: 第3期 | B23: 3 | C23: 46392 | D23: =IF(3<=①前提条件!$B$51,0,MIN(F22,ROUND(①前提条件!$B$48/(①前提条件!$B$50-①前提条件!$B$51),0))) -> 0 | E23: =ROUND(F22*①前提条件!$B$49/12,0) -> 14583 | F23: =F22-D23 -> 7000000 | H23: 第3期 | I23: 3 | J23: =MIN(L22,①前提条件!$B$54) -> 108108 | K23: =ROUND(L22*0.02/12,0) -> 7648 | L23: =L22-J23 -> 4480495
A24: 第3期 | B24: 4 | C24: 46423 | D24: =IF(4<=①前提条件!$B$51,0,MIN(F23,ROUND(①前提条件!$B$48/(①前提条件!$B$50-①前提条件!$B$51),0))) -> 0 | E24: =ROUND(F23*①前提条件!$B$49/12,0) -> 14583 | F24: =F23-D24 -> 7000000 | H24: 第3期 | I24: 4 | J24: =MIN(L23,①前提条件!$B$54) -> 108108 | K24: =ROUND(L23*0.02/12,0) -> 7467 | L24: =L23-J24 -> 4372387
A25: 第3期 | B25: 5 | C25: 46451 | D25: =IF(5<=①前提条件!$B$51,0,MIN(F24,ROUND(①前提条件!$B$48/(①前提条件!$B$50-①前提条件!$B$51),0))) -> 0 | E25: =ROUND(F24*①前提条件!$B$49/12,0) -> 14583 | F25: =F24-D25 -> 7000000 | H25: 第3期 | I25: 5 | J25: =MIN(L24,①前提条件!$B$54) -> 108108 | K25: =ROUND(L24*0.02/12,0) -> 7287 | L25: =L24-J25 -> 4264279
A26: 第3期 | B26: 6 | C26: 46482 | D26: =IF(6<=①前提条件!$B$51,0,MIN(F25,ROUND(①前提条件!$B$48/(①前提条件!$B$50-①前提条件!$B$51),0))) -> 0 | E26: =ROUND(F25*①前提条件!$B$49/12,0) -> 14583 | F26: =F25-D26 -> 7000000 | H26: 第3期 | I26: 6 | J26: =MIN(L25,①前提条件!$B$54) -> 108108 | K26: =ROUND(L25*0.02/12,0) -> 7107 | L26: =L25-J26 -> 4156171
A27: 第3期 | B27: 7 | C27: 46512 | D27: =IF(7<=①前提条件!$B$51,0,MIN(F26,ROUND(①前提条件!$B$48/(①前提条件!$B$50-①前提条件!$B$51),0))) -> 89744 | E27: =ROUND(F26*①前提条件!$B$49/12,0) -> 14583 | F27: =F26-D27 -> 6910256 | H27: 第3期 | I27: 7 | J27: =MIN(L26,①前提条件!$B$54) -> 108108 | K27: =ROUND(L26*0.02/12,0) -> 6927 | L27: =L26-J27 -> 4048063
A28: 第3期 | B28: 8 | C28: 46543 | D28: =IF(8<=①前提条件!$B$51,0,MIN(F27,ROUND(①前提条件!$B$48/(①前提条件!$B$50-①前提条件!$B$51),0))) -> 89744 | E28: =ROUND(F27*①前提条件!$B$49/12,0) -> 14396 | F28: =F27-D28 -> 6820512 | H28: 第3期 | I28: 8 | J28: =MIN(L27,①前提条件!$B$54) -> 108108 | K28: =ROUND(L27*0.02/12,0) -> 6747 | L28: =L27-J28 -> 3939955
A29: 第3期 | B29: 9 | C29: 46573 | D29: =IF(9<=①前提条件!$B$51,0,MIN(F28,ROUND(①前提条件!$B$48/(①前提条件!$B$50-①前提条件!$B$51),0))) -> 89744 | E29: =ROUND(F28*①前提条件!$B$49/12,0) -> 14209 | F29: =F28-D29 -> 6730768 | H29: 第3期 | I29: 9 | J29: =MIN(L28,①前提条件!$B$54) -> 108108 | K29: =ROUND(L28*0.02/12,0) -> 6567 | L29: =L28-J29 -> 3831847
A30: 第3期 | B30: 10 | C30: 46604 | D30: =IF(10<=①前提条件!$B$51,0,MIN(F29,ROUND(①前提条件!$B$48/(①前提条件!$B$50-①前提条件!$B$51),0))) -> 89744 | E30: =ROUND(F29*①前提条件!$B$49/12,0) -> 14022 | F30: =F29-D30 -> 6641024 | H30: 第3期 | I30: 10 | J30: =MIN(L29,①前提条件!$B$54) -> 108108 | K30: =ROUND(L29*0.02/12,0) -> 6386 | L30: =L29-J30 -> 3723739
A31: 第4期 | B31: 11 | C31: 46635 | D31: =IF(11<=①前提条件!$B$51,0,MIN(F30,ROUND(①前提条件!$B$48/(①前提条件!$B$50-①前提条件!$B$51),0))) -> 89744 | E31: =ROUND(F30*①前提条件!$B$49/12,0) -> 13835 | F31: =F30-D31 -> 6551280 | H31: 第3期 | I31: 11 | J31: =MIN(L30,①前提条件!$B$54) -> 108108 | K31: =ROUND(L30*0.02/12,0) -> 6206 | L31: =L30-J31 -> 3615631
A32: 第4期 | B32: 12 | C32: 46665 | D32: =IF(12<=①前提条件!$B$51,0,MIN(F31,ROUND(①前提条件!$B$48/(①前提条件!$B$50-①前提条件!$B$51),0))) -> 89744 | E32: =ROUND(F31*①前提条件!$B$49/12,0) -> 13649 | F32: =F31-D32 -> 6461536 | H32: 第3期 | I32: 12 | J32: =MIN(L31,①前提条件!$B$54) -> 108108 | K32: =ROUND(L31*0.02/12,0) -> 6026 | L32: =L31-J32 -> 3507523
A33: 第4期 | B33: 13 | C33: 46696 | D33: =IF(13<=①前提条件!$B$51,0,MIN(F32,ROUND(①前提条件!$B$48/(①前提条件!$B$50-①前提条件!$B$51),0))) -> 89744 | E33: =ROUND(F32*①前提条件!$B$49/12,0) -> 13462 | F33: =F32-D33 -> 6371792 | H33: 第4期 | I33: 13 | J33: =MIN(L32,①前提条件!$B$54) -> 108108 | K33: =ROUND(L32*0.02/12,0) -> 5846 | L33: =L32-J33 -> 3399415
A34: 第4期 | B34: 14 | C34: 46726 | D34: =IF(14<=①前提条件!$B$51,0,MIN(F33,ROUND(①前提条件!$B$48/(①前提条件!$B$50-①前提条件!$B$51),0))) -> 89744 | E34: =ROUND(F33*①前提条件!$B$49/12,0) -> 13275 | F34: =F33-D34 -> 6282048 | H34: 第4期 | I34: 14 | J34: =MIN(L33,①前提条件!$B$54) -> 108108 | K34: =ROUND(L33*0.02/12,0) -> 5666 | L34: =L33-J34 -> 3291307
A35: 第4期 | B35: 15 | C35: 46757 | D35: =IF(15<=①前提条件!$B$51,0,MIN(F34,ROUND(①前提条件!$B$48/(①前提条件!$B$50-①前提条件!$B$51),0))) -> 89744 | E35: =ROUND(F34*①前提条件!$B$49/12,0) -> 13088 | F35: =F34-D35 -> 6192304 | H35: 第4期 | I35: 15 | J35: =MIN(L34,①前提条件!$B$54) -> 108108 | K35: =ROUND(L34*0.02/12,0) -> 5486 | L35: =L34-J35 -> 3183199
A36: 第4期 | B36: 16 | C36: 46788 | D36: =IF(16<=①前提条件!$B$51,0,MIN(F35,ROUND(①前提条件!$B$48/(①前提条件!$B$50-①前提条件!$B$51),0))) -> 89744 | E36: =ROUND(F35*①前提条件!$B$49/12,0) -> 12901 | F36: =F35-D36 -> 6102560 | H36: 第4期 | I36: 16 | J36: =MIN(L35,①前提条件!$B$54) -> 108108 | K36: =ROUND(L35*0.02/12,0) -> 5305 | L36: =L35-J36 -> 3075091
A37: 第4期 | B37: 17 | C37: 46817 | D37: =IF(17<=①前提条件!$B$51,0,MIN(F36,ROUND(①前提条件!$B$48/(①前提条件!$B$50-①前提条件!$B$51),0))) -> 89744 | E37: =ROUND(F36*①前提条件!$B$49/12,0) -> 12714 | F37: =F36-D37 -> 6012816 | H37: 第4期 | I37: 17 | J37: =MIN(L36,①前提条件!$B$54) -> 108108 | K37: =ROUND(L36*0.02/12,0) -> 5125 | L37: =L36-J37 -> 2966983
A38: 第4期 | B38: 18 | C38: 46848 | D38: =IF(18<=①前提条件!$B$51,0,MIN(F37,ROUND(①前提条件!$B$48/(①前提条件!$B$50-①前提条件!$B$51),0))) -> 89744 | E38: =ROUND(F37*①前提条件!$B$49/12,0) -> 12527 | F38: =F37-D38 -> 5923072 | H38: 第4期 | I38: 18 | J38: =MIN(L37,①前提条件!$B$54) -> 108108 | K38: =ROUND(L37*0.02/12,0) -> 4945 | L38: =L37-J38 -> 2858875
A39: 第4期 | B39: 19 | C39: 46878 | D39: =IF(19<=①前提条件!$B$51,0,MIN(F38,ROUND(①前提条件!$B$48/(①前提条件!$B$50-①前提条件!$B$51),0))) -> 89744 | E39: =ROUND(F38*①前提条件!$B$49/12,0) -> 12340 | F39: =F38-D39 -> 5833328 | H39: 第4期 | I39: 19 | J39: =MIN(L38,①前提条件!$B$54) -> 108108 | K39: =ROUND(L38*0.02/12,0) -> 4765 | L39: =L38-J39 -> 2750767
A40: 第4期 | B40: 20 | C40: 46909 | D40: =IF(20<=①前提条件!$B$51,0,MIN(F39,ROUND(①前提条件!$B$48/(①前提条件!$B$50-①前提条件!$B$51),0))) -> 89744 | E40: =ROUND(F39*①前提条件!$B$49/12,0) -> 12153 | F40: =F39-D40 -> 5743584 | H40: 第4期 | I40: 20 | J40: =MIN(L39,①前提条件!$B$54) -> 108108 | K40: =ROUND(L39*0.02/12,0) -> 4585 | L40: =L39-J40 -> 2642659
A41: 第4期 | B41: 21 | C41: 46939 | D41: =IF(21<=①前提条件!$B$51,0,MIN(F40,ROUND(①前提条件!$B$48/(①前提条件!$B$50-①前提条件!$B$51),0))) -> 89744 | E41: =ROUND(F40*①前提条件!$B$49/12,0) -> 11966 | F41: =F40-D41 -> 5653840 | H41: 第4期 | I41: 21 | J41: =MIN(L40,①前提条件!$B$54) -> 108108 | K41: =ROUND(L40*0.02/12,0) -> 4404 | L41: =L40-J41 -> 2534551
A42: 第4期 | B42: 22 | C42: 46970 | D42: =IF(22<=①前提条件!$B$51,0,MIN(F41,ROUND(①前提条件!$B$48/(①前提条件!$B$50-①前提条件!$B$51),0))) -> 89744 | E42: =ROUND(F41*①前提条件!$B$49/12,0) -> 11779 | F42: =F41-D42 -> 5564096 | H42: 第4期 | I42: 22 | J42: =MIN(L41,①前提条件!$B$54) -> 108108 | K42: =ROUND(L41*0.02/12,0) -> 4224 | L42: =L41-J42 -> 2426443
A43: 第5期 | B43: 23 | C43: 47001 | D43: =IF(23<=①前提条件!$B$51,0,MIN(F42,ROUND(①前提条件!$B$48/(①前提条件!$B$50-①前提条件!$B$51),0))) -> 89744 | E43: =ROUND(F42*①前提条件!$B$49/12,0) -> 11592 | F43: =F42-D43 -> 5474352 | H43: 第4期 | I43: 23 | J43: =MIN(L42,①前提条件!$B$54) -> 108108 | K43: =ROUND(L42*0.02/12,0) -> 4044 | L43: =L42-J43 -> 2318335
A44: 第5期 | B44: 24 | C44: 47031 | D44: =IF(24<=①前提条件!$B$51,0,MIN(F43,ROUND(①前提条件!$B$48/(①前提条件!$B$50-①前提条件!$B$51),0))) -> 89744 | E44: =ROUND(F43*①前提条件!$B$49/12,0) -> 11405 | F44: =F43-D44 -> 5384608 | H44: 第4期 | I44: 24 | J44: =MIN(L43,①前提条件!$B$54) -> 108108 | K44: =ROUND(L43*0.02/12,0) -> 3864 | L44: =L43-J44 -> 2210227
A45: 第5期 | B45: 25 | C45: 47062 | D45: =IF(25<=①前提条件!$B$51,0,MIN(F44,ROUND(①前提条件!$B$48/(①前提条件!$B$50-①前提条件!$B$51),0))) -> 89744 | E45: =ROUND(F44*①前提条件!$B$49/12,0) -> 11218 | F45: =F44-D45 -> 5294864 | H45: 第5期 | I45: 25 | J45: =MIN(L44,①前提条件!$B$54) -> 108108 | K45: =ROUND(L44*0.02/12,0) -> 3684 | L45: =L44-J45 -> 2102119
...

Sheet ⑦純資産と債務超過
A1: ⑦ 純資産の推移と債務超過の解消
A2: 第2期末の債務超過を、第3期（FRANK GOLF 営業1年目）で解消する計画です。単位：円
A4: 項目 | B4: 第2期 実績 （令和8年7月31日） | C4: 第2期 見込 （通期） | D4: 第3期 計画 | E4: 第4期 計画 | F4: 第5期 計画 | G4: 備考
A5: 期首 純資産 | B5: -276759 | C5: -276759 | D5: =C6 -> -1711921 | E5: =D6 -> -580758 | F5: =E6 -> 8230032 | G5: 第1期末（2025年8月31日）の純資産 ▲276,759円＝資本金300,000＋繰越利益剰余金▲576,759
A6: 期末 純資産 | B6: -1281921 | C6: =C5+C7 -> -1711921 | D6: =D5+D7 -> -580758 | E6: =E5+E7 -> 8230032 | F6: =F5+F7 -> 18245863 | G6: 第3期に債務超過を解消する計画
A7: 当期純損益 | B7: -1005162 | C7: =-1005162+①前提条件!$B$60 -> -1435162 | D7: =③3か年収支計画!E18 -> 1131163 | E7: =③3か年収支計画!F18 -> 8810790 | F7: =③3か年収支計画!G18 -> 10015831 | G7: ③3か年収支計画シートから連動
A8: （税務）期首 繰越欠損金 | D8: =MIN(0,C6-300000) -> -2011921 | E8: =MIN(0,D6-300000) -> -880758 | F8: =MIN(0,E6-300000) -> 0 | G8: 資本金300,000円を控除した繰越利益剰余金。法人税等の計算に使用（③シート）
A9: 債務超過の状態 | B9: =IF(B6<0,"債務超過","解消") -> 債務超過 | C9: =IF(C6<0,"債務超過","解消") -> 債務超過 | D9: =IF(D6<0,"債務超過","解消") -> 債務超過 | E9: =IF(E6<0,"債務超過","解消") -> 解消 | F9: =IF(F6<0,"債務超過","解消") -> 解消
A10: （参考）役員借入金 | B10: 1500000 | C10: 1500000 | D10: 1500000 | E10: 1500000 | F10: 1500000 | G10: 小川取締役からの借入 1,500,000円。返済順位を劣後させる念書を差し入れ、資本性借入金とみなしていただく前提
A11: （参考）実質純資産（役員借入を資本性とみなした場合） | B11: =B6+B10 -> 218079 | C11: =C6+C10 -> -211921 | D11: =D6+D10 -> 919242 | E11: =E6+E10 -> 9730032 | F11: =F6+F10 -> 19745863 | G11: この基準では第3期に債務超過を解消する
A12: 同上 債務超過の状態 | B12: =IF(B11<0,"債務超過","解消") -> 解消 | C12: =IF(C11<0,"債務超過","解消") -> 債務超過 | D12: =IF(D11<0,"債務超過","解消") -> 解消 | E12: =IF(E11<0,"債務超過","解消") -> 解消 | F12: =IF(F11<0,"債務超過","解消") -> 解消
A14: ■ 債務超過の中身と、解消の道すじ
A15: ・第2期の当期純損失は、①2号店 FRANK GOLF の開業先行費用（2026年6月からの地代家賃440,000円/月ほか。開業は9月2日で当期の売上貢献はゼロ）、
A16: ②システム内製化への投資（AIを使った自社開発）が主因です。既存店（GOLF WING 宝塚）は単体では黒字です。
A17: ・したがって第2期の赤字は、売れないことによる赤字ではなく、2号店を立ち上げるための先行投資です。
A18: ・第3期は、その2号店が通年で寄与します。全社の営業損益・当期純損益はともに黒字に転換する計画です（③3か年収支計画）。
A19: ・FRANK GOLF 単体は、損益分岐会員数（②シートに自動計算）に到達する月から単月黒字になります。通期では第3期はわずかに赤字、第4期から本格的に寄与します。
A20: ・会計上の純資産は第3期末で解消の一歩手前、第4期に確実に解消します。役員借入1,500,000円を資本性とみなした実質ベースでは第3期に解消します。
A21: ・あわせて経費削減 月100,000円（年1,200,000円）を実行します。これは計画が成立するための条件として織り込んでいます。
A22: ・役員借入（小川取締役 1,500,000円）は、実質的な自己資本とみなしていただけるよう、返済順位を劣後させる念書の差入れに応じる用意があります。

Sheet ⑧実績データ
A1: ⑧ 計画の根拠となる実績データ
A2: 出典：Supabase（会員台帳・予約台帳・売上台帳）／税理士作成 残高試算表（令和8年7月31日）
A4: 【1】GOLF WING 宝塚 課金会員数の推移
A5: 月 | B5: 会員数 | C5: 前年同月 | D5: 前年同月比 | E5: 新規入会 | F5: 退会
A6: 2025-09 | B6: 148 | C6: 110 | D6: =B6/C6-1 -> 0.34545455 | E6: 6 | F6: 0
A7: 2025-10 | B7: 155 | C7: 113 | D7: =B7/C7-1 -> 0.37168142 | E7: 7 | F7: 0
A8: 2025-11 | B8: 161 | C8: 114 | D8: =B8/C8-1 -> 0.4122807 | E8: 7 | F8: 0
A9: 2025-12 | B9: 169 | C9: 116 | D9: =B9/C9-1 -> 0.45689655 | E9: 8 | F9: 0
A10: 2026-01 | B10: 172 | C10: 118 | D10: =B10/C10-1 -> 0.45762712 | E10: 3 | F10: 0
A11: 2026-02 | B11: 180 | C11: 119 | D11: =B11/C11-1 -> 0.51260504 | E11: 8 | F11: 0
A12: 2026-03 | B12: 188 | C12: 120 | D12: =B12/C12-1 -> 0.56666667 | E12: 8 | F12: 0
A13: 2026-04 | B13: 196 | C13: 121 | D13: =B13/C13-1 -> 0.61983471 | E13: 9 | F13: 0
A14: 2026-05 | B14: 203 | C14: 126 | D14: =B14/C14-1 -> 0.61111111 | E14: 9 | F14: 0
A15: 2026-06 | B15: 210 | C15: 130 | D15: =B15/C15-1 -> 0.61538462 | E15: 9 | F15: 10
