Workbook

Sheet 一時利用顧客名簿 
A1: 日付 | B1: 利用区分 | C1: 名前 | D1: フリガナ | E1: 生年月日 | F1: 性別 | G1: 郵便番号 | H1: 住所 | I1: お店までの距離 | J1: 電話番号 | K1: email | L1: 職業 | M1: 連絡方法 | N1: 利用料 | O1: 割引（公式ライン、社長紹介、ロータリー関連、再来） | P1: 再来の場合日付記入 | Q1: 支払い方法（店頭、WEB） | R1: 担当プロ | S1: 担当受付 | T1: 成約（入会、購入） | U1: 再アプローチ (日付) | V1: 備考 | W1: 何で知ったか | X1: 何で知ったか (その他) | Y1: 1 （フィッティング） | Z1: 2 （フィッティング） | AA1: 3 （フィッティング） | AB1: 4 （フィッティング） | AC1: 5 （フィッティング） | AD1: その他 | AE1: 公式LINE ｱﾌﾀｰﾌｫﾛｰ実施日 | AF1: 1（体験理由） | AG1: 2（体験理由） | AH1: 3（体験理由） | AI1: 4（体験理由） | AJ1: 5（体験理由） | AK1: その他 | AL1: ゴルフスクールに通う目的 1 | AM1: ゴルフスクールに通う目的 2 | AN1: ゴルフスクールに通う目的 3 | AO1: 入会興味の有無 | AP1: 体験後のコメント、フォロー状況 | AQ1: 体験から の入会 | AR1: 再アプローチ (日付)
A2: 43498 | B2: 打席利用 | C2: 吉田 龍藏 | E2: 19441 | G2: 666-0035 | H2: 川西市花屋敷2-8-21-204 | I2: 2.8 | J2: 090-3494-1446 | L2: 会社経営者・役員 | N2: 5500 | V2: 4回目利用 | W2: 知人の紹介 | Y2: 天候に左右されない練習環境 | AW2: ←携帯番号はお母様の番号 | AX2: 天候に左右されない練習環境 | AY2: 体験利用 | AZ2: 会社経営者・役員 | BA2: 店頭 | BB2: 杉田 | BC2: 公式ライン | BD2: ワンポイントレッスンを受けてみたい | BE2: 定期的に体を動かしたい
A3: 43567 | B3: 体験利用 | C3: 別所 健三 | E3: 32008 | G3: 666-0257 | H3: 兵庫県川辺郡猪名川町白金2-30-30 | I3: 14.4km | J3: 080-3816-2307 | K3: kenchan0819@ymobile.ne.jp | L3: 公務員 | W3: その他 | Y3: 飛距離を伸ばすため | AW3: ←松本隆司様にＤＭ送付した際戻ってきたので… | AX3: トラックマン等計測設備の利用 | AY3: フィッティング | AZ3: 自営業 | BA3: WEB | BB3: 卜部 | BC3: 社長紹介 | BD3: PGAプロに習ってみたい | BE3: スコアアップを目指したい
A4: 43574 | B4: フィッティング | C4: 宇都宮 受仁也 | E4: 30876 | G4: 562-0001 | H4: 大阪府箕面市箕面2-7-32 | I4: 9.4km | J4: 080-3865-6048 | K4: juniya0713@gmail.com | L4: 自営業 | V4: 宮坂月子 知り合い | W4: 知人の紹介 | Y4: 天候に左右されない練習環境 | AW4: 2021.2.6 ﾌｨｯﾃｨﾝｸﾞ来店。本日もﾌｨｯﾃｨﾝｸﾞ目的でご自身で打席予約されて来店。55分のみの予約だったので、ﾌｨｯﾃｨﾝｸﾞではなく体験に変更されました。 | AX4: シャフトの種類の多さ | AY4: シャフト試打 | AZ4: 公務員 | BB4: 谷川 | BC4: ロータリー関連 | BD4: インドアゴルフを利用してみたい | BE4: 今よりも飛距離を伸ばしたい
A5: 43574 | B5: フィッティング | C5: 藤原 伸充 | E5: 30250 | G5: 560-0082 | H5: 大阪府豊中市新千里東町1-1-2-5103 | I5: 12.3km | J5: 090-5258-7299 | K5: hole.in.one.26@gmail.com | L5: 会社経営者・役員 | V5: 宮坂月子 知り合い | W5: 知人の紹介 | Y5: トラックマン等計測設備の利用 | AW5: SNS | AX5: PGAプロの在籍 | AY5: ビジター打席 | AZ5: 会社員 | BB5: 古川 | BC5: 再来 | BD5: トラックマン等計測設備の利用 | BE5: 気軽に練習できる環境が欲しい
A6: 43574 | B6: 体験利用 | C6: 向田 忠男 | E6: 21045.081 | G6: 665-0886 | H6: 兵庫県宝塚市山手台西2-32-4 | I6: 2.3km | J6: 0797-80-0321 | L6: 会社経営者・役員 | T6: 入会 | V6: 入会 | AW6: TVのCM | AX6: シミュレーションシステムの活用 | AY6: 会員家族 | AZ6: 専業主婦 | BD6: シュミレーションを利用してみたい | BE6: ゴルフスイングの理論やテクニックに関する理解を深めたい
A7: 43574 | B7: 体験利用 | C7: 向田 香代子 | E7: 17020 | G7: 665-0886 | H7: 兵庫県宝塚市山手台西2-32-4 | I7: 2.3km | J7: 0797-80-0321 | L7: 会社経営者・役員 | T7: 入会 | V7: 入会 | AW7: youtube | AX7: 会員同士のコミュニケーション | AY7: パーソナルレッスン | AZ7: 学生 | BD7: スイングロボを利用してみたい
A8: 43575 | B8: 体験利用 | C8: 若松 明子 | E8: 26189 | G8: 665-0807 | H8: 兵庫県宝塚市長尾台2-12-14 | I8: 4.5km | J8: 072-755-6746 | L8: 会社員 | V8: 藤原美也子さん 知り合い | W8: 知人の紹介 | Y8: トラックマン等計測設備の利用 | AW8: ホームページ | AX8: 自宅が近いから | AY8: 無記入 | AZ8: その他
A9: 43576 | B9: フィッティング | C9: 山形 進 | E9: 23619 | G9: 561-0862 | H9: 大阪府豊中市西泉丘1-3-7-303 | I9: 11.5km | J9: 090-5090-7754 | V9: 社長 知り合い | W9: 知人の紹介 | Y9: その他 | AW9: 考え中 | AX9: 友人が入会しているから
A10: 43577 | B10: 体験利用 | C10: 若松 吉己 | E10: 23969 | G10: 665-0807 | H10: 兵庫県宝塚市長尾台2-12-14 | I10: 4.5km | J10: 090-5676-7162 | L10: 会社経営者・役員 | W10: 知人の紹介 | Y10: 天候に左右されない練習環境 | AW10: 新聞・雑誌の広告 | AX10: 会社が近いから
A11: 43579 | B11: 体験利用 | C11: 奥田 恭三 | E11: 23281 | G11: 665-0022 | H11: 兵庫県宝塚市野上1-9-21 | I11: 5.9km | J11: 090-8821-8537 | L11: 会社員 | W11: インターネット | Y11: 自宅が近いから | AW11: その他 | AX11: 飛距離を伸ばすため
A12: 43580 | B12: 体験利用 | C12: 亀谷 龍也 | E12: 23553 | G12: 553-0003 | H12: 大阪市福島区福島8-2-8 | I12: 19.9km | J12: 090-3263-7750 | L12: 自営業 | V12: 則藤さん 知り合い | W12: 知人の紹介 | AW12: 知人の紹介 | AX12: JPDA認定トレーナー在籍
A13: 43581 | B13: フィッティング | C13: 星山 美枝子 | E13: 26202 | G13: 671-1107 | H13: 兵庫県姫路市広畑区西蒲田1584 | I13: 89km | J13: 079-227-5106/090-5159-0260 | K13: kmtys293711@icloud.com | L13: 会社員 | V13: 永井さん知り合い シャフトご購入 | W13: 知人の紹介 | Y13: 飛距離を伸ばすため | AW13: 転勤になった | AX13: その他
A14: 43581 | B14: フィッティング | C14: 椎田 淑惠 | E14: 21104 | G14: 672-8048 | H14: 兵庫県姫路市飾磨区三宅3-24-2 | I14: 82.4 | J14: 090-2352-2381 | K14: ms.toshie-1011@au.com | L14: 自営業 | V14: 永井さん知り合い シャフトご購入 | W14: 知人の紹介 | Y14: シャフトの種類の多さ | AW14: 通りすがり
A15: 43581 | B15: 体験利用 | C15: 上野 佑 | E15: 30905 | G15: 665-0882 | H15: 兵庫県宝塚市山本南1-37-12-102 | I15: 0.6 | J15: 090-5380-6202 | L15: 会社員 | T15: 入会 | V15: 入会 | Y15: 自宅が近いから | AW15: 入会するとしたら10月から
A16: 43582 | B16: 体験利用 | C16: 寺村 貞利 | E16: 22298 | G16: 665-0886 | H16: 兵庫県宝塚市山手台西3-8-1-603 | I16: 4.9km | J16: 090-171-5014 | L16: 会社員 | W16: 知人の紹介 | Y16: トラックマン等計測設備の利用 | AW16: 不在
A17: 43582 | B17: 体験利用 | C17: 寺村 みどり | E17: 28654 | G17: 665-0886 | H17: 兵庫県宝塚市山手台西3-8-1-603 | I17: 4.9km | J17: 090-4756-8936 | L17: その他 | W17: 知人の紹介 | Y17: 自宅が近いから
A18: 43583 | B18: 体験利用 | C18: 日高 弘道 | E18: 29290 | G18: 665-0886 | H18: 兵庫県宝塚市山手台西1-3-3 | I18: 4.7km | J18: 090-7102-0880 | L18: 会社員 | W18: インターネット | Y18: シミュレーションシステムの活用
A19: 43583 | B19: フィッティング | C19: 田中 維知子 | E19: 24003 | G19: 550-0014 | H19: 大阪府大阪市西区北堀江2-5-5 | I19: 27.6km | J19: 06-6533-2050 | L19: 専業主婦 | V19: シャフトご購入 | W19: 知人の紹介 | Y19: シャフトの種類の多さ
A20: 43584 | B20: 体験利用 | C20: 川根 暁 | E20: 23188 | G20: 561-0859 | H20: 豊中市服部豊町1-2-2 アネックス服部202 | I20: 12.7km | J20: 090-8751-8973 | L20: 会社員 | W20: 知人の紹介 | Y20: トラックマン等計測設備の利用
A21: 43584 | B21: フィッティング | C21: 加藤 弦 | E21: 31126 | G21: 545-0022 | H21: 大阪府大阪市阿倍野区播磨町1-8-22 リーベル北畠ガーデンシティ402 | I21: 30.4km | J21: 080-1478-5606 | L21: 会社経営者・役員 | V21: シャフトご購入 | W21: 知人の紹介
A22: 43584 | B22: 体験利用 | C22: 永澤 祥行 | E22: 22738 | G22: 563-0050 | H22: 大阪府池田市新町10-7-202 | I22: 4.1km | J22: 090-2069-2223 | L22: 会社員 | W22: 知人の紹介 | Y22: シミュレーションシステムの活用
A23: 43585 | B23: フィッティング | C23: 石川 貴洋 | E23: 22923 | G23: 661-0021 | H23: 兵庫県尼崎市名神町2-9-37 | I23: 17.8km | J23: 06-6426-7496 | L23: 自営業 | V23: 社長 知り合い | W23: 知人の紹介 | Y23: 会員同士のコミュニケーション
A24: 43585 | B24: 体験利用 | C24: 竹田 正人 | J24: 090-1592-5048 | T24: 入会 | V24: 入会（法人）
A25: 43586 | B25: フィッティング | C25: 金山 熹章 | E25: 16771 | G25: 567-0009 | H25: 大阪府茨木市山手台5-25-17 | I25: 23.2km | J25: 090-2117-4423 | L25: 会社経営者・役員 | V25: シャフトご購入 | W25: 知人の紹介 | Y25: シャフトの種類の多さ
A26: 43588 | B26: 体験利用 | C26: 弓場 基司 | E26: 25022 | G26: 665-0873 | H26: 兵庫県宝塚市長尾町8-13-1003 | I26: 0.6km | J26: 080-9862-1119 | L26: 会社員 | W26: その他 | Y26: 自宅が近いから
A27: 43589 | B27: 体験利用 | C27: 小谷 光晴 | E27: 22861 | G27: 665-0874 | H27: 兵庫県宝塚市中筋2-9-12-308 | I27: 0.8km | J27: 0797-80-2329 | L27: 会社員 | W27: 知人の紹介 | Y27: トラックマン等計測設備の利用
A28: 43590 | B28: 体験利用 | C28: 楢崎 茂士 | E28: 22679 | G28: 665-0847 | H28: 兵庫県宝塚市すみれが丘3-2-1-1322 | I28: 6.6km | J28: 090-2517-5535 | L28: 会社員 | W28: 知人の紹介 | Y28: トラックマン等計測設備の利用 | AR28: 住所不明
A29: 43590 | B29: フィッティング | C29: 川津 颯太 | E29: 33647 | G29: 651-0056 | H29: 兵庫県神戸市中央区熊内町2-9-8 | I29: 38.3km | J29: 080-4316-6450 | L29: 自営業 | U29: 住所不明 | V29: 井殿プロお知り合いの浜プロお友達、シャフトご購入 | W29: インターネット | Y29: トラックマン等計測設備の利用
A30: 43591 | B30: 体験利用 | C30: 林 路人 | E30: 27499 | G30: 537-0002 | H30: 大阪府大阪市東成区深江南3-4-21 | I30: 29.6km | J30: 090-5048-7858 | W30: 知人の紹介
A31: 43591 | B31: 体験利用 | C31: 柴田 敏行 | E31: 25128 | G31: 571-0030 | H31: 大阪府門真市末広町18-22-307 | I31: 27.3km | J31: 080-3856-6063 | L31: 会社員 | W31: インターネット | Y31: シャフトの種類の多さ
A32: 43591 | B32: 体験利用 | C32: 高松 繁 | E32: 20391 | G32: 664-0857 | H32: 兵庫県伊丹市行基町4-50 | I32: 6.6km | J32: 090-7355-9319 | K32: s19551029@i.softbank.jp | L32: 会社員 | W32: インターネット | Y32: 飛距離を伸ばすため
A33: 43591 | B33: 体験利用 | C33: 堀古 一男 | E33: 22247 | G33: 664-0001 | H33: 兵庫県伊丹市荒牧1-8-5 | I33: 2km | J33: 090-3284-2385 | T33: 入会 | V33: ご入会（6か月まとめて現金払い） | W33: その他 | Y33: 自宅が近いから
A34: 43594 | B34: 体験利用 | C34: 藤島 一廣 | E34: 19139 | G34: 665-0874 | H34: 兵庫県宝塚市中筋7-6-17 | I34: 1.6km | J34: 0797-52-7617 | L34: その他 | Y34: PGAプロの在籍
A35: 43594 | B35: フィッティング | C35: 吉本 雅人 | E35: 24985 | G35: 563-0103 | H35: 大阪府豊能郡豊能町東ときわ台5-8-12 | I35: 13.8km | J35: 080-5700-5288 | L35: 会社員 | W35: 知人の紹介 | Y35: 飛距離を伸ばすため
A36: 43594 | B36: フィッティング | C36: 吉本 奈緒美 | E36: 27694 | G36: 563-0103 | H36: 大阪府豊能郡豊能町東ときわ台5-8-12 | I36: 13.8km | J36: 080-5343-3430 | L36: 会社員 | V36: シャフトプレゼントのお客様 | W36: 知人の紹介 | Y36: 飛距離を伸ばすため
A37: 43595 | B37: 体験利用 | C37: 西川 武尊 | E37: 29892 | G37: 573-0083 | H37: 大阪府枚方市茄子作北町56-10 | I37: 40.8km | J37: 090-3979-8733 | L37: 自営業 | V37: 自宅遠方のため今後ビジター利用希望 | W37: 知人の紹介 | Y37: 飛距離を伸ばすため
A38: 43595 | B38: 体験利用 | C38: 三上 栄治 | E38: 25161 | G38: 669-1112 | H38: 兵庫県西宮市宝生ヶ丘2-13-8 | I38: 7km | J38: 090-4561-6080 | L38: 会社経営者・役員 | W38: インターネット | Y38: シミュレーションシステムの活用
A39: 43595 | B39: シャフト試打 | C39: 平山 菊代 | E39: 23752 | G39: 561-0802 | H39: 大阪府豊中市曽根東町1-11-46-203 | I39: 11.1km | J39: 090-8829-5752 | L39: 会社員 | V39: 5本 | W39: 知人の紹介 | Y39: シャフトの種類の多さ
A40: 43595 | B40: シャフト試打 | C40: 小瀬 正也 | G40: 665-0823 | H40: 兵庫県宝塚市安倉2-8-13 | I40: 2.9km | V40: 5本 会員小瀬様のお連れ様 | W40: 知人の紹介
...

Sheet Sheet1
A1: 【2026年3月 経営報告用データ】
A3: ■会員
A4: 月初会員数： | B4: =月別会員数!CI38 -> 198
A5: 入会者数： | B5: =入会者!K26 -> 9
A6: 退会者数： | B6: =退会者!K25 -> 5
A7: 休会者数： | B7: 5
A8: 月末会員数： | B8: =月別会員数!CJ38 -> 202
A9: 会費売上： | B9: 3237000
A11: ■集客・入会
A12: 体験者数： | B12: =体験利用者数!K18 -> 12
A13: 体験からの入会者数： | B13: =体験利用者数!K19 -> 9
A14: 入会率： | B14: =B13/B12 -> 0.75
A15: 1か月以内入会： | B15: 不明
A16: 2か月以内入会： | B16: 不明
A18: ■流入経路
A19: 知人紹介： | B19: 2
A20: インターネット： | B20: 5
A21: SNS： | B21: 0
A22: YouTube： | B22: 0
A23: 通りすがり： | B23: 5
A24: その他： | B24: 0
A25: 無回答： | B25: 0
A27: ■物販売上
A28: 物販総売上： | B28: 809470
A29: ビジター物販： | B29: 388430
A30: 会員物販： | B30: 328980
A31: その他： | B31: 92060
A32: 仕入金額： | B32: 534089
A34: ■フィッティング
A35: 件数： | B35: 5
A36: 購入件数： | B36: 5
A37: 特記事項： | B37: プロ紹介２件、再来２件、新規１件
A39: ■レッスン
A40: パーソナルレッスン件数： | B40: 23
A41: プロ別内訳： | B41: 安東：２０件、卜部：１件、古川：２件
A43: ■広報・販促
A44: SNS投稿数： | B44: ５件
A45: 紹介施策の実績： | B45: 実施検討中
A46: ゴルフ場連携の進捗： | B46: 実施検討中
A47: 法人会員チラシ進捗： | B47: チラシ作成中、次は配布会社選定要
...

Sheet 入会者
A1: ２９期
A2: 新規入会 | B2: 6月 | C2: 7月 | D2: 8月 | E2: 9月 | F2: 10月 | G2: 11月 | H2: 12月 | I2: 1月 | J2: 2月 | K2: 3月 | L2: 4月 | M2: 5月
A3: マスター | B3: 1 | C3: 3 | D3: 2 | G3: 1 | I3: 1 | J3: 1 | M3: 0
A4: レギュラー | B4: 6 | C4: 5 | D4: 12 | E4: 8 | F4: 9 | G4: 8 | H4: 4 | I4: 6 | J4: 10 | K4: 9 | L4: 4 | M4: 5
A5: ライト | B5: 0 | C5: 0
A6: 法人 | B6: 0 | C6: 0 | L6: 1
A7: チケット | B7: 0 | C7: 1 | D7: 1 | G7: 1 | K7: 1 | L7: 1 | M7: 1
A8: 計 | B8: =SUM(B3:B7) -> 7 | C8: =SUM(C3:C7) -> 9 | D8: =SUM(D3:D7) -> 15 | E8: =SUM(E3:E7) -> 8 | F8: =SUM(F3:F7) -> 9 | G8: =SUM(G3:G7) -> 10 | H8: =SUM(H3:H7) -> 4 | I8: =SUM(I3:I7) -> 7 | ... M8: =SUM(M3:M7) -> 6
A10: ３０期
A11: 新規入会 | B11: 6月 | C11: 7月 | D11: 8月 | E11: 9月 | F11: 10月 | G11: 11月 | H11: 12月 | I11: 1月 | J11: 2月 | K11: 3月 | L11: 4月 | M11: 5月
A12: マスター | B12: 4 | C12: 2 | D12: 0 | E12: 2 | I12: 1 | L12: 1 | M12: 1
A13: レギュラー | B13: 5 | C13: 7 | D13: 6 | E13: 9 | F13: 5 | G13: 2 | H13: 3 | I13: 4 | J13: 3 | K13: 2 | L13: 3 | M13: 6
A14: ライト | D14: 0 | E14: 0
A15: 法人 | D15: 1 | E15: 0 | M15: 1
A16: チケット | D16: 1 | E16: 0 | F16: 1 | J16: 1 | K16: 1 | L16: 2
A17: 計 | B17: =SUM(B12:B16) -> 9 | C17: =SUM(C12:C16) -> 9 | D17: =SUM(D12:D16) -> 8 | E17: =SUM(E12:E16) -> 11 | F17: =SUM(F12:F16) -> 6 | G17: =SUM(G12:G16) -> 2 | H17: =SUM(H12:H16) -> 3 | I17: =SUM(I12:I16) -> 5 | ... M17: =SUM(M12:M16) -> 8
A19: ３１期
A20: 新規入会 | B20: 6月 | C20: 7月 | D20: 8月 | E20: 9月 | F20: 10月 | G20: 11月 | H20: 12月 | I20: 1月 | J20: 2月 | K20: 3月 | L20: 4月 | M20: 5月
A21: マスター | B21: 0 | C21: 2 | D21: 0 | E21: 0 | F21: 0 | G21: 1 | H21: 2 | I21: 1 | J21: 3 | K21: 2 | L21: 3 | M21: 2
A22: レギュラー | B22: 7 | C22: 6 | D22: 10 | E22: 5 | F22: 7 | G22: 8 | H22: 8 | I22: 1 | J22: 4 | K22: 6 | L22: 2 | M22: 8
A23: ライト | B23: 0 | C23: 0 | D23: 0 | E23: 0 | F23: 0 | G23: 0 | H23: 0 | I23: 0 | J23: 0 | L23: 0 | M23: 0
A24: 法人 | B24: 1 | C24: 1 | D24: 0 | E24: 2 | F24: 1 | G24: 1 | H24: 0 | I24: 0 | J24: 0 | L24: 1 | M24: 0
A25: チケット | B25: 0 | C25: 0 | D25: 1 | E25: 0 | F25: 0 | G25: 0 | H25: 0 | I25: 2 | J25: 1 | K25: 1 | L25: 1 | M25: 0
A26: 計 | B26: =SUM(B21:B25) -> 8 | C26: =SUM(C21:C25) -> 9 | D26: =SUM(D21:D25) -> 11 | E26: =SUM(E21:E25) -> 7 | F26: =SUM(F21:F25) -> 8 | G26: =SUM(G21:G25) -> 10 | H26: =SUM(H21:H25) -> 10 | I26: =SUM(I21:I25) -> 4 | ... M26: =SUM(M21:M25) -> 10
A27: トライアル | B27: 0 | C27: 2 | D27: 2 | E27: 0 | F27: 0 | G27: 0 | H27: 0 | I27: 0 | J27: 0 | K27: 0 | L27: 0 | M27: 4
A29: ３２ 期
A30: 新規入会 | B30: 6月 | C30: 7月 | D30: 8月 | E30: 9月 | F30: 10月 | G30: 11月 | H30: 12月 | I30: 1月 | J30: 2月 | K30: 3月 | L30: 4月 | M30: 5月
A31: マスター | B31: 2 | C31: 0 | D31: 0 | E31: 0 | F31: 0 | G31: 0 | H31: 0 | I31: 0 | J31: 0 | K31: 0 | L31: 0 | M31: 0
A32: レギュラー | B32: 3 | C32: 0 | D32: 0 | E32: 0 | F32: 0 | G32: 0 | H32: 0 | I32: 0 | J32: 0 | K32: 0 | L32: 0 | M32: 0
A33: ライト | B33: 0 | C33: 0 | D33: 0 | E33: 0 | F33: 0 | G33: 0 | H33: 0 | I33: 0 | J33: 0 | K33: 0 | L33: 0 | M33: 0
A34: 法人 | B34: 0 | C34: 0 | D34: 0 | E34: 0 | F34: 0 | G34: 0 | H34: 0 | I34: 0 | J34: 0 | K34: 0 | L34: 0 | M34: 0
A35: チケット | B35: 1 | C35: 0 | D35: 0 | E35: 0 | F35: 0 | G35: 0 | H35: 0 | I35: 0 | J35: 0 | K35: 0 | L35: 0 | M35: 0
A36: 計 | B36: =SUM(B31:B35) -> 6 | C36: =SUM(C31:C35) -> 0 | D36: =SUM(D31:D35) -> 0 | E36: =SUM(E31:E35) -> 0 | F36: =SUM(F31:F35) -> 0 | G36: =SUM(G31:G35) -> 0 | H36: =SUM(H31:H35) -> 0 | I36: =SUM(I31:I35) -> 0 | ... M36: =SUM(M31:M35) -> 0
A37: トライアル | B37: 2 | C37: 2 | D37: 2 | E37: 0 | F37: 0 | G37: 0 | H37: 0 | I37: 0 | J37: 0 | K37: 0 | L37: 0 | M37: 0

Sheet 退会者
A1: ２９期
A2: 退会数 | B2: 6月 | C2: 7月 | D2: 8月 | E2: 9月 | F2: 10月 | G2: 11月 | H2: 12月 | I2: 1月 | J2: 2月 | K2: 3月 | L2: 4月 | M2: 5月
A3: マスター | G3: 2 | I3: 1 | J3: 1 | K3: 2 | L3: 0
A4: レギュラー | B4: 5 | C4: 2 | D4: 3 | E4: 5 | F4: 4 | G4: 6 | H4: 7 | I4: 3 | J4: 5 | K4: 5 | L4: 1 | M4: 7
A5: ライト | B5: 1 | C5: 1 | G5: 1 | H5: 2
A6: 法人 | L6: 1 | M6: 1
A7: チケット | H7: 0 | I7: 1 | J7: 2 | K7: 1 | L7: 2 | M7: 1
A8: 退会者計 | B8: =SUM(B3:B7) -> 6 | C8: =SUM(C3:C7) -> 3 | D8: =SUM(D3:D7) -> 3 | E8: =SUM(E3:E7) -> 5 | F8: =SUM(F3:F7) -> 4 | G8: =SUM(G3:G7) -> 9 | H8: =SUM(H3:H7) -> 9 | I8: =SUM(I3:I7) -> 5 | ... M8: =SUM(M3:M7) -> 9
A9: ３０期
A10: 退会 | B10: 6月 | C10: 7月 | D10: 8月 | E10: 9月 | F10: 10月 | G10: 11月 | H10: 12月 | I10: 1月 | J10: 2月 | K10: 3月 | L10: 4月 | M10: 5月
A11: マスター | B11: 1 | C11: 3 | F11: 1 | K11: 2 | L11: 1 | M11: 1
A12: レギュラー | B12: 7 | C12: 3 | D12: 6 | E12: 8 | F12: 4 | G12: 7 | H12: 1 | I12: 5 | J12: 5 | K12: 3 | L12: 10 | M12: 3
A13: ライト | B13: 0
A14: 法人 | B14: 0 | D14: 1 | H14: 1
A15: チケット | B15: 1 | F15: 1 | G15: 1 | I15: 1 | J15: 1
A16: 計 | B16: =SUM(B11:B15) -> 9 | C16: =SUM(C11:C15) -> 6 | D16: =SUM(D11:D15) -> 7 | E16: =SUM(E11:E15) -> 8 | F16: =SUM(F11:F15) -> 6 | G16: =SUM(G11:G15) -> 8 | H16: =SUM(H11:H15) -> 2 | I16: =SUM(I11:I15) -> 6 | ... M16: =SUM(M11:M15) -> 4
A17: 退会率 | B17: =B16/月別会員数!BO38 -> 0.051136364 | C17: =C16/月別会員数!BP38 -> 0.033519553 | D17: =D16/月別会員数!BQ38 -> 0.038888889 | E17: =E16/月別会員数!BR38 -> 0.043715847 | F17: =F16/月別会員数!BS38 -> 0.032786885 | G17: =G16/月別会員数!BT38 -> 0.04519774 | H17: =H16/月別会員数!BU38 -> 0.011235955 | I17: =I16/月別会員数!BV38 -> 0.033898305 | ... M17: =M16/月別会員数!BZ38 -> 0.022988506
A18: ３１期
A19: 退会 | B19: 6月 | C19: 7月 | D19: 8月 | E19: 9月 | F19: 10月 | G19: 11月 | H19: 12月 | I19: 1月 | J19: 2月 | K19: 3月 | L19: 4月 | M19: 5月
A20: マスター | B20: 0 | C20: 0 | D20: 0 | E20: 1 | F20: 0 | G20: 0 | H20: 0 | I20: 0 | J20: 0 | K20: 0 | L20: 0 | M20: 0
A21: レギュラー | B21: 4 | C21: 6 | D21: 3 | E21: 6 | F21: 4 | G21: 4 | H21: 5 | I21: 4 | J21: 3 | K21: 5 | L21: 2 | M21: 6
A22: ライト | B22: 0 | C22: 0 | D22: 0 | E22: 0 | F22: 1 | G22: 0 | H22: 1 | I22: 0 | J22: 0 | K22: 0 | L22: 0 | M22: 0
A23: 法人 | B23: 0 | C23: 0 | D23: 0 | E23: 0 | F23: 0 | G23: 0 | H23: 1 | I23: 0 | J23: 0 | K23: 0 | L23: 0 | M23: 0
A24: チケット | B24: 1 | C24: 0 | D24: 2 | E24: 2 | F24: 0 | G24: 0 | H24: 0 | I24: 0 | J24: 0 | K24: 0 | L24: 0 | M24: 0
A25: 計 | B25: =SUM(B20:B24) -> 5 | C25: =SUM(C20:C24) -> 6 | D25: =SUM(D20:D24) -> 5 | E25: =SUM(E20:E24) -> 9 | F25: =SUM(F20:F24) -> 5 | G25: =SUM(G20:G24) -> 4 | H25: =SUM(H20:H24) -> 7 | I25: =SUM(I20:I24) -> 4 | ... M25: =SUM(M20:M24) -> 6
A26: ３２期
A27: 退会 | B27: 6月 | C27: 7月 | D27: 8月 | E27: 9月 | F27: 10月 | G27: 11月 | H27: 12月 | I27: 1月 | J27: 2月 | K27: 3月 | L27: 4月 | M27: 5月
A28: マスター | B28: 0 | C28: 0 | D28: 0 | E28: 0 | F28: 0 | G28: 0 | H28: 0 | I28: 0 | J28: 0 | K28: 0 | L28: 0 | M28: 0
A29: レギュラー | B29: 7 | C29: 0 | D29: 0 | E29: 0 | F29: 0 | G29: 0 | H29: 0 | I29: 0 | J29: 0 | K29: 0 | L29: 0 | M29: 0
A30: ライト | B30: 0 | C30: 0 | D30: 0 | E30: 0 | F30: 0 | G30: 0 | H30: 0 | I30: 0 | J30: 0 | K30: 0 | L30: 0 | M30: 0
A31: 法人 | B31: 0 | C31: 0 | D31: 0 | E31: 0 | F31: 0 | G31: 0 | H31: 0 | I31: 0 | J31: 0 | K31: 0 | L31: 0 | M31: 0
A32: チケット | B32: 0 | C32: 0 | D32: 0 | E32: 0 | F32: 0 | G32: 0 | H32: 0 | I32: 0 | J32: 0 | K32: 0 | L32: 0 | M32: 0
A33: 計 | B33: =SUM(B28:B32) -> 7 | C33: =SUM(C28:C32) -> 0 | D33: =SUM(D28:D32) -> 0 | E33: =SUM(E28:E32) -> 0 | F33: =SUM(F28:F32) -> 0 | G33: =SUM(G28:G32) -> 0 | H33: =SUM(H28:H32) -> 0 | I33: =SUM(I28:I32) -> 0 | ... M33: =SUM(M28:M32) -> 0

Sheet 体験利用者数
A1: 27期 | I1: 1月 | J1: 2月 | K1: 3月 | L1: 4月 | M1: 5月 | O1: 合計 | Q1: 平均
A2: 体験者数(名) | I2: 22 | J2: 18 | K2: 9 | L2: 13 | M2: 14 | O2: =SUM(G2:N2) -> 76 | Q2: =O2/12 -> 6.3333333
A3: 入会者数(名) | I3: 5 | J3: 10 | K3: 8 | L3: 0 | M3: 4 | O3: =SUM(G3:N3) -> 27 | Q3: =O3/12 -> 2.25
A5: 28期 | B5: 6月 | C5: 7月 | D5: 8月 | E5: 9月 | F5: 10月 | G5: 11月 | H5: 12月 | I5: 1月 | J5: 2月 | K5: 3月 | L5: 4月 | M5: 5月 | O5: 合計 | Q5: 平均
A6: 体験者数(名) | B6: 10 | C6: 8 | D6: 9 | E6: 10 | F6: 9 | G6: 13 | H6: 10 | I6: 13 | J6: 13 | K6: 9 | L6: 13 | M6: 12 | O6: =SUM(I6:N6) -> 60 | Q6: =O6/12 -> 5
A7: 入会者数(名) | B7: 6 | C7: 3 | D7: 7 | E7: 6 | F7: 6 | G7: 4 | H7: 4 | I7: 11 | J7: 4 | K7: 9 | L7: 8 | M7: 6 | O7: =SUM(I7:N7) -> 38 | Q7: =O7/12 -> 3.1666667
A9: 29期 | B9: 6月 | C9: 7月 | D9: 8月 | E9: 9月 | F9: 10月 | G9: 11月 | H9: 12月 | I9: 1月 | J9: 2月 | K9: 3月 | L9: 4月 | M9: 5月 | O9: 合計 | Q9: 平均
A10: 体験者数(名) | B10: 7 | C10: 13 | D10: 8 | E10: 8 | F10: 11 | G10: 14 | H10: 6 | I10: 11 | J10: 12 | K10: 8 | L10: 7 | M10: 6 | O10: =SUM(I10:M10) -> 44 | Q10: =O10/12 -> 3.6666667
A11: 入会者数(名) | B11: 7 | C11: 9 | D11: 15 | E11: 8 | F11: 9 | G11: 10 | H11: 4 | I11: 7 | J11: 11 | K11: 10 | L11: 6 | M11: 6 | O11: =SUM(I11:N11) -> 40 | Q11: =O11/12 -> 3.3333333
A13: 30期 | B13: 6月 | C13: 7月 | D13: 8月 | E13: 9月 | F13: 10月 | G13: 11月 | H13: 12月 | I13: 1月 | J13: 2月 | K13: 3月 | L13: 4月 | M13: 5月 | O13: 合計 | Q13: 平均
A14: 体験者数(名) | B14: 12 | C14: 5 | D14: 11 | E14: 5 | F14: 2 | G14: 3 | H14: 5 | I14: 9 | J14: 3 | K14: 8 | L14: 14 | M14: 5 | O14: =SUM(I14:M14) -> 39 | Q14: =O14/12 -> 3.25
A15: 入会者数(名) | B15: 9 | C15: 9 | D15: 8 | E15: 11 | F15: 6 | G15: 2 | H15: 3 | I15: 5 | J15: 4 | K15: 3 | L15: 6 | M15: 4 | O15: =SUM(I15:M15) -> 22 | Q15: =O15/12 -> 1.8333333
A17: 31期 | B17: 6月 | C17: 7月 | D17: 8月 | E17: 9月 | F17: 10月 | G17: 11月 | H17: 12月 | I17: 1月 | J17: 2月 | K17: 3月 | L17: 4月 | M17: 5月 | O17: 合計 | Q17: 平均
A18: 体験者数(名) | B18: 7 | C18: 15 | D18: 13 | E18: 21 | F18: 14 | G18: 22 | H18: 9 | I18: 19 | J18: 21 | K18: 12 | L18: 10 | M18: 19 | O18: =SUM(B18:M18) -> 182 | Q18: =O18/10 -> 18.2
A19: 入会者数(名) | B19: =入会者!B26 -> 8 | C19: 11 | D19: 11 | E19: 5 | F19: 8 | G19: 10 | H19: 10 | I19: 4 | J19: 8 | K19: 9 | L19: 7 | M19: 10 | O19: =SUM(B19:M19) -> 101 | Q19: =O19/12 -> 8.4166667
D20: trial１
H23: 30期 | I23: 何を見てきたか | J23: 来店数 | K23: 割合 | L23: 入会数 | M23: 入会率
I24: SNS | J24: 6 | K24: =J24/J31 -> 0.073170732 | L24: 4 | M24: =L24/J24 -> 0.66666667
I25: インターネット | J25: 30 | K25: =J25/$J$31 -> 0.36585366 | L25: 21 | M25: =L25/J25 -> 0.7
I26: 知人の紹介 | J26: 13 | K26: =J26/$J$31 -> 0.15853659 | L26: 9 | M26: =L26/J26 -> 0.69230769
I27: チラシ | J27: 3 | K27: =J27/$J$31 -> 0.036585366 | L27: 0 | M27: =L27/J27 -> 0
I28: 通りすがり | J28: 21 | K28: =J28/$J$31 -> 0.25609756 | L28: 9 | M28: =L28/J28 -> 0.42857143
I29: その他 | J29: 4 | K29: =J29/$J$31 -> 0.048780488 | L29: 2 | M29: =L29/J29 -> 0.5
I30: 未回答 | J30: 5 | K30: =J30/$J$31 -> 0.06097561 | L30: 2 | M30: =L30/J30 -> 0.4
I31: 合計 | J31: =SUM(J24:J30) -> 82

Sheet フィッティング者数
A2: 28期 | B2: 6月 | C2: 7月 | D2: 8月 | E2: 9月 | F2: 10月 | G2: 11月 | H2: 12月 | I2: 1月 | J2: 2月 | K2: 3月 | L2: 4月 | M2: 5月 | O2: 合計 | Q2: 平均
A3: フィッティング者数(名) | B3: 8 | C3: 13 | D3: 13 | E3: 15 | F3: 9 | G3: 13 | H3: 6 | I3: 12 | J3: 7 | K3: 13 | L3: 8 | M3: 9 | O3: =SUM(B3:N3) -> 126 | Q3: =O3/12 -> 10.5
A4: 購入者数(名) | B4: 4 | C4: 9 | D4: 6 | E4: 8 | F4: 5 | G4: 6 | H4: 5 | I4: 7 | J4: 5 | K4: 10 | L4: 7 | M4: 7 | O4: =SUM(B4:M4) -> 79 | Q4: =O4/12 -> 6.5833333
A5: 購入率 | B5: =B4/B3 -> 0.5 | C5: =C4/C3 -> 0.69230769 | D5: =D4/D3 -> 0.46153846 | E5: =E4/E3 -> 0.53333333 | F5: =F4/F3 -> 0.55555556 | G5: =G4/G3 -> 0.46153846 | H5: =H4/H3 -> 0.83333333 | I5: =I4/I3 -> 0.58333333 | ... M5: =M4/M3 -> 0.77777778
A7: 29期 | B7: 6月 | C7: 7月 | D7: 8月 | E7: 9月 | F7: 10月 | G7: 11月 | H7: 12月 | I7: 1月 | J7: 2月 | K7: 3月 | L7: 4月 | M7: 5月 | O7: 合計 | Q7: 平均
A8: フィッティング者数(名) | B8: 9 | C8: 8 | D8: 10 | E8: 6 | F8: 9 | G8: 12 | H8: 4 | I8: 13 | J8: 14 | K8: 17 | L8: 12 | M8: 10 | O8: =SUM(B8:N8) -> 124 | Q8: =O8/12 -> 10.333333
A9: 購入者数(名) | B9: 6 | C9: 2 | D9: 7 | E9: 3 | F9: 6 | G9: 7 | H9: 4 | I9: 7 | J9: 12 | K9: 12 | L9: 10 | M9: 7 | O9: =SUM(B9:N9) -> 83 | Q9: =O9/12 -> 6.9166667
A10: 購入率 | B10: =B9/B8 -> 0.66666667 | C10: =C9/C8 -> 0.25 | D10: =D9/D8 -> 0.7 | E10: =E9/E8 -> 0.5 | F10: =F9/F8 -> 0.66666667 | G10: =G9/G8 -> 0.58333333 | H10: =H9/H8 -> 1 | I10: =I9/I8 -> 0.53846154 | ... M10: =M9/M8 -> 0.7
A12: 30期 | B12: 6月 | C12: 7月 | D12: 8月 | E12: 9月 | F12: 10月 | G12: 11月 | H12: 12月 | I12: 1月 | J12: 2月 | K12: 3月 | L12: 4月 | M12: 5月 | O12: 合計 | Q12: 平均
A13: フィッティング者数(名) | B13: 16 | C13: 20 | D13: 6 | E13: 11 | F13: 11 | G13: 17 | H13: 4 | I13: 6 | J13: 12 | K13: 4 | L13: 12 | M13: 12 | O13: =SUM(B13:M13) -> 131 | Q13: =O13/12 -> 10.916667
A14: 購入者数(名) | B14: 10 | C14: 14 | D14: 4 | E14: 8 | F14: 8 | G14: 12 | H14: 3 | I14: 4 | J14: 11 | K14: 3 | L14: 8 | M14: 7 | O14: =SUM(B14:N14) -> 92 | Q14: =O14/12 -> 7.6666667
A15: 購入率 | B15: =B14/B13 -> 0.625 | C15: =C14/C13 -> 0.7 | D15: =D14/D13 -> 0.66666667 | E15: =E14/E13 -> 0.72727273 | F15: =F14/F13 -> 0.72727273 | G15: =G14/G13 -> 0.70588235 | H15: =H14/H13 -> 0.75 | I15: =I14/I13 -> 0.66666667 | ... M15: =M14/M13 -> 0.58333333
A17: 31期 | B17: 6月 | C17: 7月 | D17: 8月 | E17: 9月 | F17: 10月 | G17: 11月 | H17: 12月 | I17: 1月 | J17: 2月 | K17: 3月 | L17: 4月 | M17: 5月 | O17: 合計 | Q17: 平均
A18: フィッティング者数(名) | B18: 9 | C18: 14 | D18: 6 | E18: 6 | F18: 6 | G18: 9 | H18: 7 | I18: 6 | J18: 2 | K18: 5 | L18: 8 | M18: 14 | O18: =SUM(B18:M18) -> 92 | Q18: =O18/12 -> 7.6666667
A19: 購入者数(名) | B19: 5 | C19: 10 | D19: 5 | E19: 2 | F19: 4 | G19: 4 | H19: 5 | I19: 3 | J19: 2 | K19: 5 | L19: 6 | M19: 9 | O19: =SUM(B19:M19) -> 60 | Q19: =O19/12 -> 5
A20: 購入率 | B20: =B19/B18 -> 0.55555556 | C20: =C19/C18 -> 0.71428571 | D20: =D19/D18 -> 0.83333333 | E20: =E19/E18 -> 0.33333333 | F20: =F19/F18 -> 0.66666667 | G20: =G19/G18 -> 0.44444444 | H20: =H19/H18 -> 0.71428571 | I20: =I19/I18 -> 0.5 | ... M20: =M19/M18 -> 0.64285714
A22: 32期 | B22: 6月 | C22: 7月 | D22: 8月 | E22: 9月 | F22: 10月 | G22: 11月 | H22: 12月 | I22: 1月 | J22: 2月 | K22: 3月 | L22: 4月 | M22: 5月
A23: フィッティング者数(名) | B23: 0 | C23: 0 | D23: 0 | E23: 0 | F23: 0 | G23: 0 | H23: 0 | I23: 0 | J23: 0 | K23: 0 | L23: 0 | M23: 0
A24: 購入者数(名) | B24: 0 | C24: 0 | D24: 0 | E24: 0 | F24: 0 | G24: 0 | H24: 0 | I24: 0 | J24: 0 | K24: 0 | L24: 0 | M24: 0
A25: 購入率 | B25: =B24/B23 -> #DIV/0! | C25: =C24/C23 -> #DIV/0! | D25: =D24/D23 -> #DIV/0! | E25: =E24/E23 -> #DIV/0! | F25: =F24/F23 -> #DIV/0! | G25: =G24/G23 -> #DIV/0! | H25: =H24/H23 -> #DIV/0! | I25: =I24/I23 -> #DIV/0! | ... M25: =M24/M23 -> #DIV/0!

Sheet 月初報告
A1: 30期 | B1: ６月 | C1: ７月 | D1: ８月 | E1: ９月 | F1: １０月 | G1: １１月 | H1: １２月 | I1: １月 | J1: ２月 | K1: ３月 | L1: ４月 | M1: ５月
A2: 入会者 | B2: =月別会員数!BO9 -> 9 | C2: =月別会員数!BP9 -> 9 | D2: =月別会員数!BQ9 -> 8 | E2: =月別会員数!BR9 -> 11 | F2: =月別会員数!BS9 -> 6 | G2: =月別会員数!BT9 -> 2 | H2: =月別会員数!BU9 -> 3 | I2: =月別会員数!BV9 -> 5 | ... M2: =月別会員数!BZ9 -> 8
A3: 退会者 | B3: =月別会員数!BO19 -> 9 | C3: =月別会員数!BP19 -> 6 | D3: =月別会員数!BQ19 -> 7 | E3: =月別会員数!BR19 -> 8 | F3: =月別会員数!BS19 -> 6 | G3: =月別会員数!BT19 -> 8 | H3: =月別会員数!BU19 -> 2 | I3: =月別会員数!BV19 -> 6 | ... M3: =月別会員数!BZ19 -> 4
A4: 体験 | B4: =体験利用者数!B14 -> 12 | C4: =体験利用者数!C14 -> 5 | D4: =体験利用者数!D14 -> 11 | E4: =体験利用者数!E14 -> 5 | F4: =体験利用者数!F14 -> 2 | G4: =体験利用者数!G14 -> 3 | H4: =体験利用者数!H14 -> 5 | I4: =体験利用者数!I14 -> 9 | ... M4: =体験利用者数!M14 -> 5
A5: フィッティング数 | B5: =フィッティング者数!B13 -> 16 | C5: =フィッティング者数!C13 -> 20 | D5: =フィッティング者数!D13 -> 6 | E5: =フィッティング者数!E13 -> 11 | F5: =フィッティング者数!F13 -> 11 | G5: =フィッティング者数!G13 -> 17 | H5: =フィッティング者数!H13 -> 4 | I5: =フィッティング者数!I13 -> 6 | ... M5: =フィッティング者数!M13 -> 12
A6: 物販売上総額 | M6: 1114215
A7: ビジター | M7: 628910
A8: 会員 | M8: 311100
A9: シャフト | M9: 585800
A10: ヘッド | M10: 270000
A14: ３１期 | B14: ６月 | C14: ７月 | D14: ８月 | E14: ９月 | F14: １０月 | G14: １１月 | H14: １２月 | I14: １月 | J14: ２月 | K14: ３月 | L14: ４月 | M14: ５月
A15: 入会者 | B15: =月別会員数!CA9 -> 7 | C15: 9 | D15: =月別会員数!CC9 -> 11 | E15: =月別会員数!CD9 -> 7 | F15: =月別会員数!CE9 -> 8 | G15: =月別会員数!CF9 -> 10 | H15: =月別会員数!CG9 -> 10 | I15: =月別会員数!CH9 -> 4 | J15: =月別会員数!CI9 -> 8 | K15: =月別会員数!CJ9 -> 9 | ... M15: =月別会員数!CL9 -> 10
A16: 退会者 | B16: =退会者!B25 -> 5 | C16: =退会者!C25 -> 6 | D16: =退会者!D25 -> 5 | E16: =退会者!E25 -> 9 | F16: =退会者!F25 -> 5 | G16: =退会者!G25 -> 4 | H16: =退会者!H25 -> 7 | I16: =退会者!I25 -> 4 | ... M16: =退会者!M25 -> 6
A17: 体験 | B17: =体験利用者数!B18 -> 7 | C17: =体験利用者数!C18 -> 15 | D17: =体験利用者数!D18 -> 13 | E17: =体験利用者数!E18 -> 21 | F17: =体験利用者数!F18 -> 14 | G17: =体験利用者数!G18 -> 22 | H17: =体験利用者数!H18 -> 9 | I17: =体験利用者数!I18 -> 19 | ... M17: =体験利用者数!M18 -> 19
A18: フィッティング数 | B18: {=フィッティング者数!B18:M18} -> 9 | C18: 14 | D18: 6 | E18: 6 | F18: 6 | G18: 9 | H18: 7 | I18: 6 | J18: 2 | K18: 5 | L18: 8 | M18: 14
A19: 物販売上総額
A20: ビジター
A21: 会員
A22: シャフト
A23: ヘッド

Sheet 月別会員数
C1: 2019年 | L1: 2020年 | CT1: 1
C2: 4月 | D2: 5月 | E2: 6月 | F2: 7月 | G2: 8月 | H2: 9月 | I2: 10月 | J2: 11月 | K2: 12月 | L2: 1月 | M2: 2月 | N2: 3月 | O2: 4月 | P2: 5月 | S2: 26期 | AE2: 27期 | AQ2: 28期 | BC2: 29期 | BO2: 30期 | CA2: 31期
A3: 新規入会 | B3: プラチナ | R3: 新規入会 | S3: 6月 | T3: 7月 | U3: 8月 | V3: 9月 | W3: 10月 | X3: 11月 | Y3: 12月 | Z3: 1月 | AA3: 2月 | AB3: 3月 | AC3: 4月 | AD3: 5月 | AE3: 6月 | AF3: 7月 | AG3: 8月 | AH3: 9月 | AI3: 10月 | AJ3: 11月 | AK3: 12月 | AL3: 1月 | AM3: 2月 | AN3: 3月 | AO3: 4月 | AP3: 5月 | AQ3: 6月 | AR3: 7月 | AS3: 8月 | AT3: 9月 | AU3: 10月 | AV3: 11月 | AW3: 12月 | AX3: 1月 | AY3: 2月 | AZ3: 3月 | BA3: 4月 | BB3: 5月 | BC3: 6月 | BD3: 7月 | BE3: 8月 | BF3: 9月 | BG3: 10月 | BH3: 11月 | BI3: 12月 | BJ3: 1月 | BK3: 2月 | BL3: 3月 | BM3: 4月 | BN3: 5月 | BO3: 6月 | BP3: 7月 | BQ3: 8月 | BR3: 9月 | BS3: 10月 | BT3: 11月 | BU3: 12月 | BV3: 1月 | BW3: 2月 | BX3: 3月 | BY3: 4月 | BZ3: 5月 | CA3: 6月 | CB3: 7月 | CC3: 8月 | CD3: 9月 | CE3: 10月 | CF3: 11月 | CG3: 12月 | CH3: 1月 | CI3: 2月 | CJ3: 3月 | CK3: 4月 | CL3: 5月 | CM3: 6月 | CN3: 7月 | CO3: 8月 | CP3: 9月 | CQ3: 10月 | CR3: 11月
B4: マスター | C4: 3 | E4: 1 | F4: 3 | R4: マスター | S4: 1 | T4: 0 | U4: 1 | V4: 2 | W4: 1 | X4: 2 | Y4: 0 | Z4: 2 | AA4: 1 | AB4: 0 | AC4: 0 | AD4: 0 | AE4: 0 | AF4: 0 | AG4: 2 | AH4: 1 | AI4: 0 | AJ4: 0 | AK4: 2 | AL4: 1 | AM4: 1 | AN4: 1 | AO4: 0 | AP4: 3 | AQ4: 0 | AR4: 0 | AS4: 0 | AT4: 0 | AU4: 0 | AV4: 1 | AW4: 1 | AX4: 0 | AY4: 0 | AZ4: 0 | BA4: 0 | BB4: 0 | BC4: 1 | BD4: 3 | BE4: 2 | BH4: 1 | BJ4: 1 | BK4: 1 | BN4: 0 | BO4: 4 | BP4: 2 | BR4: 2 | BV4: 1 | BY4: 1 | BZ4: 1 | CA4: 0 | CB4: 1 | CC4: 0 | CD4: 0 | CE4: 0 | CF4: 1 | CG4: 2 | CH4: 1 | CI4: 3 | CJ4: =入会者!K21 -> 2 | CK4: =入会者!L21 -> 3 | CL4: 2
B5: レギュラー | C5: 14 | D5: 13 | E5: 5 | F5: 6 | G5: 8 | H5: 6 | I5: 1 | J5: 3 | K5: 2 | L5: 10 | M5: 2 | N5: 0 | O5: 3 | P5: 2 | R5: レギュラー | S5: 10 | T5: 3 | U5: 1 | V5: 2 | W5: 5 | X5: 4 | Y5: 7 | Z5: 6 | AA5: 3 | AB5: 9 | AC5: 6 | AD5: 8 | AE5: 5 | AF5: 5 | AG5: 7 | AH5: 7 | AI5: 2 | AJ5: 6 | AK5: 3 | AL5: 4 | AM5: 8 | AN5: 5 | AO5: 0 | AP5: 1 | AQ5: 6 | AR5: 3 | AS5: 5 | AT5: 5 | AU5: 6 | AV5: 3 | AW5: 2 | AX5: 8 | AY5: 4 | AZ5: 5 | BA5: 8 | BB5: 5 | BC5: 6 | BD5: 5 | BE5: 12 | BF5: 8 | BG5: 9 | BH5: 8 | BI5: 4 | BJ5: 6 | BK5: 10 | BL5: 9 | BM5: 4 | BN5: 5 | BO5: 5 | BP5: 7 | BQ5: 6 | BR5: 9 | BS5: 5 | BT5: 2 | BU5: 3 | BV5: 4 | BW5: 3 | BX5: 2 | BY5: 3 | BZ5: 6 | CA5: 7 | CB5: 8 | CC5: 10 | CD5: 5 | CE5: 7 | CF5: 8 | CG5: 8 | CH5: 1 | CI5: 4 | CJ5: =入会者!K22 -> 6 | CK5: =入会者!L22 -> 2 | CL5: 8
B6: ライト | R6: ライト | S6: 11 | T6: 4 | U6: 4 | V6: 1 | W6: 10 | X6: 7 | Y6: 4 | Z6: 8 | AA6: 4 | AB6: 1 | AC6: 2 | AD6: 0 | AE6: 1 | AF6: 1 | AG6: 0 | AH6: 0 | AI6: 0 | AJ6: 1 | AK6: 0 | AL6: 0 | AM6: 0 | AN6: 0 | AO6: 0 | AP6: 0 | AQ6: 0 | AR6: 0 | AS6: 0 | AT6: 0 | AU6: 0 | AV6: 0 | AW6: 0 | AX6: 0 | AY6: 0 | AZ6: 0 | BA6: 0 | BB6: 0 | BC6: 0 | BD6: 0 | CA6: 0 | CB6: 0 | CC6: 0 | CD6: 0 | CE6: 0 | CF6: 0 | CG6: 0 | CJ6: =入会者!K23 -> 0 | CK6: =入会者!L23 -> 0 | CL6: 0
B7: 法人 | C7: 2 | D7: 1 | R7: 法人 | S7: 0 | T7: 0 | U7: 0 | V7: 0 | W7: 0 | X7: 0 | Y7: 0 | Z7: 1 | AA7: 0 | AB7: 0 | AC7: 0 | AD7: 0 | AE7: 0 | AF7: 0 | AG7: 0 | AH7: 0 | AI7: 0 | AJ7: 0 | AK7: 0 | AL7: 0 | AM7: 0 | AN7: 1 | AO7: 0 | AP7: 0 | AQ7: 0 | AR7: 0 | AS7: 0 | AT7: 0 | AU7: 0 | AV7: 0 | AW7: 0 | AX7: 0 | AY7: 0 | AZ7: 2 | BA7: 0 | BB7: 0 | BC7: 0 | BD7: 0 | BM7: 1 | BQ7: 1 | BZ7: 1 | CA7: 0 | CB7: 0 | CC7: 0 | CD7: 2 | CE7: 1 | CF7: 1 | CG7: 0 | CJ7: =入会者!K24 -> 0 | CK7: =入会者!L24 -> 1 | CL7: 0
B8: チケット | R8: チケット | S8: 0 | T8: 0 | U8: 1 | V8: 0 | W8: 0 | X8: 1 | Y8: 0 | Z8: 0 | AA8: 0 | AB8: 0 | AC8: 2 | AD8: 1 | AE8: 0 | AF8: 0 | AG8: 1 | AH8: 1 | AI8: 0 | AJ8: 0 | AK8: 0 | AL8: 0 | AM8: 1 | AN8: 1 | AO8: 0 | AP8: 0 | AQ8: 0 | AR8: 0 | AS8: 2 | AT8: 1 | AU8: 0 | AV8: 0 | AW8: 1 | AX8: 3 | AY8: 0 | AZ8: 2 | BA8: 0 | BB8: 1 | BC8: 0 | BD8: 1 | BE8: 1 | BH8: 1 | BL8: 1 | BM8: 1 | BN8: 1 | BQ8: 1 | BS8: 1 | BW8: 1 | BX8: 1 | BY8: 2 | CA8: 0 | CB8: 1 | CC8: 1 | CD8: 0 | CE8: 0 | CF8: 0 | CG8: 0 | CH8: 2 | CI8: 1 | CJ8: =入会者!K25 -> 1 | CK8: =入会者!L25 -> 1 | CL8: 0
B9: 計 | C9: =SUM(C3:C8) -> 19 | D9: =SUM(D3:D8) -> 14 | E9: =SUM(E3:E8) -> 6 | F9: =SUM(F3:F8) -> 9 | G9: =SUM(G3:G8) -> 8 | H9: =SUM(H3:H8) -> 6 | I9: =SUM(I3:I8) -> 1 | J9: =SUM(J3:J8) -> 3 | ... P9: =SUM(P3:P8) -> 2 | R9: 計 | S9: =SUM(S4:S8) -> 22 | T9: =SUM(T4:T8) -> 7 | U9: =SUM(U4:U8) -> 7 | V9: =SUM(V4:V8) -> 5 | W9: =SUM(W4:W8) -> 16 | X9: =SUM(X4:X8) -> 14 | Y9: =SUM(Y4:Y8) -> 11 | Z9: =SUM(Z4:Z8) -> 17 | ... AN9: =SUM(AN4:AN8) -> 8 | AO9: 0 | AP9: 3 | AQ9: =SUM(AQ4:AQ8) -> 6 | AR9: =SUM(AR4:AR8) -> 3 | AS9: =SUM(AS4:AS8) -> 7 | AT9: =SUM(AT4:AT8) -> 6 | AU9: =SUM(AU4:AU8) -> 6 | AV9: =SUM(AV4:AV8) -> 4 | AW9: =SUM(AW4:AW8) -> 4 | AX9: =SUM(AX4:AX8) -> 11 | ... BD9: =SUM(BD4:BD8) -> 9 | BE9: =SUM(BE3:BE8) -> 15 | BF9: =SUM(BF3:BF8) -> 8 | BG9: =SUM(BG3:BG8) -> 9 | BH9: =SUM(BH3:BH8) -> 10 | BI9: =SUM(BI3:BI8) -> 4 | BJ9: =SUM(BJ3:BJ8) -> 7 | BK9: =SUM(BK3:BK8) -> 11 | BL9: =SUM(BL3:BL8) -> 10 | ... BN9: =SUM(BN3:BN8) -> 6 | BO9: 9 | BP9: 9 | BQ9: 8 | BR9: 11 | BS9: 6 | BT9: 2 | BU9: 3 | BV9: 5 | BW9: 4 | BX9: 3 | BY9: 6 | BZ9: 8 | CA9: =SUM(CA4:CA8) -> 7 | CB9: =SUM(CB4:CB8) -> 10 | CC9: =SUM(CC3:CC8) -> 11 | CD9: =SUM(CD3:CD8) -> 7 | CE9: =SUM(CE3:CE8) -> 8 | CF9: =SUM(CF3:CF8) -> 10 | CG9: =SUM(CG3:CG8) -> 10 | CH9: =SUM(CH3:CH8) -> 4 | CI9: =SUM(CI3:CI8) -> 8 | CJ9: =SUM(CJ3:CJ8) -> 9 | ... CL9: =SUM(CL3:CL8) -> 10
AP10: =SUM(AE9:AP9) -> 71 | BB10: =SUM(AQ9:BB9) -> 74 | BN10: =SUM(BC9:BN9) -> 102 | BZ10: =SUM(BO9:BZ9) -> 74 | CB10: tri 2 | CC10: tri 1 | CD10: triから入会 | CL10: =SUM(CA9:CL9) -> 101
C11: 2019年 | L11: 2020年
C12: 4月 | D12: 5月 | E12: 6月 | F12: 7月 | G12: 8月 | H12: 9月 | I12: 10月 | J12: 11月 | K12: 12月 | L12: 1月 | M12: 2月 | N12: 3月 | O12: 4月 | P12: 5月 | S12: 26期 | AE12: 27期 | AQ12: 28期 | BC12: 29期 | BO12: 30期 | CA12: 31期
A13: 退会数 | B13: プラチナ | R13: 退会数 | S13: 6月 | T13: 7月 | U13: 8月 | V13: 9月 | W13: 10月 | X13: 11月 | Y13: 12月 | Z13: 1月 | AA13: 2月 | AB13: 3月 | AC13: 4月 | AD13: 5月 | AE13: 6月 | AF13: 7月 | AG13: 8月 | AH13: 9月 | AI13: 10月 | AJ13: 11月 | AK13: 12月 | AL13: 1月 | AM13: 2月 | AN13: 3月 | AO13: 4月 | AP13: 5月 | AQ13: 6月 | AR13: 7月 | AS13: 8月 | AT13: 9月 | AU13: 10月 | AV13: 11月 | AW13: 12月 | AX13: 1月 | AY13: 2月 | AZ13: 3月 | BA13: 4月 | BB13: 5月 | BC13: 6月 | BD13: 7月 | BE13: 8月 | BF13: 9月 | BG13: 10月 | BH13: 11月 | BI13: 12月 | BJ13: 1月 | BK13: 2月 | BL13: 3月 | BM13: 4月 | BN13: 5月 | BO13: 6月 | BP13: 7月 | BQ13: 8月 | BR13: 9月 | BS13: 10月 | BT13: 11月 | BU13: 12月 | BV13: 1月 | BW13: 2月 | BX13: 3月 | BY13: 4月 | BZ13: 5月 | CA13: 6月 | CB13: 7月 | CC13: 8月 | CD13: 9月 | CE13: 10月 | CF13: 11月 | CG13: 12月 | CH13: 1月 | CI13: 2月 | CJ13: 3月 | CK13: 4月 | CL13: 5月 | CM13: 6月 | CN13: 7月 | CO13: 8月 | CP13: 9月 | CQ13: 10月 | CR13: 11月
B14: マスター | H14: 2 | K14: 2 | L14: 1 | M14: 1 | R14: マスター | X14: 1 | AD14: 2 | AE14: 1 | AG14: 1 | AH14: 0 | AI14: 0 | AK14: 1 | AL14: 1 | AP14: 3 | AS14: 2 | AT14: 3 | AU14: 0 | AV14: 0 | AW14: 0 | AX14: 1 | AY14: 0 | AZ14: 0 | BH14: 2 | BJ14: 1 | BK14: 1 | BL14: 2 | BM14: 0 | BO14: 1 | BP14: 3 | BS14: 1 | BX14: 2 | BY14: 1 | BZ14: 1 | CA14: 0 | CB14: 0 | CC14: 0 | CD14: 1 | CE14: 0 | CF14: 0 | CG14: 0 | CH14: 0 | CI14: 0 | CJ14: =退会者!K20 -> 0 | CK14: =退会者!L20 -> 0 | CL14: =退会者!M20 -> 0 | CM14: =退会者!N20 -> 0 | CN14: =退会者!O20 -> 0 | CO14: =退会者!P20 -> 0 | CP14: =退会者!Q20 -> 0 | CQ14: =退会者!R20 -> 0 | CR14: =退会者!S20 -> 0
B15: レギュラー | D15: 1 | H15: 3 | I15: 3 | K15: 5 | L15: 5 | M15: 2 | N15: 7 | O15: 2 | P15: 4 | R15: レギュラー | S15: 2 | T15: 1 | U15: 2 | V15: 2 | W15: 2 | X15: 1 | Y15: 1 | Z15: 4 | AA15: 2 | AB15: 3 | AC15: 4 | AD15: 3 | AE15: 4 | AF15: 5 | AG15: 5 | AH15: 4 | AI15: 6 | AJ15: 1 | AK15: 3 | AL15: 2 | AM15: 3 | AN15: 2 | AO15: 6 | AP15: 6 | AQ15: 4 | AR15: 5 | AS15: 7 | AT15: 2 | AU15: 2 | AV15: 4 | AW15: 0 | AX15: 3 | AY15: 3 | AZ15: 4 | BA15: 8 | BC15: 5 | BD15: 2 | BE15: 3 | BF15: 5 | BG15: 4 | BH15: 6 | BI15: 7 | BJ15: 3 | BK15: 5 | BL15: 5 | BM15: 1 | BN15: 9 | BO15: 7 | BP15: 3 | BQ15: 6 | BR15: 8 | BS15: 4 | BT15: 7 | BU15: 1 | BV15: 5 | BW15: 5 | BX15: 3 | BY15: 10 | BZ15: 3 | CA15: 4 | CB15: 6 | CC15: 3 | CD15: 6 | CE15: 4 | CF15: 4 | CG15: 6 | CH15: 4 | CI15: 3 | CJ15: =退会者!K21 -> 5 | CK15: =退会者!L21 -> 2 | CL15: =退会者!M21 -> 6 | CM15: =退会者!N21 -> 0 | CN15: =退会者!O21 -> 0 | CO15: =退会者!P21 -> 0 | CP15: =退会者!Q21 -> 0 | CQ15: =退会者!R21 -> 0 | CR15: =退会者!S21 -> 0
B16: ライト | R16: ライト | U16: 1 | Y16: 3 | AB16: 2 | AC16: 6 | AF16: 3 | AG16: 1 | AH16: 1 | AI16: 4 | AJ16: 2 | AK16: 2 | AL16: 1 | AO16: 1 | AP16: 2 | AR16: 1 | AS16: 3 | AU16: 1 | AV16: 0 | AW16: 0 | AX16: 0 | AY16: 0 | AZ16: 0 | BC16: 1 | BD16: 1 | BH16: 1 | BI16: 2 | CA16: 0 | CB16: 0 | CC16: 0 | CD16: 0 | CE16: 1 | CF16: 0 | CG16: 1 | CH16: 0 | CI16: 0 | CJ16: =退会者!K22 -> 0 | CK16: =退会者!L22 -> 0 | CL16: =退会者!M22 -> 0 | CM16: =退会者!N22 -> 0 | CN16: =退会者!O22 -> 0 | CO16: =退会者!P22 -> 0 | CP16: =退会者!Q22 -> 0 | CQ16: =退会者!R22 -> 0 | CR16: =退会者!S22 -> 0
B17: 法人 | G17: 1 | K17: 1 | N17: 1 | R17: 法人 | AI17: 0 | AP17: 0 | AQ17: 1 | AV17: 0 | AW17: 0 | AX17: 0 | AY17: 0 | AZ17: 0 | BM17: 1 | BN17: 1 | BQ17: 1 | BU17: 1 | CA17: 0 | CB17: 0 | CC17: 0 | CD17: 0 | CE17: 0 | CF17: 0 | CG17: 1 | CH17: 0 | CI17: 0 | CJ17: =退会者!K23 -> 0 | CK17: =退会者!L23 -> 0 | CL17: =退会者!M23 -> 0 | CM17: =退会者!N23 -> 0 | CN17: =退会者!O23 -> 0 | CO17: =退会者!P23 -> 0 | CP17: =退会者!Q23 -> 0 | CQ17: =退会者!R23 -> 0 | CR17: =退会者!S23 -> 0
B18: チケット | R18: チケット | AE18: 1 | AH18: 2 | AI18: 0 | AK18: 2 | AO18: 1 | AP18: 1 | AW18: 0 | AX18: 0 | AY18: 0 | AZ18: 1 | BB18: 1 | BI18: 0 | BJ18: 1 | BK18: 2 | BL18: 1 | BM18: 2 | BN18: 1 | BO18: 1 | BS18: 1 | BT18: 1 | BV18: 1 | BW18: 1 | CA18: 1 | CB18: 0 | CC18: 2 | CD18: 2 | CE18: 0 | CF18: 0 | CG18: 0 | CH18: 0 | CI18: 0 | CJ18: =退会者!K24 -> 0 | CK18: =退会者!L24 -> 0 | CL18: =退会者!M24 -> 0 | CM18: =退会者!N24 -> 0 | CN18: =退会者!O24 -> 0 | CO18: =退会者!P24 -> 0 | CP18: =退会者!Q24 -> 0 | CQ18: =退会者!R24 -> 0 | CR18: =退会者!S24 -> 0
B19: 計 | C19: =SUM(C13:C18) -> 0 | D19: =SUM(D13:D18) -> 1 | E19: =SUM(E13:E18) -> 0 | F19: =SUM(F13:F18) -> 0 | G19: =SUM(G13:G18) -> 1 | H19: =SUM(H13:H18) -> 5 | I19: =SUM(I13:I18) -> 3 | J19: =SUM(J13:J18) -> 0 | ... P19: =SUM(P13:P18) -> 4 | R19: 計 | S19: =SUM(S13:S18) -> 2 | T19: =SUM(T13:T18) -> 1 | U19: =SUM(U13:U18) -> 3 | V19: =SUM(V13:V18) -> 2 | W19: =SUM(W13:W18) -> 2 | X19: =SUM(X13:X18) -> 2 | Y19: =SUM(Y13:Y18) -> 4 | Z19: =SUM(Z13:Z18) -> 4 | ... BN19: =SUM(BN13:BN18) -> 11 | BO19: 9 | BP19: 6 | BQ19: 7 | BR19: 8 | BS19: 6 | BT19: 8 | BU19: 2 | BV19: 6 | BW19: 6 | BX19: 5 | BY19: 11 | BZ19: 4 | CA19: =SUM(CA13:CA18) -> 5 | CB19: =SUM(CB13:CB18) -> 6 | CC19: =SUM(CC13:CC18) -> 5 | CD19: =SUM(CD13:CD18) -> 9 | CE19: =SUM(CE13:CE18) -> 5 | CF19: =SUM(CF13:CF18) -> 4 | CG19: =SUM(CG13:CG18) -> 8 | CH19: =SUM(CH13:CH18) -> 4 | ... CR19: =SUM(CR13:CR18) -> 0
AD20: =SUM(S19:AD19) -> 42 | AP20: =SUM(AE19:AP19) -> 78 | BB20: =SUM(AQ19:BB19) -> 56 | BG20: 1名除名：森田光昭 | BN20: =SUM(BC19:BN19) -> 75 | BZ20: =SUM(BO19:BZ19) -> 78 | CL20: =SUM(CA19:CL19) -> 62
C21: 2019年 | L21: 2020年 | BN21: 2名除名 入澤、
C22: 4月 | D22: 5月 | E22: 6月 | F22: 7月 | G22: 8月 | H22: 9月 | I22: 10月 | J22: 11月 | K22: 12月 | L22: 1月 | M22: 2月 | N22: 3月 | O22: 4月 | P22: 5月 | S22: 26期 | AE22: 27期 | AQ22: 28期 | BO22: 30期 | CA22: 31期
A23: プラン変更 | B23: プラチナ | R23: プラン変 | S23: 6月 | T23: 7月 | U23: 8月 | V23: 9月 | W23: 10月 | X23: 11月 | Y23: 12月 | Z23: 1月 | AA23: 2月 | AB23: 3月 | AC23: 4月 | AD23: 5月 | AE23: 6月 | AF23: 7月 | AG23: 8月 | AH23: 9月 | AI23: 10月 | AJ23: 11月 | AK23: 12月 | AL23: 1月 | AM23: 2月 | AN23: 3月 | AO23: 4月 | AP23: 5月 | AQ23: 6月 | AR23: 7月 | AS23: 8月 | AT23: 9月 | AU23: 10月 | AV23: 11月 | AW23: 12月 | AX23: 1月 | AY23: 2月 | AZ23: 3月 | BA23: 4月 | BB23: 5月 | BC23: 6月 | BD23: 7月 | BE23: 8月 | BF23: 9月 | BG23: 10月 | BH23: 11月 | BI23: 12月 | BJ23: 1月 | BK23: 2月 | BL23: 3月 | BM23: 4月 | BN23: 5月 | BO23: 6月 | BP23: 7月 | BQ23: 8月 | BR23: 9月 | BS23: 10月 | BT23: 11月 | BU23: 12月 | BV23: 1月 | BW23: 2月 | BX23: 3月 | BY23: 4月 | BZ23: 5月 | CA23: 6月 | CB23: 7月 | CC23: 8月 | CD23: 9月 | CE23: 10月 | CF23: 11月 | CG23: 12月 | CH23: 1月 | CI23: 2月 | CJ23: 3月 | CK23: 4月 | CL23: 5月 | CM23: 6月 | CN23: 7月 | CO23: 8月 | CP23: 9月 | CQ23: 10月 | CR23: 11月
B24: マスター | L24: 1 | R24: マスター | AB24: -1 | AC24: 2 | AF24: 1 | AL24: 1 | AO24: 2 | AV24: 1 | AW24: 1 | BA24: 1 | BC24: 3 | BD24: -1 | BE24: 1 | BH24: 1 | BK24: 1 | BM24: -1 | BN24: 1 | BR24: -1 | BU24: -1 | BW24: -2 | BX24: -3 | BY24: 1 | CA24: 0 | CB24: 0 | CC24: 0 | CD24: 0 | CE24: -2 | CF24: 1 | CG24: 0 | CI24: 1 | CJ24: -1 | CK24: 1
B25: レギュラー | L25: -1 | P25: -1 | R25: レギュラー | S25: -3 | T25: 2 | Z25: 1 | AC25: -2 | AE25: 1 | AF25: -1 | AG25: 1 | AI25: -1 | AJ25: -1 | AL25: 0 | AO25: -2 | AU25: 1 | AV25: -1 | AW25: -1 | BA25: -1 | BC25: 4 | BD25: 1 | BE25: -1 | BF25: 2 | BH25: -1 | BK25: -1 | BM25: 2 | BN25: -1 | BR25: -1 | BU25: 1 | BW25: 2 | BX25: 2 | BZ25: -1 | CA25: -1 | CB25: -2 | CC25: 0 | CD25: 0 | CE25: 2 | CF25: -1 | CG25: 0 | CH25: -1 | CI25: -1 | CJ25: 1 | CK25: -1 | CL25: -1
B26: ライト | P26: 1 | R26: ライト | S26: 3 | T26: -2 | Z26: -1 | AB26: 1 | AE26: -1 | AU26: -1 | BC26: -7 | BD26: -1 | CA26: 0 | CB26: 0 | CC26: 0 | CD26: 0 | CE26: 0 | CF26: 0 | CG26: 0
B27: 法人 | R27: 法人 | BM27: -1 | CA27: 1 | CB27: 1 | CC27: 0 | CD27: 0 | CE27: 0 | CF27: 0 | CG27: 0 | CL27: -1
B28: チケット | R28: チケット | AG28: -1 | AI28: 1 | AJ28: 1 | AL28: -1 | BD28: 1 | BF28: -2 | BR28: 2 | BX28: 1 | BY28: -1 | BZ28: 1 | CA28: 0 | CB28: 0 | CC28: 0 | CD28: 0 | CE28: 0 | CF28: 0 | CG28: 0 | CH28: 1 | CL28: 2
B29: 計 | R29: 計
BO31: 30期 | CA31: 31期
A32: 継続会員数 | B32: プラチナ | C32: =SUM(C3,-C13,C23) -> 0 | D32: =SUM(C32,D3,-D13,D23) -> 0 | E32: =SUM(D32,E3,-E13,E23) -> 0 | F32: =SUM(E32,F3,-F13,F23) -> 0 | G32: =SUM(F32,G3,-G13,G23) -> 0 | H32: =SUM(G32,H3,-H13,H23) -> 0 | I32: =SUM(H32,I3,-I13,I23) -> 0 | J32: =SUM(I32,J3,-J13,J23) -> 0 | K32: =SUM(J32,K3,-K13,K23) -> 0 | ... N32: =SUM(M32,N3,-N13,N23) -> 0 | R32: 累積 | S32: 6月 | T32: 7月 | U32: 8月 | V32: 9月 | W32: 10月 | X32: 11月 | Y32: 12月 | Z32: 1月 | AA32: 2月 | AB32: 3月 | AC32: 4月 | AD32: 5月 | AE32: 6月 | AF32: 7月 | AG32: 8月 | AH32: 9月 | AI32: 10月 | AJ32: 11月 | AK32: 12月 | AL32: 1月 | AM32: 2月 | AN32: 3月 | AO32: 4月 | AP32: 5月 | AQ32: 6月 | AR32: 7月 | AS32: 8月 | AT32: 9月 | AU32: 10月 | AV32: 11月 | AW32: 12月 | AX32: 1月 | AY32: 2月 | AZ32: 3月 | BA32: 4月 | BB32: 5月 | BC32: 6月 | BD32: 7月 | BE32: 8月 | BF32: 9月 | BG32: 10月 | BH32: 11月 | BI32: 12月 | BJ32: 1月 | BK32: 2月 | BL32: 3月 | BM32: 4月 | BN32: 5月 | BO32: 6月 | BP32: 7月 | BQ32: 8月 | BR32: 9月 | BS32: 10月 | BT32: 11月 | BU32: 12月 | BV32: 1月 | BW32: 2月 | BX32: 3月 | BY32: 4月 | BZ32: 5月 | CA32: 6月 | CB32: 7月 | CC32: 8月 | CD32: 9月 | CE32: 10月 | CF32: 11月 | CG32: 12月 | CH32: 1月 | CI32: 2月 | CJ32: 3月 | CK32: 4月 | CL32: 5月 | CM32: 6月 | CN32: 7月 | CO32: 8月 | CP32: 9月 | CQ32: 10月 | CR32: 11月
B33: マスター | C33: =SUM(C4,-C14,C24) -> 3 | D33: =SUM(C33,D4,-D14,D24) -> 3 | E33: =SUM(D33,E4,-E14,E24) -> 4 | F33: =SUM(E33,F4,-F14,F24) -> 7 | G33: =SUM(F33,G4,-G14,G24) -> 7 | H33: =SUM(G33,H4,-H14,H24) -> 5 | I33: =SUM(H33,I4,-I14,I24) -> 5 | J33: =SUM(I33,J4,-J14,J24) -> 5 | K33: =SUM(J33,K4,-K14,K24) -> 3 | ... P33: =SUM(O33,P4,-P14,P24) -> 2 | R33: マスター | S33: =SUM(P33,S4,-S14,S24) -> 3 | T33: =SUM(S33,T4,-T14,T24) -> 3 | U33: =SUM(T33,U4,-U14,U24) -> 4 | V33: =SUM(U33,V4,-V14,V24) -> 6 | W33: =SUM(V33,W4,-W14,W24) -> 7 | X33: =SUM(W33,X4,-X14,X24) -> 8 | Y33: =SUM(X33,Y4,-Y14,Y24) -> 8 | Z33: =SUM(Y33,Z4,-Z14,Z24) -> 10 | AA33: =SUM(Z33,AA4,-AA14,AA24) -> 11 | ... AD33: =SUM(AC33,AD4,-AD14,AD24) -> 10 | AE33: =SUM(9,AE4,-AE14,AE24) -> 8 | AF33: =SUM(AE33,AF4,-AF14,AF24) -> 9 | AG33: =SUM(AF33,AG4,-AG14,AG24) -> 10 | AH33: =SUM(AG33,AH4,-AH14,AH24) -> 11 | AI33: =SUM(AH33,AI4,-AI14,AI24) -> 11 | AJ33: =SUM(AI33,AJ4,-AJ14,AJ24) -> 11 | AK33: =SUM(AJ33,AK4,-AK14,AK24) -> 12 | AL33: =SUM(AK33,AL4,-AL14,AL24) -> 13 | AM33: =SUM(AL33,AM4,-AM14,AM24) -> 14 | ... AP33: =SUM(AO33,AP4,-AP14,AP24) -> 17 | AQ33: 13 | AR33: =SUM(AQ33,AR4,-AR14,AR24) -> 13 | AS33: =SUM(AR33,AS4,-AS14,AS24) -> 11 | AT33: =SUM(AS33,AT4,-AT14,AT24) -> 8 | AU33: =SUM(AT33,AU4,-AU14,AU24) -> 8 | AV33: =SUM(AU33,AV4,-AV14,AV24) -> 10 | AW33: =SUM(AV33,AW4,-AW14,AW24) -> 12 | AX33: =SUM(AW33,AX4,-AX14,AX24) -> 11 | AY33: =SUM(AX33,AY4,-AY14,AY24) -> 11 | ... BW33: =SUM(BV33,BW4,-BW14,BW24) -> 20 | BX33: 17 | BY33: 18 | BZ33: 18 | CA33: 19 | CB33: 19 | CC33: 19 | CD33: 18 | CE33: =CD33+CE24-CE14+CE4 -> 16 | CF33: =CE33+CF24-CF14+CF4 -> 18 | CG33: =CF33+CG24-CG14+CG4 -> 20 | CH33: =CG33+CH24-CH14+CH4 -> 21 | CI33: =CH33+CI24-CI14+CI4 -> 25 | CJ33: =CI33+CJ24-CJ14+CJ4 -> 26 | CK33: =CJ33+CK24-CK14+CK4 -> 30 | CL33: =CK33+CL24-CL14+CL4 -> 32
B34: レギュラー | C34: =SUM(C5,-C15,C25) -> 14 | D34: =SUM(C34,D5,-D15,D25) -> 26 | E34: =SUM(D34,E5,-E15,E25) -> 31 | F34: =SUM(E34,F5,-F15,F25) -> 37 | G34: =SUM(F34,G5,-G15,G25) -> 45 | H34: =SUM(G34,H5,-H15,H25) -> 48 | I34: =SUM(H34,I5,-I15,I25) -> 46 | J34: =SUM(I34,J5,-J15,J25) -> 49 | K34: =SUM(J34,K5,-K15,K25) -> 46 | ... P34: =SUM(O34,P5,-P15,P25) -> 41 | R34: レギュラー | S34: =SUM(P34,S5,-S15,S25) -> 46 | T34: =SUM(S34,T5,-T15,T25) -> 50 | U34: =SUM(T34,U5,-U15,U25) -> 49 | V34: =SUM(U34,V5,-V15,V25) -> 49 | W34: =SUM(V34,W5,-W15,W25) -> 52 | X34: =SUM(W34,X5,-X15,X25) -> 55 | Y34: =SUM(X34,Y5,-Y15,Y25) -> 61 | Z34: =SUM(Y34,Z5,-Z15,Z25) -> 64 | AA34: =SUM(Z34,AA5,-AA15,AA25) -> 65 | ... AD34: =SUM(AC34,AD5,-AD15,AD25) -> 76 | AE34: =SUM(73,AE5,-AE15,AE25) -> 75 | AF34: =SUM(AE34,AF5,-AF15,AF25) -> 74 | AG34: =SUM(AF34,AG5,-AG15,AG25) -> 77 | AH34: =SUM(AG34,AH5,-AH15,AH25) -> 80 | AI34: =SUM(AH34,AI5,-AI15,AI25) -> 75 | AJ34: =SUM(AI34,AJ5,-AJ15,AJ25) -> 79 | AK34: =SUM(AJ34,AK5,-AK15,AK25) -> 79 | AL34: =SUM(AK34,AL5,-AL15,AL25) -> 81 | AM34: =SUM(AL34,AM5,-AM15,AM25) -> 86 | ... AP34: =SUM(AO34,AP5,-AP15,AP25) -> 76 | AQ34: 85 | AR34: =SUM(AQ34,AR5,-AR15,AR25) -> 83 | AS34: =SUM(AR34,AS5,-AS15,AS25) -> 81 | AT34: =SUM(AS34,AT5,-AT15,AT25) -> 84 | AU34: =SUM(AT34,AU5,-AU15,AU25) -> 89 | AV34: =SUM(AU34,AV5,-AV15,AV25) -> 87 | AW34: =SUM(AV34,AW5,-AW15,AW25) -> 88 | AX34: =SUM(AW34,AX5,-AX15,AX25) -> 93 | AY34: =SUM(AX34,AY5,-AY15,AY25) -> 94 | ... BZ34: =SUM(BY34,BZ5,-BZ15,BZ25) -> 131 | CA34: 132 | CB34: 134 | CC34: 141 | CD34: 140 | CE34: =CD34+CE25-CE15+CE5 -> 145 | CF34: =CE34+CF25-CF15+CF5 -> 148 | CG34: =CF34+CG25-CG15+CG5 -> 150 | CH34: =CG34+CH25-CH15+CH5 -> 146 | CI34: =CH34+CI25-CI15+CI5 -> 146 | CJ34: =CI34+CJ25-CJ15+CJ5 -> 148 | CK34: =CJ34+CK25-CK15+CK5 -> 147 | CL34: =CK34+CL25-CL15+CL5 -> 148
B35: ライト | O35: =SUM(N35,O6,-O16,O26) -> 0 | P35: =SUM(O35,P6,-P16,P26) -> 1 | R35: ライト | S35: =SUM(P35,S6,-S16,S26) -> 15 | T35: =SUM(S35,T6,-T16,T26) -> 17 | U35: =SUM(T35,U6,-U16,U26) -> 20 | V35: =SUM(U35,V6,-V16,V26) -> 21 | W35: =SUM(V35,W6,-W16,W26) -> 31 | X35: =SUM(W35,X6,-X16,X26) -> 38 | Y35: =SUM(X35,Y6,-Y16,Y26) -> 39 | Z35: =SUM(Y35,Z6,-Z16,Z26) -> 46 | AA35: =SUM(Z35,AA6,-AA16,AA26) -> 50 | ... BZ35: =SUM(BY35,BZ6,-BZ16,BZ26) -> 12 | CA35: 11 | CB35: 11 | CC35: 11 | CD35: 11 | CE35: =CD35+CE26-CE16+CE6 -> 10 | CF35: =CE35+CF26-CF16+CF6 -> 10 | CG35: =CF35+CG26-CG16+CG6 -> 9 | CH35: =CG35+CH26-CH16+CH6 -> 9 | CI35: =CH35+CI26-CI16+CI6 -> 9 | CJ35: =CI35+CJ26-CJ16+CJ6 -> 9 | CK35: =CJ35+CK26-CK16+CK6 -> 9 | CL35: =CK35+CL26-CL16+CL6 -> 9
B36: 法人 | C36: =SUM(C7,-C17,C27) -> 2 | D36: =SUM(C36,D7,-D17,D27) -> 3 | E36: =SUM(D36,E7,-E17,E27) -> 3 | F36: =SUM(E36,F7,-F17,F27) -> 3 | G36: =SUM(F36,G7,-G17,G27) -> 2 | H36: =SUM(G36,H7,-H17,H27) -> 2 | I36: =SUM(H36,I7,-I17,I27) -> 2 | J36: =SUM(I36,J7,-J17,J27) -> 2 | K36: =SUM(J36,K7,-K17,K27) -> 1 | ... P36: =SUM(O36,P7,-P17,P27) -> 0 | R36: 法人 | S36: =SUM(P36,S7,-S17,S27) -> 0 | T36: =SUM(S36,T7,-T17,T27) -> 0 | U36: =SUM(T36,U7,-U17,U27) -> 0 | V36: =SUM(U36,V7,-V17,V27) -> 0 | W36: =SUM(V36,W7,-W17,W27) -> 0 | X36: =SUM(W36,X7,-X17,X27) -> 0 | Y36: =SUM(X36,Y7,-Y17,Y27) -> 0 | Z36: =SUM(Y36,Z7,-Z17,Z27) -> 1 | AA36: =SUM(Z36,AA7,-AA17,AA27) -> 1 | ... BZ36: =SUM(BY36,BZ7,-BZ17,BZ27) -> 1 | CA36: 2 | CB36: 3 | CC36: 3 | CD36: 4 | CE36: =CD36+CE27-CE17+CE7 -> 5 | CF36: =CE36+CF27-CF17+CF7 -> 6 | CG36: =CF36+CG27-CG17+CG7 -> 5 | CH36: =CG36+CH27-CH17+CH7 -> 5 | CI36: =CH36+CI27-CI17+CI7 -> 5 | CJ36: =CI36+CJ27-CJ17+CJ7 -> 5 | CK36: =CJ36+CK27-CK17+CK7 -> 6 | CL36: =CK36+CL27-CL17+CL7 -> 5
B37: チケット | R37: チケット | S37: =SUM(P37,S8,-S18,S28) -> 0 | T37: =SUM(S37,T8,-T18,T28) -> 0 | U37: =SUM(T37,U8,-U18,U28) -> 1 | V37: =SUM(U37,V8,-V18,V28) -> 1 | W37: =SUM(V37,W8,-W18,W28) -> 1 | X37: =SUM(W37,X8,-X18,X28) -> 2 | Y37: =SUM(X37,Y8,-Y18,Y28) -> 2 | Z37: =SUM(Y37,Z8,-Z18,Z28) -> 2 | AA37: =SUM(Z37,AA8,-AA18,AA28) -> 2 | ... AD37: =SUM(AC37,AD8,-AD18,AD28) -> 5 | AE37: =SUM(8,AE8,-AE18,AE28) -> 7 | AF37: =SUM(AE37,AF8,-AF18,AF28) -> 7 | AG37: =SUM(AF37,AG8,-AG18,AG28) -> 7 | AH37: =SUM(AG37,AH8,-AH18,AH28) -> 6 | AI37: =SUM(AH37,AI8,-AI18,AI28) -> 7 | AJ37: =SUM(AI37,AJ8,-AJ18,AJ28) -> 8 | AK37: =SUM(AJ37,AK8,-AK18,AK28) -> 6 | AL37: =SUM(AK37,AL8,-AL18,AL28) -> 5 | AM37: =SUM(AL37,AM8,-AM18,AM28) -> 6 | ... AP37: =SUM(AO37,AP8,-AP18,AP28) -> 5 | AQ37: 2 | AR37: =SUM(AQ37,AR8,-AR18,AR28) -> 2 | AS37: =SUM(AR37,AS8,-AS18,AS28) -> 4 | AT37: =SUM(AS37,AT8,-AT18,AT28) -> 5 | AU37: =SUM(AT37,AU8,-AU18,AU28) -> 5 | AV37: =SUM(AU37,AV8,-AV18,AV28) -> 5 | AW37: =SUM(AV37,AW8,-AW18,AW28) -> 6 | AX37: =SUM(AW37,AX8,-AX18,AX28) -> 9 | AY37: =SUM(AX37,AY8,-AY18,AY28) -> 9 | ... BZ37: =SUM(BY37,BZ8,-BZ18,BZ28) -> 12 | CA37: 12 | CB37: 12 | CC37: 11 | CD37: 9 | CE37: =CD37+CE28-CE18+CE8 -> 9 | CF37: =CE37+CF28-CF18+CF8 -> 9 | CG37: =CF37+CG28-CG18+CG8 -> 9 | CH37: =CG37+CH28-CH18+CH8 -> 12 | CI37: =CH37+CI28-CI18+CI8 -> 13 | CJ37: =CI37+CJ28-CJ18+CJ8 -> 14 | CK37: =CJ37+CK28-CK18+CK8 -> 15 | CL37: =CK37+CL28-CL18+CL8 -> 17
B38: 計 | C38: =SUM(C32:C37) -> 19 | D38: =SUM(D32:D37) -> 32 | E38: =SUM(E32:E37) -> 38 | F38: =SUM(F32:F37) -> 47 | G38: =SUM(G32:G37) -> 54 | H38: =SUM(H32:H37) -> 55 | I38: =SUM(I32:I37) -> 53 | J38: =SUM(J32:J37) -> 56 | ... P38: =SUM(P32:P37) -> 44 | R38: 計 | S38: =SUM(S33:S37) -> 64 | T38: =SUM(T33:T37) -> 70 | U38: =SUM(U33:U37) -> 74 | V38: =SUM(V33:V37) -> 77 | W38: =SUM(W33:W37) -> 91 | X38: =SUM(X33:X37) -> 103 | Y38: =SUM(Y33:Y37) -> 110 | Z38: =SUM(Z33:Z37) -> 123 | ... BZ38: =SUM(BZ33:BZ37) -> 174 | CA38: 176 | CB38: 179 | CC38: 185 | CD38: =SUM(CD33:CD37) -> 182 | CE38: =SUM(CE33:CE37) -> 185 | CF38: =SUM(CF33:CF37) -> 191 | CG38: =SUM(CG33:CG37) -> 193 | CH38: =SUM(CH33:CH37) -> 193 | CI38: =SUM(CI33:CI37) -> 198 | CJ38: =SUM(CJ33:CJ37) -> 202 | CK38: =SUM(CK33:CK37) -> 207 | CL38: =SUM(CL33:CL37) -> 211
AQ40: 28期平日 | AR40: 28期土日 | BO40: 30期 | BY40: 合計 | BZ40: =SUM(BO47:BZ47) -> 56 | CA40: 31期
A41: 休会数 | B41: プラチナ | R41: 休会 | BO41: 6月 | BP41: 7月 | BQ41: 8月 | BR41: 9月 | BS41: 10月 | BT41: 11月 | BU41: 12月 | BV41: 1月 | BW41: 2月 | BX41: 3月 | BY41: 4月 | BZ41: 5月 | CA41: 6月 | CB41: 7月 | CC41: 8月 | CD41: 9月 | CE41: 10月 | CF41: 11月 | CG41: 12月 | CH41: 1月 | CI41: 2月 | CJ41: 3月 | CK41: 4月 | CL41: 5月
B42: マスター | H42: 2 | K42: 2 | L42: 1 | M42: 1 | R42: マスター | BO42: 1 | BS42: 1 | BV42: 1 | BW42: 1 | BX42: 1 | BY42: 1 | CD42: 1
...

Sheet プロ紹介管理表
A1: フィッティング紹介サービス管理表
A3: 日付 | B3: ご利用者名 | C3: メニュー
